Workbook
Name ЕВРО: ПНЕВМАТИКА!$A$1
Name ЕВРО_2025_08_29: 93.49
Name НДС: 1.22
Name НДС_20: 1.2
Name Список_артикулов: База[Артикул]
Name Список_комплектов: Комплекты[Комплект]
Name Список_Сводная_Пневматика_2026: Пневматика_СВОДНАЯ_2026[Ключ]
Name Список_Сводная_Тормоз_2026: Тормоз_СВОДНАЯ_2026[Ключ]
Name ЮАНЬ: ПНЕВМАТИКА!$A$2
Name ЮАНЬ_2025_08_29: 11.25

Sheet ТОРМОЗ
A1: 93.49 | B1: - курс евро/рубль | E1: Дата | G1: 46171 | K1: НДС_20 Проверка
A2: 11.25 | B2: - курс юань/рубль | K2: НДС Проверка
F3: Подсветить артикул: | G3: ъ | I3: 2026-I | N3: 2026 | BS3: 2027 _ НЕ АКТУАЛИЗИРУЕТСЯ | DT3: 2028 _ НЕ АКТУАЛИЗИРУЕТСЯ
A4: Клиент | B4: Условия оплаты | C4: Поставщик | D4: Менеджер | E4: п\п | F4: 2 - продукт WABCO | G4: Номер изделия/ артикул | H4: Наименование | I4: Цена для плана, CNY, без НДС | J4: Цена в валюте, без НДС | K4: Валюта | L4: Цена от курса, CNY, без НДС | N4: ПР 26 | O4: 46023 | S4: 46054 | W4: 46082 | AA4: 46113 | AE4: 46143 | AI4: 46174 | AM4: 46204 | AQ4: 46235 | AU4: 46266 | AY4: 46296 | BC4: 46327 | BG4: 46357 | BL4: ИТОГО, 2026 | BS4: ПР 27 | BT4: 46388 | BX4: 46419 | CB4: 46447 | CF4: 46478 | CJ4: 46508 | CN4: 46539 | CR4: 46569 | CV4: 46600 | CZ4: 46631 | DD4: 46661 | DH4: 46692 | DL4: 46722 | DQ4: ИТОГО, 2027 | DT4: ПР 28 | DU4: 46753 | DY4: 46784 | EC4: 46813 | EG4: 46844 | EK4: 46874 | EO4: 46905 | ES4: 46935 | EW4: 46966 | FA4: 46997 | FE4: 47027 | FI4: 47058 | FM4: 47088 | FR4: ИТОГО, 2028
O5: AOP, шт | P5: Прогноз, шт | Q5: Факт, шт | R5: Коментарий | S5: AOP, шт | T5: Прогноз, шт | U5: Факт, шт | V5: Коментарий | W5: AOP, шт | X5: Прогноз, шт | Y5: Факт, шт | Z5: Коментарий | AA5: AOP, шт | AB5: Прогноз, шт | AC5: Факт, шт | AD5: Коментарий | AE5: AOP, шт | AF5: Прогноз, шт | AG5: Факт, шт | AH5: Коментарий | AI5: AOP, шт | AJ5: Прогноз, шт | AK5: Факт, шт | AL5: Коментарий | AM5: AOP, шт | AN5: Прогноз, шт | AO5: Факт, шт | AP5: Коментарий | AQ5: AOP, шт | AR5: Прогноз, шт | AS5: Факт, шт | AT5: Коментарий | AU5: AOP, шт | AV5: Прогноз, шт | AW5: Факт, шт | AX5: Коментарий | AY5: AOP, шт | AZ5: Прогноз, шт | BA5: Факт, шт | BB5: Коментарий | BC5: AOP, шт | BD5: Прогноз, шт | BE5: Факт, шт | BF5: Коментарий | BG5: AOP, шт | BH5: Прогноз, шт | BI5: Факт, шт | BJ5: Коментарий | BL5: AOP, шт | BM5: Продажи AOP, CNY | BN5: Прогноз, шт | BO5: Продажи Прогноз, CNY | BP5: Факт, шт | BQ5: Продажи Факт, CNY | BT5: AOP, шт | BU5: Прогноз, шт | BV5: Факт, шт | BW5: Коментарий | BX5: AOP, шт | BY5: Прогноз, шт | BZ5: Факт, шт | CA5: Коментарий | CB5: AOP, шт | CC5: Прогноз, шт | CD5: Факт, шт | CE5: Коментарий | CF5: AOP, шт | CG5: Прогноз, шт | CH5: Факт, шт | CI5: Коментарий | CJ5: AOP, шт | CK5: Прогноз, шт | CL5: Факт, шт | CM5: Коментарий | CN5: AOP, шт | CO5: Прогноз, шт | CP5: Факт, шт | CQ5: Коментарий | CR5: AOP, шт | CS5: Прогноз, шт | CT5: Факт, шт | CU5: Коментарий | CV5: AOP, шт | CW5: Прогноз, шт | CX5: Факт, шт | CY5: Коментарий | CZ5: AOP, шт | DA5: Прогноз, шт | DB5: Факт, шт | DC5: Коментарий | DD5: AOP, шт | DE5: Прогноз, шт | DF5: Факт, шт | DG5: Коментарий | DH5: AOP, шт | DI5: Прогноз, шт | DJ5: Факт, шт | DK5: Коментарий | DL5: AOP, шт | DM5: Прогноз, шт | DN5: Факт, шт | DO5: Коментарий | DQ5: AOP, шт | DR5: Продажи AOP, CNY | DU5: AOP, шт | DV5: Прогноз, шт | DW5: Факт, шт | DX5: Коментарий | DY5: AOP, шт | DZ5: Прогноз, шт | EA5: Факт, шт | EB5: Коментарий | EC5: AOP, шт | ED5: Прогноз, шт | EE5: Факт, шт | EF5: Коментарий | EG5: AOP, шт | EH5: Прогноз, шт | EI5: Факт, шт | EJ5: Коментарий | EK5: AOP, шт | EL5: Прогноз, шт | EM5: Факт, шт | EN5: Коментарий | EO5: AOP, шт | EP5: Прогноз, шт | EQ5: Факт, шт | ER5: Коментарий | ES5: AOP, шт | ET5: Прогноз, шт | EU5: Факт, шт | EV5: Коментарий | EW5: AOP, шт | EX5: Прогноз, шт | EY5: Факт, шт | EZ5: Коментарий | FA5: AOP, шт | FB5: Прогноз, шт | FC5: Факт, шт | FD5: Коментарий | FE5: AOP, шт | FF5: Прогноз, шт | FG5: Факт, шт | FH5: Коментарий | FI5: AOP, шт | FJ5: Прогноз, шт | FK5: Факт, шт | FL5: Коментарий | FM5: AOP, шт | FN5: Прогноз, шт | FO5: Факт, шт | FP5: Коментарий | FR5: AOP, шт | FS5: Продажи AOP, CNY
A6: АВТОКОМПОНЕНТ НАО | B6: Предоплата 50% | C6: ВБК Восток | D6: Прасолов, Соловьёв | E6: =IF(ISBLANK(G6),"",IF($A$6:$A$64=$A6,COUNTIF($A$6:A6,$A6),"")) -> 1 | F6: 1 | G6: 6402250560 | H6: 6402250560 AD Тормоз дисковый ( левый ) | I6: 2048 | L6: =IF(K6="RUB",J6/ЮАНЬ,IF(K6="EUR",J6*ЕВРО/ЮАНЬ,"")) | N6: =IF(BP6>0,1,IF(BN6>0,2,)) -> 2 | U6: 0 | AA6: 9 | AE6: 9 | AG6: 0 | AI6: 60 | AM6: 120 | AQ6: 120 | AU6: 120 | AV6: 60 | AY6: 240 | AZ6: 60 | BC6: 240 | BD6: 120 | BG6: 240 | BH6: 240 | BL6: =SUMPRODUCT(--(MOD(COLUMN($O6:$AL6),4)=MOD(COLUMN($O6)+0,4)),$O6:$AL6) +SUMPRODUCT(--(MOD(COLUMN($AM6:$BJ6),4)=MOD(COLUMN($AM6)+0,4)),$AM6:$BJ6) -> 1158 | BM6: =SUMPRODUCT(--(MOD(COLUMN($O6:$AL6),4)=MOD(COLUMN($O6)+0,4)),$O6:$AL6)*$I6 +SUMPRODUCT(--(MOD(COLUMN($AM6:$BJ6),4)=MOD(COLUMN($AM6)+0,4)),$AM6:$BJ6)*$I6 -> 2371584 | BN6: =SUMPRODUCT(--(MOD(COLUMN($O6:$AL6),4)=MOD(COLUMN($O6)+1,4)),$O6:$AL6) +SUMPRODUCT(--(MOD(COLUMN($AM6:$BJ6),4)=MOD(COLUMN($AM6)+1,4)),$AM6:$BJ6) -> 480 | BO6: =SUMPRODUCT(--(MOD(COLUMN($O6:$AL6),4)=MOD(COLUMN($O6)+1,4)),$O6:$AL6)*$I6 +SUMPRODUCT(--(MOD(COLUMN($AM6:$BJ6),4)=MOD(COLUMN($AM6)+1,4)),$AM6:$BJ6)*$I6 -> 983040 | BP6: =SUMPRODUCT(--(MOD(COLUMN($O6:$AL6),4)=MOD(COLUMN($O6)+2,4)),$O6:$AL6) +SUMPRODUCT(--(MOD(COLUMN($AM6:$BJ6),4)=MOD(COLUMN($AM6)+2,4)),$AM6:$BJ6) -> 0 | BQ6: =SUMPRODUCT(--(MOD(COLUMN($O6:$AL6),4)=MOD(COLUMN($O6)+2,4)),$O6:$AL6)*$I6 +SUMPRODUCT(--(MOD(COLUMN($AM6:$BJ6),4)=MOD(COLUMN($AM6)+2,4)),$AM6:$BJ6)*$I6 -> 0 | BT6: 1041 | BX6: 1041 | CB6: 1041 | CF6: 1041 | CJ6: 1041 | CN6: 1041 | CR6: 1041 | CV6: 1041 | CZ6: 1041 | DD6: 1041 | DH6: 1041 | DL6: 1041 | DQ6: =SUMPRODUCT(--(MOD(COLUMN(BT6:CQ6),4)=MOD(COLUMN(BT6),4)),BT6:CQ6)+SUMPRODUCT(--(MOD(COLUMN(CR6:DO6),4)=MOD(COLUMN(CR6),4)),CR6:DO6) -> 12492 | DR6: =SUMPRODUCT(--(MOD(COLUMN(BT6:CQ6),4)=MOD(COLUMN(BT6),4)),BT6:CQ6)*#REF!+SUMPRODUCT(--(MOD(COLUMN(CR6:DO6),4)=MOD(COLUMN(CR6),4)),CR6:DO6)*#REF! -> #REF! | DU6: 2082 | DY6: 2082 | EC6: 2082 | EG6: 2082 | EK6: 2082 | EO6: 2082 | ES6: 2082 | EW6: 2082 | FA6: 2082 | FE6: 2082 | FI6: 2082 | FM6: 2082 | FR6: =SUMPRODUCT(--(MOD(COLUMN(DU6:ER6),4)=MOD(COLUMN(DU6),4)),DU6:ER6)+SUMPRODUCT(--(MOD(COLUMN(ES6:FP6),4)=MOD(COLUMN(ES6),4)),ES6:FP6) -> 24984 | FS6: =SUMPRODUCT(--(MOD(COLUMN(DU6:ER6),4)=MOD(COLUMN(DU6),4)),DU6:ER6)*#REF!+SUMPRODUCT(--(MOD(COLUMN(ES6:FP6),4)=MOD(COLUMN(ES6),4)),ES6:FP6)*#REF! -> #REF!
A7: АВТОКОМПОНЕНТ НАО | B7: Предоплата 50% | C7: ВБК Восток | D7: Прасолов, Соловьёв | E7: =IF(ISBLANK(G7),"",IF($A$6:$A$64=$A7,COUNTIF($A$6:A7,$A7),"")) -> 2 | F7: 1 | G7: 6402250570 | H7: 6402250570 AD Тормоз дисковый ( правый ) | I7: =I6 -> 2048 | L7: =IF(K7="RUB",J7/ЮАНЬ,IF(K7="EUR",J7*ЕВРО/ЮАНЬ,"")) | N7: =IF(BP7>0,1,IF(BN7>0,2,)) -> 2 | U7: 0 | AA7: 9 | AE7: 9 | AG7: 0 | AI7: 60 | AM7: 120 | AQ7: 120 | AU7: 120 | AV7: =AV6 -> 60 | AY7: 240 | AZ7: =AZ6 -> 60 | BC7: 240 | BD7: =BD6 -> 120 | BG7: 240 | BH7: =BH6 -> 240 | BL7: =SUMPRODUCT(--(MOD(COLUMN($O7:$AL7),4)=MOD(COLUMN($O7)+0,4)),$O7:$AL7) +SUMPRODUCT(--(MOD(COLUMN($AM7:$BJ7),4)=MOD(COLUMN($AM7)+0,4)),$AM7:$BJ7) -> 1158 | BM7: =SUMPRODUCT(--(MOD(COLUMN($O7:$AL7),4)=MOD(COLUMN($O7)+0,4)),$O7:$AL7)*$I7 +SUMPRODUCT(--(MOD(COLUMN($AM7:$BJ7),4)=MOD(COLUMN($AM7)+0,4)),$AM7:$BJ7)*$I7 -> 2371584 | BN7: =SUMPRODUCT(--(MOD(COLUMN($O7:$AL7),4)=MOD(COLUMN($O7)+1,4)),$O7:$AL7) +SUMPRODUCT(--(MOD(COLUMN($AM7:$BJ7),4)=MOD(COLUMN($AM7)+1,4)),$AM7:$BJ7) -> 480 | BO7: =SUMPRODUCT(--(MOD(COLUMN($O7:$AL7),4)=MOD(COLUMN($O7)+1,4)),$O7:$AL7)*$I7 +SUMPRODUCT(--(MOD(COLUMN($AM7:$BJ7),4)=MOD(COLUMN($AM7)+1,4)),$AM7:$BJ7)*$I7 -> 983040 | BP7: =SUMPRODUCT(--(MOD(COLUMN($O7:$AL7),4)=MOD(COLUMN($O7)+2,4)),$O7:$AL7) +SUMPRODUCT(--(MOD(COLUMN($AM7:$BJ7),4)=MOD(COLUMN($AM7)+2,4)),$AM7:$BJ7) -> 0 | BQ7: =SUMPRODUCT(--(MOD(COLUMN($O7:$AL7),4)=MOD(COLUMN($O7)+2,4)),$O7:$AL7)*$I7 +SUMPRODUCT(--(MOD(COLUMN($AM7:$BJ7),4)=MOD(COLUMN($AM7)+2,4)),$AM7:$BJ7)*$I7 -> 0 | BT7: 1041 | BX7: 1041 | CB7: 1041 | CF7: 1041 | CJ7: 1041 | CN7: 1041 | CR7: 1041 | CV7: 1041 | CZ7: 1041 | DD7: 1041 | DH7: 1041 | DL7: 1041 | DQ7: =SUMPRODUCT(--(MOD(COLUMN(BT7:CQ7),4)=MOD(COLUMN(BT7),4)),BT7:CQ7)+SUMPRODUCT(--(MOD(COLUMN(CR7:DO7),4)=MOD(COLUMN(CR7),4)),CR7:DO7) -> 12492 | DR7: =SUMPRODUCT(--(MOD(COLUMN(BT7:CQ7),4)=MOD(COLUMN(BT7),4)),BT7:CQ7)*#REF!+SUMPRODUCT(--(MOD(COLUMN(CR7:DO7),4)=MOD(COLUMN(CR7),4)),CR7:DO7)*#REF! -> #REF! | DU7: 2082 | DY7: 2082 | EC7: 2082 | EG7: 2082 | EK7: 2082 | EO7: 2082 | ES7: 2082 | EW7: 2082 | FA7: 2082 | FE7: 2082 | FI7: 2082 | FM7: 2082 | FR7: =SUMPRODUCT(--(MOD(COLUMN(DU7:ER7),4)=MOD(COLUMN(DU7),4)),DU7:ER7)+SUMPRODUCT(--(MOD(COLUMN(ES7:FP7),4)=MOD(COLUMN(ES7),4)),ES7:FP7) -> 24984 | FS7: =SUMPRODUCT(--(MOD(COLUMN(DU7:ER7),4)=MOD(COLUMN(DU7),4)),DU7:ER7)*#REF!+SUMPRODUCT(--(MOD(COLUMN(ES7:FP7),4)=MOD(COLUMN(ES7),4)),ES7:FP7)*#REF! -> #REF!
A8: АВТОКОМПОНЕНТ НАО | B8: Предоплата 50% | C8: ВБК Восток | D8: Прасолов, Соловьёв | E8: =IF(ISBLANK(G8),"",IF($A$6:$A$64=$A8,COUNTIF($A$6:A8,$A8),"")) -> 3 | F8: 1 | G8: 4410328790 | H8: Датчик АБС, 1 м | I8: =90/НДС_20 -> 75 | L8: =IF(K8="RUB",J8/ЮАНЬ,IF(K8="EUR",J8*ЕВРО/ЮАНЬ,"")) | N8: =IF(BP8>0,1,IF(BN8>0,2,)) -> 1 | S8: 1000 | U8: 0 | AA8: 6 | AB8: =1000 -> 1000 | AC8: 1000 | AE8: 6 | AG8: 0 | AI8: 40 | AM8: 80 | AQ8: 80 | AU8: 80 | AV8: =SUM(AV6:AV7)/3 -> 40 | AY8: 160 | AZ8: =SUM(AZ6:AZ7)/3 -> 40 | BC8: 160 | BD8: =SUM(BD6:BD7)/3 -> 80 | BG8: 160 | BH8: =SUM(BH6:BH7)/3 -> 160 | BL8: =SUMPRODUCT(--(MOD(COLUMN($O8:$AL8),4)=MOD(COLUMN($O8)+0,4)),$O8:$AL8) +SUMPRODUCT(--(MOD(COLUMN($AM8:$BJ8),4)=MOD(COLUMN($AM8)+0,4)),$AM8:$BJ8) -> 1772 | BM8: =SUMPRODUCT(--(MOD(COLUMN($O8:$AL8),4)=MOD(COLUMN($O8)+0,4)),$O8:$AL8)*$I8 +SUMPRODUCT(--(MOD(COLUMN($AM8:$BJ8),4)=MOD(COLUMN($AM8)+0,4)),$AM8:$BJ8)*$I8 -> 132900 | BN8: =SUMPRODUCT(--(MOD(COLUMN($O8:$AL8),4)=MOD(COLUMN($O8)+1,4)),$O8:$AL8) +SUMPRODUCT(--(MOD(COLUMN($AM8:$BJ8),4)=MOD(COLUMN($AM8)+1,4)),$AM8:$BJ8) -> 1320 | BO8: =SUMPRODUCT(--(MOD(COLUMN($O8:$AL8),4)=MOD(COLUMN($O8)+1,4)),$O8:$AL8)*$I8 +SUMPRODUCT(--(MOD(COLUMN($AM8:$BJ8),4)=MOD(COLUMN($AM8)+1,4)),$AM8:$BJ8)*$I8 -> 99000 | BP8: =SUMPRODUCT(--(MOD(COLUMN($O8:$AL8),4)=MOD(COLUMN($O8)+2,4)),$O8:$AL8) +SUMPRODUCT(--(MOD(COLUMN($AM8:$BJ8),4)=MOD(COLUMN($AM8)+2,4)),$AM8:$BJ8) -> 1000 | BQ8: =SUMPRODUCT(--(MOD(COLUMN($O8:$AL8),4)=MOD(COLUMN($O8)+2,4)),$O8:$AL8)*$I8 +SUMPRODUCT(--(MOD(COLUMN($AM8:$BJ8),4)=MOD(COLUMN($AM8)+2,4)),$AM8:$BJ8)*$I8 -> 75000 | BT8: 694 | BX8: 694 | CB8: 694 | CF8: 694 | CJ8: 694 | CN8: 694 | CR8: 694 | CV8: 694 | CZ8: 694 | DD8: 694 | DH8: 694 | DL8: 694 | DQ8: =SUMPRODUCT(--(MOD(COLUMN(BT8:CQ8),4)=MOD(COLUMN(BT8),4)),BT8:CQ8)+SUMPRODUCT(--(MOD(COLUMN(CR8:DO8),4)=MOD(COLUMN(CR8),4)),CR8:DO8) -> 8328 | DR8: =SUMPRODUCT(--(MOD(COLUMN(BT8:CQ8),4)=MOD(COLUMN(BT8),4)),BT8:CQ8)*#REF!+SUMPRODUCT(--(MOD(COLUMN(CR8:DO8),4)=MOD(COLUMN(CR8),4)),CR8:DO8)*#REF! -> #REF! | DU8: 1388 | DY8: 1388 | EC8: 1388 | EG8: 1388 | EK8: 1388 | EO8: 1388 | ES8: 1388 | EW8: 1388 | FA8: 1388 | FE8: 1388 | FI8: 1388 | FM8: 1388 | FR8: =SUMPRODUCT(--(MOD(COLUMN(DU8:ER8),4)=MOD(COLUMN(DU8),4)),DU8:ER8)+SUMPRODUCT(--(MOD(COLUMN(ES8:FP8),4)=MOD(COLUMN(ES8),4)),ES8:FP8) -> 16656 | FS8: =SUMPRODUCT(--(MOD(COLUMN(DU8:ER8),4)=MOD(COLUMN(DU8),4)),DU8:ER8)*#REF!+SUMPRODUCT(--(MOD(COLUMN(ES8:FP8),4)=MOD(COLUMN(ES8),4)),ES8:FP8)*#REF! -> #REF!
A9: АВТОКОМПОНЕНТ НАО | B9: Предоплата 50% | C9: ВБК Восток | D9: Прасолов, Соловьёв | E9: =IF(ISBLANK(G9),"",IF($A$6:$A$64=$A9,COUNTIF($A$6:A9,$A9),"")) -> 4 | F9: 1 | G9: 8997605104 | H9: Втулка датчика АБС | I9: =8.4/НДС_20 -> 7 | L9: =IF(K9="RUB",J9/ЮАНЬ,IF(K9="EUR",J9*ЕВРО/ЮАНЬ,"")) | N9: =IF(BP9>0,1,IF(BN9>0,2,)) -> 1 | S9: 1000 | U9: 0 | AA9: 6 | AB9: =1000 -> 1000 | AC9: 1000 | AE9: 6 | AG9: 0 | AI9: 40 | AM9: 80 | AQ9: 80 | AU9: 80 | AV9: =SUM(AV6:AV7)/3 -> 40 | AY9: 160 | AZ9: =SUM(AZ6:AZ7)/3 -> 40 | BC9: 160 | BD9: =SUM(BD6:BD7)/3 -> 80 | BG9: 160 | BH9: =SUM(BH6:BH7)/3 -> 160 | BL9: =SUMPRODUCT(--(MOD(COLUMN($O9:$AL9),4)=MOD(COLUMN($O9)+0,4)),$O9:$AL9) +SUMPRODUCT(--(MOD(COLUMN($AM9:$BJ9),4)=MOD(COLUMN($AM9)+0,4)),$AM9:$BJ9) -> 1772 | BM9: =SUMPRODUCT(--(MOD(COLUMN($O9:$AL9),4)=MOD(COLUMN($O9)+0,4)),$O9:$AL9)*$I9 +SUMPRODUCT(--(MOD(COLUMN($AM9:$BJ9),4)=MOD(COLUMN($AM9)+0,4)),$AM9:$BJ9)*$I9 -> 12404 | BN9: =SUMPRODUCT(--(MOD(COLUMN($O9:$AL9),4)=MOD(COLUMN($O9)+1,4)),$O9:$AL9) +SUMPRODUCT(--(MOD(COLUMN($AM9:$BJ9),4)=MOD(COLUMN($AM9)+1,4)),$AM9:$BJ9) -> 1320 | BO9: =SUMPRODUCT(--(MOD(COLUMN($O9:$AL9),4)=MOD(COLUMN($O9)+1,4)),$O9:$AL9)*$I9 +SUMPRODUCT(--(MOD(COLUMN($AM9:$BJ9),4)=MOD(COLUMN($AM9)+1,4)),$AM9:$BJ9)*$I9 -> 9240 | BP9: =SUMPRODUCT(--(MOD(COLUMN($O9:$AL9),4)=MOD(COLUMN($O9)+2,4)),$O9:$AL9) +SUMPRODUCT(--(MOD(COLUMN($AM9:$BJ9),4)=MOD(COLUMN($AM9)+2,4)),$AM9:$BJ9) -> 1000 | BQ9: =SUMPRODUCT(--(MOD(COLUMN($O9:$AL9),4)=MOD(COLUMN($O9)+2,4)),$O9:$AL9)*$I9 +SUMPRODUCT(--(MOD(COLUMN($AM9:$BJ9),4)=MOD(COLUMN($AM9)+2,4)),$AM9:$BJ9)*$I9 -> 7000 | BT9: 694 | BX9: 694 | CB9: 694 | CF9: 694 | CJ9: 694 | CN9: 694 | CR9: 694 | CV9: 694 | CZ9: 694 | DD9: 694 | DH9: 694 | DL9: 694 | DQ9: =SUMPRODUCT(--(MOD(COLUMN(BT9:CQ9),4)=MOD(COLUMN(BT9),4)),BT9:CQ9)+SUMPRODUCT(--(MOD(COLUMN(CR9:DO9),4)=MOD(COLUMN(CR9),4)),CR9:DO9) -> 8328 | DR9: =SUMPRODUCT(--(MOD(COLUMN(BT9:CQ9),4)=MOD(COLUMN(BT9),4)),BT9:CQ9)*#REF!+SUMPRODUCT(--(MOD(COLUMN(CR9:DO9),4)=MOD(COLUMN(CR9),4)),CR9:DO9)*#REF! -> #REF! | DU9: 1388 | DY9: 1388 | EC9: 1388 | EG9: 1388 | EK9: 1388 | EO9: 1388 | ES9: 1388 | EW9: 1388 | FA9: 1388 | FE9: 1388 | FI9: 1388 | FM9: 1388 | FR9: =SUMPRODUCT(--(MOD(COLUMN(DU9:ER9),4)=MOD(COLUMN(DU9),4)),DU9:ER9)+SUMPRODUCT(--(MOD(COLUMN(ES9:FP9),4)=MOD(COLUMN(ES9),4)),ES9:FP9) -> 16656 | FS9: =SUMPRODUCT(--(MOD(COLUMN(DU9:ER9),4)=MOD(COLUMN(DU9),4)),DU9:ER9)*#REF!+SUMPRODUCT(--(MOD(COLUMN(ES9:FP9),4)=MOD(COLUMN(ES9),4)),ES9:FP9)*#REF! -> #REF!
A10: АВТОКОМПОНЕНТ НАО | B10: Предоплата 50% | C10: ВБК Восток | D10: Прасолов, Соловьёв | E10: =IF(ISBLANK(G10),"",IF($A$6:$A$64=$A10,COUNTIF($A$6:A10,$A10),"")) -> 5 | F10: 1 | G10: 4235041001 | H10: Тормозная камера, тип 20 | I10: =163.08/НДС_20 -> 135.9 | L10: =IF(K10="RUB",J10/ЮАНЬ,IF(K10="EUR",J10*ЕВРО/ЮАНЬ,"")) | N10: =IF(BP10>0,1,IF(BN10>0,2,)) -> 2 | U10: 0 | AG10: 0 | AR10: =600 -> 600 | BL10: =SUMPRODUCT(--(MOD(COLUMN($O10:$AL10),4)=MOD(COLUMN($O10)+0,4)),$O10:$AL10) +SUMPRODUCT(--(MOD(COLUMN($AM10:$BJ10),4)=MOD(COLUMN($AM10)+0,4)),$AM10:$BJ10) -> 0 | BM10: =SUMPRODUCT(--(MOD(COLUMN($O10:$AL10),4)=MOD(COLUMN($O10)+0,4)),$O10:$AL10)*$I10 +SUMPRODUCT(--(MOD(COLUMN($AM10:$BJ10),4)=MOD(COLUMN($AM10)+0,4)),$AM10:$BJ10)*$I10 -> 0 | BN10: =SUMPRODUCT(--(MOD(COLUMN($O10:$AL10),4)=MOD(COLUMN($O10)+1,4)),$O10:$AL10) +SUMPRODUCT(--(MOD(COLUMN($AM10:$BJ10),4)=MOD(COLUMN($AM10)+1,4)),$AM10:$BJ10) -> 600 | BO10: =SUMPRODUCT(--(MOD(COLUMN($O10:$AL10),4)=MOD(COLUMN($O10)+1,4)),$O10:$AL10)*$I10 +SUMPRODUCT(--(MOD(COLUMN($AM10:$BJ10),4)=MOD(COLUMN($AM10)+1,4)),$AM10:$BJ10)*$I10 -> 81540 | BP10: =SUMPRODUCT(--(MOD(COLUMN($O10:$AL10),4)=MOD(COLUMN($O10)+2,4)),$O10:$AL10) +SUMPRODUCT(--(MOD(COLUMN($AM10:$BJ10),4)=MOD(COLUMN($AM10)+2,4)),$AM10:$BJ10) -> 0 | BQ10: =SUMPRODUCT(--(MOD(COLUMN($O10:$AL10),4)=MOD(COLUMN($O10)+2,4)),$O10:$AL10)*$I10 +SUMPRODUCT(--(MOD(COLUMN($AM10:$BJ10),4)=MOD(COLUMN($AM10)+2,4)),$AM10:$BJ10)*$I10 -> 0 | BT10: 694 | BX10: 694 | CB10: 694 | CF10: 694 | CJ10: 694 | CN10: 694 | CR10: 694 | CV10: 694 | CZ10: 694 | DD10: 694 | DH10: 694 | DL10: 694 | DQ10: =SUMPRODUCT(--(MOD(COLUMN(BT10:CQ10),4)=MOD(COLUMN(BT10),4)),BT10:CQ10)+SUMPRODUCT(--(MOD(COLUMN(CR10:DO10),4)=MOD(COLUMN(CR10),4)),CR10:DO10) -> 8328 | DR10: =SUMPRODUCT(--(MOD(COLUMN(BT10:CQ10),4)=MOD(COLUMN(BT10),4)),BT10:CQ10)*#REF!+SUMPRODUCT(--(MOD(COLUMN(CR10:DO10),4)=MOD(COLUMN(CR10),4)),CR10:DO10)*#REF! -> #REF! | DU10: 1388 | DY10: 1388 | EC10: 1388 | EG10: 1388 | EK10: 1388 | EO10: 1388 | ES10: 1388 | EW10: 1388 | FA10: 1388 | FE10: 1388 | FI10: 1388 | FM10: 1388 | FR10: =SUMPRODUCT(--(MOD(COLUMN(DU10:ER10),4)=MOD(COLUMN(DU10),4)),DU10:ER10)+SUMPRODUCT(--(MOD(COLUMN(ES10:FP10),4)=MOD(COLUMN(ES10),4)),ES10:FP10) -> 16656 | FS10: =SUMPRODUCT(--(MOD(COLUMN(DU10:ER10),4)=MOD(COLUMN(DU10),4)),DU10:ER10)*#REF!+SUMPRODUCT(--(MOD(COLUMN(ES10:FP10),4)=MOD(COLUMN(ES10),4)),ES10:FP10)*#REF! -> #REF!
A11: АВТОКОМПОНЕНТ НАО | B11: Предоплата 50% | C11: ВБК Восток | D11: Прасолов, Соловьёв | E11: =IF(ISBLANK(G11),"",IF($A$6:$A$64=$A11,COUNTIF($A$6:A11,$A11),"")) -> 6 | F11: 1 | G11: 9254800504 | H11: Энергоаккумулятор, тип 20/24 | I11: =373.98/НДС_20 -> 311.65 | L11: =IF(K11="RUB",J11/ЮАНЬ,IF(K11="EUR",J11*ЕВРО/ЮАНЬ,"")) | N11: =IF(BP11>0,1,IF(BN11>0,2,)) -> 2 | U11: 0 | AG11: 0 | AR11: =1000 -> 1000 | BL11: =SUMPRODUCT(--(MOD(COLUMN($O11:$AL11),4)=MOD(COLUMN($O11)+0,4)),$O11:$AL11) +SUMPRODUCT(--(MOD(COLUMN($AM11:$BJ11),4)=MOD(COLUMN($AM11)+0,4)),$AM11:$BJ11) -> 0 | BM11: =SUMPRODUCT(--(MOD(COLUMN($O11:$AL11),4)=MOD(COLUMN($O11)+0,4)),$O11:$AL11)*$I11 +SUMPRODUCT(--(MOD(COLUMN($AM11:$BJ11),4)=MOD(COLUMN($AM11)+0,4)),$AM11:$BJ11)*$I11 -> 0 | BN11: =SUMPRODUCT(--(MOD(COLUMN($O11:$AL11),4)=MOD(COLUMN($O11)+1,4)),$O11:$AL11) +SUMPRODUCT(--(MOD(COLUMN($AM11:$BJ11),4)=MOD(COLUMN($AM11)+1,4)),$AM11:$BJ11) -> 1000 | BO11: =SUMPRODUCT(--(MOD(COLUMN($O11:$AL11),4)=MOD(COLUMN($O11)+1,4)),$O11:$AL11)*$I11 +SUMPRODUCT(--(MOD(COLUMN($AM11:$BJ11),4)=MOD(COLUMN($AM11)+1,4)),$AM11:$BJ11)*$I11 -> 311650 | BP11: =SUMPRODUCT(--(MOD(COLUMN($O11:$AL11),4)=MOD(COLUMN($O11)+2,4)),$O11:$AL11) +SUMPRODUCT(--(MOD(COLUMN($AM11:$BJ11),4)=MOD(COLUMN($AM11)+2,4)),$AM11:$BJ11) -> 0 | BQ11: =SUMPRODUCT(--(MOD(COLUMN($O11:$AL11),4)=MOD(COLUMN($O11)+2,4)),$O11:$AL11)*$I11 +SUMPRODUCT(--(MOD(COLUMN($AM11:$BJ11),4)=MOD(COLUMN($AM11)+2,4)),$AM11:$BJ11)*$I11 -> 0 | BT11: 1388 | BX11: 1388 | CB11: 1388 | CF11: 1388 | CJ11: 1388 | CN11: 1388 | CR11: 1388 | CV11: 1388 | CZ11: 1388 | DD11: 1388 | DH11: 1388 | DL11: 1388 | DQ11: =SUMPRODUCT(--(MOD(COLUMN(BT11:CQ11),4)=MOD(COLUMN(BT11),4)),BT11:CQ11)+SUMPRODUCT(--(MOD(COLUMN(CR11:DO11),4)=MOD(COLUMN(CR11),4)),CR11:DO11) -> 16656 | DR11: =SUMPRODUCT(--(MOD(COLUMN(BT11:CQ11),4)=MOD(COLUMN(BT11),4)),BT11:CQ11)*#REF!+SUMPRODUCT(--(MOD(COLUMN(CR11:DO11),4)=MOD(COLUMN(CR11),4)),CR11:DO11)*#REF! -> #REF! | DU11: 2776 | DY11: 2776 | EC11: 2776 | EG11: 2776 | EK11: 2776 | EO11: 2776 | ES11: 2776 | EW11: 2776 | FA11: 2776 | FE11: 2776 | FI11: 2776 | FM11: 2776 | FR11: =SUMPRODUCT(--(MOD(COLUMN(DU11:ER11),4)=MOD(COLUMN(DU11),4)),DU11:ER11)+SUMPRODUCT(--(MOD(COLUMN(ES11:FP11),4)=MOD(COLUMN(ES11),4)),ES11:FP11) -> 33312 | FS11: =SUMPRODUCT(--(MOD(COLUMN(DU11:ER11),4)=MOD(COLUMN(DU11),4)),DU11:ER11)*#REF!+SUMPRODUCT(--(MOD(COLUMN(ES11:FP11),4)=MOD(COLUMN(ES11),4)),ES11:FP11)*#REF! -> #REF!
A12: АВТОКОМПОНЕНТ НАО | B12: Предоплата 50% | C12: ВБК Восток | D12: Прасолов, Соловьёв | E12: =IF(ISBLANK(G12),"",IF($A$6:$A$64=$A12,COUNTIF($A$6:A12,$A12),"")) -> 7 | F12: 1 | G12: S4240002000 | H12: Комплект удлинения | I12: =65.4/НДС_20 -> 54.5 | L12: =IF(K12="RUB",J12/ЮАНЬ,IF(K12="EUR",J12*ЕВРО/ЮАНЬ,"")) | N12: =IF(BP12>0,1,IF(BN12>0,2,)) -> 0 | U12: 0 | BL12: =SUMPRODUCT(--(MOD(COLUMN($O12:$AL12),4)=MOD(COLUMN($O12)+0,4)),$O12:$AL12) +SUMPRODUCT(--(MOD(COLUMN($AM12:$BJ12),4)=MOD(COLUMN($AM12)+0,4)),$AM12:$BJ12) -> 0 | BM12: =SUMPRODUCT(--(MOD(COLUMN($O12:$AL12),4)=MOD(COLUMN($O12)+0,4)),$O12:$AL12)*$I12 +SUMPRODUCT(--(MOD(COLUMN($AM12:$BJ12),4)=MOD(COLUMN($AM12)+0,4)),$AM12:$BJ12)*$I12 -> 0 | BN12: =SUMPRODUCT(--(MOD(COLUMN($O12:$AL12),4)=MOD(COLUMN($O12)+1,4)),$O12:$AL12) +SUMPRODUCT(--(MOD(COLUMN($AM12:$BJ12),4)=MOD(COLUMN($AM12)+1,4)),$AM12:$BJ12) -> 0 | BO12: =SUMPRODUCT(--(MOD(COLUMN($O12:$AL12),4)=MOD(COLUMN($O12)+1,4)),$O12:$AL12)*$I12 +SUMPRODUCT(--(MOD(COLUMN($AM12:$BJ12),4)=MOD(COLUMN($AM12)+1,4)),$AM12:$BJ12)*$I12 -> 0 | BP12: =SUMPRODUCT(--(MOD(COLUMN($O12:$AL12),4)=MOD(COLUMN($O12)+2,4)),$O12:$AL12) +SUMPRODUCT(--(MOD(COLUMN($AM12:$BJ12),4)=MOD(COLUMN($AM12)+2,4)),$AM12:$BJ12) -> 0 | BQ12: =SUMPRODUCT(--(MOD(COLUMN($O12:$AL12),4)=MOD(COLUMN($O12)+2,4)),$O12:$AL12)*$I12 +SUMPRODUCT(--(MOD(COLUMN($AM12:$BJ12),4)=MOD(COLUMN($AM12)+2,4)),$AM12:$BJ12)*$I12 -> 0 | DQ12: =SUMPRODUCT(--(MOD(COLUMN(BT12:CQ12),4)=MOD(COLUMN(BT12),4)),BT12:CQ12)+SUMPRODUCT(--(MOD(COLUMN(CR12:DO12),4)=MOD(COLUMN(CR12),4)),CR12:DO12) -> 0 | DR12: =SUMPRODUCT(--(MOD(COLUMN(BT12:CQ12),4)=MOD(COLUMN(BT12),4)),BT12:CQ12)*#REF!+SUMPRODUCT(--(MOD(COLUMN(CR12:DO12),4)=MOD(COLUMN(CR12),4)),CR12:DO12)*#REF! -> #REF! | FR12: =SUMPRODUCT(--(MOD(COLUMN(DU12:ER12),4)=MOD(COLUMN(DU12),4)),DU12:ER12)+SUMPRODUCT(--(MOD(COLUMN(ES12:FP12),4)=MOD(COLUMN(ES12),4)),ES12:FP12) -> 0 | FS12: =SUMPRODUCT(--(MOD(COLUMN(DU12:ER12),4)=MOD(COLUMN(DU12),4)),DU12:ER12)*#REF!+SUMPRODUCT(--(MOD(COLUMN(ES12:FP12),4)=MOD(COLUMN(ES12),4)),ES12:FP12)*#REF! -> #REF!
A13: АВТОКОМПОНЕНТ НАО | E13: =IF(ISBLANK(G13),"",IF($A$6:$A$64=$A13,COUNTIF($A$6:A13,$A13),"")) | H13: Итого | L13: =IF(K13="RUB",J13/ЮАНЬ,IF(K13="EUR",J13*ЕВРО/ЮАНЬ,"")) | N13: =IF(BP13>0,1,IF(BN13>0,2,)) -> 0 | BL13: =SUMPRODUCT(--(MOD(COLUMN($O13:$AL13),4)=MOD(COLUMN($O13)+0,4)),$O13:$AL13) +SUMPRODUCT(--(MOD(COLUMN($AM13:$BJ13),4)=MOD(COLUMN($AM13)+0,4)),$AM13:$BJ13) -> 0 | BM13: =SUMPRODUCT(--(MOD(COLUMN($O13:$AL13),4)=MOD(COLUMN($O13)+0,4)),$O13:$AL13)*$I13 +SUMPRODUCT(--(MOD(COLUMN($AM13:$BJ13),4)=MOD(COLUMN($AM13)+0,4)),$AM13:$BJ13)*$I13 -> 0 | BN13: =SUMPRODUCT(--(MOD(COLUMN($O13:$AL13),4)=MOD(COLUMN($O13)+1,4)),$O13:$AL13) +SUMPRODUCT(--(MOD(COLUMN($AM13:$BJ13),4)=MOD(COLUMN($AM13)+1,4)),$AM13:$BJ13) -> 0 | BO13: =SUMPRODUCT(--(MOD(COLUMN($O13:$AL13),4)=MOD(COLUMN($O13)+1,4)),$O13:$AL13)*$I13 +SUMPRODUCT(--(MOD(COLUMN($AM13:$BJ13),4)=MOD(COLUMN($AM13)+1,4)),$AM13:$BJ13)*$I13 -> 0 | BP13: =SUMPRODUCT(--(MOD(COLUMN($O13:$AL13),4)=MOD(COLUMN($O13)+2,4)),$O13:$AL13) +SUMPRODUCT(--(MOD(COLUMN($AM13:$BJ13),4)=MOD(COLUMN($AM13)+2,4)),$AM13:$BJ13) -> 0 | BQ13: =SUMPRODUCT(--(MOD(COLUMN($O13:$AL13),4)=MOD(COLUMN($O13)+2,4)),$O13:$AL13)*$I13 +SUMPRODUCT(--(MOD(COLUMN($AM13:$BJ13),4)=MOD(COLUMN($AM13)+2,4)),$AM13:$BJ13)*$I13 -> 0 | DQ13: =SUMPRODUCT(--(MOD(COLUMN(BT13:CQ13),4)=MOD(COLUMN(BT13),4)),BT13:CQ13)+SUMPRODUCT(--(MOD(COLUMN(CR13:DO13),4)=MOD(COLUMN(CR13),4)),CR13:DO13) -> 0 | DR13: =SUMPRODUCT(--(MOD(COLUMN(BT13:CQ13),4)=MOD(COLUMN(BT13),4)),BT13:CQ13)*#REF!+SUMPRODUCT(--(MOD(COLUMN(CR13:DO13),4)=MOD(COLUMN(CR13),4)),CR13:DO13)*#REF! -> #REF! | FR13: =SUMPRODUCT(--(MOD(COLUMN(DU13:ER13),4)=MOD(COLUMN(DU13),4)),DU13:ER13)+SUMPRODUCT(--(MOD(COLUMN(ES13:FP13),4)=MOD(COLUMN(ES13),4)),ES13:FP13) -> 0 | FS13: =SUMPRODUCT(--(MOD(COLUMN(DU13:ER13),4)=MOD(COLUMN(DU13),4)),DU13:ER13)*#REF!+SUMPRODUCT(--(MOD(COLUMN(ES13:FP13),4)=MOD(COLUMN(ES13),4)),ES13:FP13)*#REF! -> #REF!
A14: АВТОКОМПОНЕНТ НАО | E14: =IF(ISBLANK(G14),"",IF($A$6:$A$64=$A14,COUNTIF($A$6:A14,$A14),"")) | L14: =IF(K14="RUB",J14/ЮАНЬ,IF(K14="EUR",J14*ЕВРО/ЮАНЬ,"")) | N14: =IF(BP14>0,1,IF(BN14>0,2,)) -> 0 | BL14: =SUMPRODUCT(--(MOD(COLUMN($O14:$AL14),4)=MOD(COLUMN($O14)+0,4)),$O14:$AL14) +SUMPRODUCT(--(MOD(COLUMN($AM14:$BJ14),4)=MOD(COLUMN($AM14)+0,4)),$AM14:$BJ14) -> 0 | BM14: =SUMPRODUCT(--(MOD(COLUMN($O14:$AL14),4)=MOD(COLUMN($O14)+0,4)),$O14:$AL14)*$I14 +SUMPRODUCT(--(MOD(COLUMN($AM14:$BJ14),4)=MOD(COLUMN($AM14)+0,4)),$AM14:$BJ14)*$I14 -> 0 | BN14: =SUMPRODUCT(--(MOD(COLUMN($O14:$AL14),4)=MOD(COLUMN($O14)+1,4)),$O14:$AL14) +SUMPRODUCT(--(MOD(COLUMN($AM14:$BJ14),4)=MOD(COLUMN($AM14)+1,4)),$AM14:$BJ14) -> 0 | BO14: =SUMPRODUCT(--(MOD(COLUMN($O14:$AL14),4)=MOD(COLUMN($O14)+1,4)),$O14:$AL14)*$I14 +SUMPRODUCT(--(MOD(COLUMN($AM14:$BJ14),4)=MOD(COLUMN($AM14)+1,4)),$AM14:$BJ14)*$I14 -> 0 | BP14: =SUMPRODUCT(--(MOD(COLUMN($O14:$AL14),4)=MOD(COLUMN($O14)+2,4)),$O14:$AL14) +SUMPRODUCT(--(MOD(COLUMN($AM14:$BJ14),4)=MOD(COLUMN($AM14)+2,4)),$AM14:$BJ14) -> 0 | BQ14: =SUMPRODUCT(--(MOD(COLUMN($O14:$AL14),4)=MOD(COLUMN($O14)+2,4)),$O14:$AL14)*$I14 +SUMPRODUCT(--(MOD(COLUMN($AM14:$BJ14),4)=MOD(COLUMN($AM14)+2,4)),$AM14:$BJ14)*$I14 -> 0 | DQ14: =SUMPRODUCT(--(MOD(COLUMN(BT14:CQ14),4)=MOD(COLUMN(BT14),4)),BT14:CQ14)+SUMPRODUCT(--(MOD(COLUMN(CR14:DO14),4)=MOD(COLUMN(CR14),4)),CR14:DO14) -> 0 | DR14: =SUMPRODUCT(--(MOD(COLUMN(BT14:CQ14),4)=MOD(COLUMN(BT14),4)),BT14:CQ14)*#REF!+SUMPRODUCT(--(MOD(COLUMN(CR14:DO14),4)=MOD(COLUMN(CR14),4)),CR14:DO14)*#REF! -> #REF! | FR14: =SUMPRODUCT(--(MOD(COLUMN(DU14:ER14),4)=MOD(COLUMN(DU14),4)),DU14:ER14)+SUMPRODUCT(--(MOD(COLUMN(ES14:FP14),4)=MOD(COLUMN(ES14),4)),ES14:FP14) -> 0 | FS14: =SUMPRODUCT(--(MOD(COLUMN(DU14:ER14),4)=MOD(COLUMN(DU14),4)),DU14:ER14)*#REF!+SUMPRODUCT(--(MOD(COLUMN(ES14:FP14),4)=MOD(COLUMN(ES14),4)),ES14:FP14)*#REF! -> #REF!
A15: BPW (нет в системе) | B15: Договор не подписан | C15: ВБК Восток | D15: Прасолов, Соловьёв | E15: =IF(ISBLANK(G15),"",IF($A$6:$A$64=$A15,COUNTIF($A$6:A15,$A15),"")) -> 1 | F15: 1 | G15: 6402250560 | H15: 6402250560 AA Тормоз дисковый ( левый ) | I15: =2100/НДС_20 -> 1750 | L15: =IF(K15="RUB",J15/ЮАНЬ,IF(K15="EUR",J15*ЕВРО/ЮАНЬ,"")) | N15: =IF(BP15>0,1,IF(BN15>0,2,)) -> 0 | U15: 0 | BL15: =SUMPRODUCT(--(MOD(COLUMN($O15:$AL15),4)=MOD(COLUMN($O15)+0,4)),$O15:$AL15) +SUMPRODUCT(--(MOD(COLUMN($AM15:$BJ15),4)=MOD(COLUMN($AM15)+0,4)),$AM15:$BJ15) -> 0 | BM15: =SUMPRODUCT(--(MOD(COLUMN($O15:$AL15),4)=MOD(COLUMN($O15)+0,4)),$O15:$AL15)*$I15 +SUMPRODUCT(--(MOD(COLUMN($AM15:$BJ15),4)=MOD(COLUMN($AM15)+0,4)),$AM15:$BJ15)*$I15 -> 0 | BN15: =SUMPRODUCT(--(MOD(COLUMN($O15:$AL15),4)=MOD(COLUMN($O15)+1,4)),$O15:$AL15) +SUMPRODUCT(--(MOD(COLUMN($AM15:$BJ15),4)=MOD(COLUMN($AM15)+1,4)),$AM15:$BJ15) -> 0 | BO15: =SUMPRODUCT(--(MOD(COLUMN($O15:$AL15),4)=MOD(COLUMN($O15)+1,4)),$O15:$AL15)*$I15 +SUMPRODUCT(--(MOD(COLUMN($AM15:$BJ15),4)=MOD(COLUMN($AM15)+1,4)),$AM15:$BJ15)*$I15 -> 0 | BP15: =SUMPRODUCT(--(MOD(COLUMN($O15:$AL15),4)=MOD(COLUMN($O15)+2,4)),$O15:$AL15) +SUMPRODUCT(--(MOD(COLUMN($AM15:$BJ15),4)=MOD(COLUMN($AM15)+2,4)),$AM15:$BJ15) -> 0 | BQ15: =SUMPRODUCT(--(MOD(COLUMN($O15:$AL15),4)=MOD(COLUMN($O15)+2,4)),$O15:$AL15)*$I15 +SUMPRODUCT(--(MOD(COLUMN($AM15:$BJ15),4)=MOD(COLUMN($AM15)+2,4)),$AM15:$BJ15)*$I15 -> 0 | BT15: 207 | BX15: 207 | CB15: 207 | CF15: 207 | CJ15: 207 | CN15: 207 | CR15: 207 | CV15: 207 | CZ15: 207 | DD15: 207 | DH15: 207 | DL15: 207 | DQ15: =SUMPRODUCT(--(MOD(COLUMN(BT15:CQ15),4)=MOD(COLUMN(BT15),4)),BT15:CQ15)+SUMPRODUCT(--(MOD(COLUMN(CR15:DO15),4)=MOD(COLUMN(CR15),4)),CR15:DO15) -> 2484 | DR15: =SUMPRODUCT(--(MOD(COLUMN(BT15:CQ15),4)=MOD(COLUMN(BT15),4)),BT15:CQ15)*#REF!+SUMPRODUCT(--(MOD(COLUMN(CR15:DO15),4)=MOD(COLUMN(CR15),4)),CR15:DO15)*#REF! -> #REF! | DU15: 414 | DY15: 414 | EC15: 414 | EG15: 414 | EK15: 414 | EO15: 414 | ES15: 414 | EW15: 414 | FA15: 414 | FE15: 414 | FI15: 414 | FM15: 414 | FR15: =SUMPRODUCT(--(MOD(COLUMN(DU15:ER15),4)=MOD(COLUMN(DU15),4)),DU15:ER15)+SUMPRODUCT(--(MOD(COLUMN(ES15:FP15),4)=MOD(COLUMN(ES15),4)),ES15:FP15) -> 4968 | FS15: =SUMPRODUCT(--(MOD(COLUMN(DU15:ER15),4)=MOD(COLUMN(DU15),4)),DU15:ER15)*#REF!+SUMPRODUCT(--(MOD(COLUMN(ES15:FP15),4)=MOD(COLUMN(ES15),4)),ES15:FP15)*#REF! -> #REF!
A16: BPW (нет в системе) | B16: Договор не подписан | C16: ВБК Восток | D16: Прасолов, Соловьёв | E16: =IF(ISBLANK(G16),"",IF($A$6:$A$64=$A16,COUNTIF($A$6:A16,$A16),"")) -> 2 | F16: 1 | G16: 6402250570 | H16: 6402250570 AA Тормоз дисковый ( правый ) | I16: =I15 -> 1750 | L16: =IF(K16="RUB",J16/ЮАНЬ,IF(K16="EUR",J16*ЕВРО/ЮАНЬ,"")) | N16: =IF(BP16>0,1,IF(BN16>0,2,)) -> 0 | U16: 0 | BL16: =SUMPRODUCT(--(MOD(COLUMN($O16:$AL16),4)=MOD(COLUMN($O16)+0,4)),$O16:$AL16) +SUMPRODUCT(--(MOD(COLUMN($AM16:$BJ16),4)=MOD(COLUMN($AM16)+0,4)),$AM16:$BJ16) -> 0 | BM16: =SUMPRODUCT(--(MOD(COLUMN($O16:$AL16),4)=MOD(COLUMN($O16)+0,4)),$O16:$AL16)*$I16 +SUMPRODUCT(--(MOD(COLUMN($AM16:$BJ16),4)=MOD(COLUMN($AM16)+0,4)),$AM16:$BJ16)*$I16 -> 0 | BN16: =SUMPRODUCT(--(MOD(COLUMN($O16:$AL16),4)=MOD(COLUMN($O16)+1,4)),$O16:$AL16) +SUMPRODUCT(--(MOD(COLUMN($AM16:$BJ16),4)=MOD(COLUMN($AM16)+1,4)),$AM16:$BJ16) -> 0 | BO16: =SUMPRODUCT(--(MOD(COLUMN($O16:$AL16),4)=MOD(COLUMN($O16)+1,4)),$O16:$AL16)*$I16 +SUMPRODUCT(--(MOD(COLUMN($AM16:$BJ16),4)=MOD(COLUMN($AM16)+1,4)),$AM16:$BJ16)*$I16 -> 0 | BP16: =SUMPRODUCT(--(MOD(COLUMN($O16:$AL16),4)=MOD(COLUMN($O16)+2,4)),$O16:$AL16) +SUMPRODUCT(--(MOD(COLUMN($AM16:$BJ16),4)=MOD(COLUMN($AM16)+2,4)),$AM16:$BJ16) -> 0 | BQ16: =SUMPRODUCT(--(MOD(COLUMN($O16:$AL16),4)=MOD(COLUMN($O16)+2,4)),$O16:$AL16)*$I16 +SUMPRODUCT(--(MOD(COLUMN($AM16:$BJ16),4)=MOD(COLUMN($AM16)+2,4)),$AM16:$BJ16)*$I16 -> 0 | BT16: 207 | BX16: 207 | CB16: 207 | CF16: 207 | CJ16: 207 | CN16: 207 | CR16: 207 | CV16: 207 | CZ16: 207 | DD16: 207 | DH16: 207 | DL16: 207 | DQ16: =SUMPRODUCT(--(MOD(COLUMN(BT16:CQ16),4)=MOD(COLUMN(BT16),4)),BT16:CQ16)+SUMPRODUCT(--(MOD(COLUMN(CR16:DO16),4)=MOD(COLUMN(CR16),4)),CR16:DO16) -> 2484 | DR16: =SUMPRODUCT(--(MOD(COLUMN(BT16:CQ16),4)=MOD(COLUMN(BT16),4)),BT16:CQ16)*#REF!+SUMPRODUCT(--(MOD(COLUMN(CR16:DO16),4)=MOD(COLUMN(CR16),4)),CR16:DO16)*#REF! -> #REF! | DU16: 414 | DY16: 414 | EC16: 414 | EG16: 414 | EK16: 414 | EO16: 414 | ES16: 414 | EW16: 414 | FA16: 414 | FE16: 414 | FI16: 414 | FM16: 414 | FR16: =SUMPRODUCT(--(MOD(COLUMN(DU16:ER16),4)=MOD(COLUMN(DU16),4)),DU16:ER16)+SUMPRODUCT(--(MOD(COLUMN(ES16:FP16),4)=MOD(COLUMN(ES16),4)),ES16:FP16) -> 4968 | FS16: =SUMPRODUCT(--(MOD(COLUMN(DU16:ER16),4)=MOD(COLUMN(DU16),4)),DU16:ER16)*#REF!+SUMPRODUCT(--(MOD(COLUMN(ES16:FP16),4)=MOD(COLUMN(ES16),4)),ES16:FP16)*#REF! -> #REF!
A17: BPW (нет в системе) | B17: Договор не подписан | C17: ВБК Восток | D17: Прасолов, Соловьёв | E17: =IF(ISBLANK(G17),"",IF($A$6:$A$64=$A17,COUNTIF($A$6:A17,$A17),"")) -> 3 | F17: 1 | G17: 4410328080 | H17: Датчик АБС, 0,4 м | I17: =84/НДС_20 -> 70 | L17: =IF(K17="RUB",J17/ЮАНЬ,IF(K17="EUR",J17*ЕВРО/ЮАНЬ,"")) | N17: =IF(BP17>0,1,IF(BN17>0,2,)) -> 0 | U17: 0 | BL17: =SUMPRODUCT(--(MOD(COLUMN($O17:$AL17),4)=MOD(COLUMN($O17)+0,4)),$O17:$AL17) +SUMPRODUCT(--(MOD(COLUMN($AM17:$BJ17),4)=MOD(COLUMN($AM17)+0,4)),$AM17:$BJ17) -> 0 | BM17: =SUMPRODUCT(--(MOD(COLUMN($O17:$AL17),4)=MOD(COLUMN($O17)+0,4)),$O17:$AL17)*$I17 +SUMPRODUCT(--(MOD(COLUMN($AM17:$BJ17),4)=MOD(COLUMN($AM17)+0,4)),$AM17:$BJ17)*$I17 -> 0 | BN17: =SUMPRODUCT(--(MOD(COLUMN($O17:$AL17),4)=MOD(COLUMN($O17)+1,4)),$O17:$AL17) +SUMPRODUCT(--(MOD(COLUMN($AM17:$BJ17),4)=MOD(COLUMN($AM17)+1,4)),$AM17:$BJ17) -> 0 | BO17: =SUMPRODUCT(--(MOD(COLUMN($O17:$AL17),4)=MOD(COLUMN($O17)+1,4)),$O17:$AL17)*$I17 +SUMPRODUCT(--(MOD(COLUMN($AM17:$BJ17),4)=MOD(COLUMN($AM17)+1,4)),$AM17:$BJ17)*$I17 -> 0 | BP17: =SUMPRODUCT(--(MOD(COLUMN($O17:$AL17),4)=MOD(COLUMN($O17)+2,4)),$O17:$AL17) +SUMPRODUCT(--(MOD(COLUMN($AM17:$BJ17),4)=MOD(COLUMN($AM17)+2,4)),$AM17:$BJ17) -> 0 | BQ17: =SUMPRODUCT(--(MOD(COLUMN($O17:$AL17),4)=MOD(COLUMN($O17)+2,4)),$O17:$AL17)*$I17 +SUMPRODUCT(--(MOD(COLUMN($AM17:$BJ17),4)=MOD(COLUMN($AM17)+2,4)),$AM17:$BJ17)*$I17 -> 0 | BT17: 138 | BX17: 138 | CB17: 138 | CF17: 138 | CJ17: 138 | CN17: 138 | CR17: 138 | CV17: 138 | CZ17: 138 | DD17: 138 | DH17: 138 | DL17: 138 | DQ17: =SUMPRODUCT(--(MOD(COLUMN(BT17:CQ17),4)=MOD(COLUMN(BT17),4)),BT17:CQ17)+SUMPRODUCT(--(MOD(COLUMN(CR17:DO17),4)=MOD(COLUMN(CR17),4)),CR17:DO17) -> 1656 | DR17: =SUMPRODUCT(--(MOD(COLUMN(BT17:CQ17),4)=MOD(COLUMN(BT17),4)),BT17:CQ17)*#REF!+SUMPRODUCT(--(MOD(COLUMN(CR17:DO17),4)=MOD(COLUMN(CR17),4)),CR17:DO17)*#REF! -> #REF! | DU17: 276 | DY17: 276 | EC17: 276 | EG17: 276 | EK17: 276 | EO17: 276 | ES17: 276 | EW17: 276 | FA17: 276 | FE17: 276 | FI17: 276 | FM17: 276 | FR17: =SUMPRODUCT(--(MOD(COLUMN(DU17:ER17),4)=MOD(COLUMN(DU17),4)),DU17:ER17)+SUMPRODUCT(--(MOD(COLUMN(ES17:FP17),4)=MOD(COLUMN(ES17),4)),ES17:FP17) -> 3312 | FS17: =SUMPRODUCT(--(MOD(COLUMN(DU17:ER17),4)=MOD(COLUMN(DU17),4)),DU17:ER17)*#REF!+SUMPRODUCT(--(MOD(COLUMN(ES17:FP17),4)=MOD(COLUMN(ES17),4)),ES17:FP17)*#REF! -> #REF!
A18: BPW (нет в системе) | B18: Договор не подписан | C18: ВБК Восток | D18: Прасолов, Соловьёв | E18: =IF(ISBLANK(G18),"",IF($A$6:$A$64=$A18,COUNTIF($A$6:A18,$A18),"")) -> 4 | F18: 1 | G18: 8997598154 | H18: Втулка датчика АБС | I18: =8.4/НДС_20 -> 7 | L18: =IF(K18="RUB",J18/ЮАНЬ,IF(K18="EUR",J18*ЕВРО/ЮАНЬ,"")) | N18: =IF(BP18>0,1,IF(BN18>0,2,)) -> 0 | U18: 0 | BL18: =SUMPRODUCT(--(MOD(COLUMN($O18:$AL18),4)=MOD(COLUMN($O18)+0,4)),$O18:$AL18) +SUMPRODUCT(--(MOD(COLUMN($AM18:$BJ18),4)=MOD(COLUMN($AM18)+0,4)),$AM18:$BJ18) -> 0 | BM18: =SUMPRODUCT(--(MOD(COLUMN($O18:$AL18),4)=MOD(COLUMN($O18)+0,4)),$O18:$AL18)*$I18 +SUMPRODUCT(--(MOD(COLUMN($AM18:$BJ18),4)=MOD(COLUMN($AM18)+0,4)),$AM18:$BJ18)*$I18 -> 0 | BN18: =SUMPRODUCT(--(MOD(COLUMN($O18:$AL18),4)=MOD(COLUMN($O18)+1,4)),$O18:$AL18) +SUMPRODUCT(--(MOD(COLUMN($AM18:$BJ18),4)=MOD(COLUMN($AM18)+1,4)),$AM18:$BJ18) -> 0 | BO18: =SUMPRODUCT(--(MOD(COLUMN($O18:$AL18),4)=MOD(COLUMN($O18)+1,4)),$O18:$AL18)*$I18 +SUMPRODUCT(--(MOD(COLUMN($AM18:$BJ18),4)=MOD(COLUMN($AM18)+1,4)),$AM18:$BJ18)*$I18 -> 0 | BP18: =SUMPRODUCT(--(MOD(COLUMN($O18:$AL18),4)=MOD(COLUMN($O18)+2,4)),$O18:$AL18) +SUMPRODUCT(--(MOD(COLUMN($AM18:$BJ18),4)=MOD(COLUMN($AM18)+2,4)),$AM18:$BJ18) -> 0 | BQ18: =SUMPRODUCT(--(MOD(COLUMN($O18:$AL18),4)=MOD(COLUMN($O18)+2,4)),$O18:$AL18)*$I18 +SUMPRODUCT(--(MOD(COLUMN($AM18:$BJ18),4)=MOD(COLUMN($AM18)+2,4)),$AM18:$BJ18)*$I18 -> 0 | BT18: 138 | BX18: 138 | CB18: 138 | CF18: 138 | CJ18: 138 | CN18: 138 | CR18: 138 | CV18: 138 | CZ18: 138 | DD18: 138 | DH18: 138 | DL18: 138 | DQ18: =SUMPRODUCT(--(MOD(COLUMN(BT18:CQ18),4)=MOD(COLUMN(BT18),4)),BT18:CQ18)+SUMPRODUCT(--(MOD(COLUMN(CR18:DO18),4)=MOD(COLUMN(CR18),4)),CR18:DO18) -> 1656 | DR18: =SUMPRODUCT(--(MOD(COLUMN(BT18:CQ18),4)=MOD(COLUMN(BT18),4)),BT18:CQ18)*#REF!+SUMPRODUCT(--(MOD(COLUMN(CR18:DO18),4)=MOD(COLUMN(CR18),4)),CR18:DO18)*#REF! -> #REF! | DU18: 276 | DY18: 276 | EC18: 276 | EG18: 276 | EK18: 276 | EO18: 276 | ES18: 276 | EW18: 276 | FA18: 276 | FE18: 276 | FI18: 276 | FM18: 276 | FR18: =SUMPRODUCT(--(MOD(COLUMN(DU18:ER18),4)=MOD(COLUMN(DU18),4)),DU18:ER18)+SUMPRODUCT(--(MOD(COLUMN(ES18:FP18),4)=MOD(COLUMN(ES18),4)),ES18:FP18) -> 3312 | FS18: =SUMPRODUCT(--(MOD(COLUMN(DU18:ER18),4)=MOD(COLUMN(DU18),4)),DU18:ER18)*#REF!+SUMPRODUCT(--(MOD(COLUMN(ES18:FP18),4)=MOD(COLUMN(ES18),4)),ES18:FP18)*#REF! -> #REF!
A19: BPW (нет в системе) | B19: Договор не подписан | C19: ВБК Восток | D19: Прасолов, Соловьёв | E19: =IF(ISBLANK(G19),"",IF($A$6:$A$64=$A19,COUNTIF($A$6:A19,$A19),"")) -> 5 | F19: 1 | G19: 4235041001 | H19: Тормозная камера, тип 20 | I19: =163.08/НДС_20 -> 135.9 | L19: =IF(K19="RUB",J19/ЮАНЬ,IF(K19="EUR",J19*ЕВРО/ЮАНЬ,"")) | N19: =IF(BP19>0,1,IF(BN19>0,2,)) -> 0 | U19: 0 | BL19: =SUMPRODUCT(--(MOD(COLUMN($O19:$AL19),4)=MOD(COLUMN($O19)+0,4)),$O19:$AL19) +SUMPRODUCT(--(MOD(COLUMN($AM19:$BJ19),4)=MOD(COLUMN($AM19)+0,4)),$AM19:$BJ19) -> 0 | BM19: =SUMPRODUCT(--(MOD(COLUMN($O19:$AL19),4)=MOD(COLUMN($O19)+0,4)),$O19:$AL19)*$I19 +SUMPRODUCT(--(MOD(COLUMN($AM19:$BJ19),4)=MOD(COLUMN($AM19)+0,4)),$AM19:$BJ19)*$I19 -> 0 | BN19: =SUMPRODUCT(--(MOD(COLUMN($O19:$AL19),4)=MOD(COLUMN($O19)+1,4)),$O19:$AL19) +SUMPRODUCT(--(MOD(COLUMN($AM19:$BJ19),4)=MOD(COLUMN($AM19)+1,4)),$AM19:$BJ19) -> 0 | BO19: =SUMPRODUCT(--(MOD(COLUMN($O19:$AL19),4)=MOD(COLUMN($O19)+1,4)),$O19:$AL19)*$I19 +SUMPRODUCT(--(MOD(COLUMN($AM19:$BJ19),4)=MOD(COLUMN($AM19)+1,4)),$AM19:$BJ19)*$I19 -> 0 | BP19: =SUMPRODUCT(--(MOD(COLUMN($O19:$AL19),4)=MOD(COLUMN($O19)+2,4)),$O19:$AL19) +SUMPRODUCT(--(MOD(COLUMN($AM19:$BJ19),4)=MOD(COLUMN($AM19)+2,4)),$AM19:$BJ19) -> 0 | BQ19: =SUMPRODUCT(--(MOD(COLUMN($O19:$AL19),4)=MOD(COLUMN($O19)+2,4)),$O19:$AL19)*$I19 +SUMPRODUCT(--(MOD(COLUMN($AM19:$BJ19),4)=MOD(COLUMN($AM19)+2,4)),$AM19:$BJ19)*$I19 -> 0 | BT19: 138 | BX19: 138 | CB19: 138 | CF19: 138 | CJ19: 138 | CN19: 138 | CR19: 138 | CV19: 138 | CZ19: 138 | DD19: 138 | DH19: 138 | DL19: 138 | DQ19: =SUMPRODUCT(--(MOD(COLUMN(BT19:CQ19),4)=MOD(COLUMN(BT19),4)),BT19:CQ19)+SUMPRODUCT(--(MOD(COLUMN(CR19:DO19),4)=MOD(COLUMN(CR19),4)),CR19:DO19) -> 1656 | DR19: =SUMPRODUCT(--(MOD(COLUMN(BT19:CQ19),4)=MOD(COLUMN(BT19),4)),BT19:CQ19)*#REF!+SUMPRODUCT(--(MOD(COLUMN(CR19:DO19),4)=MOD(COLUMN(CR19),4)),CR19:DO19)*#REF! -> #REF! | DU19: 276 | DY19: 276 | EC19: 276 | EG19: 276 | EK19: 276 | EO19: 276 | ES19: 276 | EW19: 276 | FA19: 276 | FE19: 276 | FI19: 276 | FM19: 276 | FR19: =SUMPRODUCT(--(MOD(COLUMN(DU19:ER19),4)=MOD(COLUMN(DU19),4)),DU19:ER19)+SUMPRODUCT(--(MOD(COLUMN(ES19:FP19),4)=MOD(COLUMN(ES19),4)),ES19:FP19) -> 3312 | FS19: =SUMPRODUCT(--(MOD(COLUMN(DU19:ER19),4)=MOD(COLUMN(DU19),4)),DU19:ER19)*#REF!+SUMPRODUCT(--(MOD(COLUMN(ES19:FP19),4)=MOD(COLUMN(ES19),4)),ES19:FP19)*#REF! -> #REF!
A20: BPW (нет в системе) | B20: Договор не подписан | C20: ВБК Восток | D20: Прасолов, Соловьёв | E20: =IF(ISBLANK(G20),"",IF($A$6:$A$64=$A20,COUNTIF($A$6:A20,$A20),"")) -> 6 | F20: 1 | G20: 9254800504 | H20: Энергоаккумулятор, тип 20/24 | I20: =373.98/НДС_20 -> 311.65 | L20: =IF(K20="RUB",J20/ЮАНЬ,IF(K20="EUR",J20*ЕВРО/ЮАНЬ,"")) | N20: =IF(BP20>0,1,IF(BN20>0,2,)) -> 0 | U20: 0 | BL20: =SUMPRODUCT(--(MOD(COLUMN($O20:$AL20),4)=MOD(COLUMN($O20)+0,4)),$O20:$AL20) +SUMPRODUCT(--(MOD(COLUMN($AM20:$BJ20),4)=MOD(COLUMN($AM20)+0,4)),$AM20:$BJ20) -> 0 | BM20: =SUMPRODUCT(--(MOD(COLUMN($O20:$AL20),4)=MOD(COLUMN($O20)+0,4)),$O20:$AL20)*$I20 +SUMPRODUCT(--(MOD(COLUMN($AM20:$BJ20),4)=MOD(COLUMN($AM20)+0,4)),$AM20:$BJ20)*$I20 -> 0 | BN20: =SUMPRODUCT(--(MOD(COLUMN($O20:$AL20),4)=MOD(COLUMN($O20)+1,4)),$O20:$AL20) +SUMPRODUCT(--(MOD(COLUMN($AM20:$BJ20),4)=MOD(COLUMN($AM20)+1,4)),$AM20:$BJ20) -> 0 | BO20: =SUMPRODUCT(--(MOD(COLUMN($O20:$AL20),4)=MOD(COLUMN($O20)+1,4)),$O20:$AL20)*$I20 +SUMPRODUCT(--(MOD(COLUMN($AM20:$BJ20),4)=MOD(COLUMN($AM20)+1,4)),$AM20:$BJ20)*$I20 -> 0 | BP20: =SUMPRODUCT(--(MOD(COLUMN($O20:$AL20),4)=MOD(COLUMN($O20)+2,4)),$O20:$AL20) +SUMPRODUCT(--(MOD(COLUMN($AM20:$BJ20),4)=MOD(COLUMN($AM20)+2,4)),$AM20:$BJ20) -> 0 | BQ20: =SUMPRODUCT(--(MOD(COLUMN($O20:$AL20),4)=MOD(COLUMN($O20)+2,4)),$O20:$AL20)*$I20 +SUMPRODUCT(--(MOD(COLUMN($AM20:$BJ20),4)=MOD(COLUMN($AM20)+2,4)),$AM20:$BJ20)*$I20 -> 0 | BT20: 276 | BX20: 276 | CB20: 276 | CF20: 276 | CJ20: 276 | CN20: 276 | CR20: 276 | CV20: 276 | CZ20: 276 | DD20: 276 | DH20: 276 | DL20: 276 | DQ20: =SUMPRODUCT(--(MOD(COLUMN(BT20:CQ20),4)=MOD(COLUMN(BT20),4)),BT20:CQ20)+SUMPRODUCT(--(MOD(COLUMN(CR20:DO20),4)=MOD(COLUMN(CR20),4)),CR20:DO20) -> 3312 | DR20: =SUMPRODUCT(--(MOD(COLUMN(BT20:CQ20),4)=MOD(COLUMN(BT20),4)),BT20:CQ20)*#REF!+SUMPRODUCT(--(MOD(COLUMN(CR20:DO20),4)=MOD(COLUMN(CR20),4)),CR20:DO20)*#REF! -> #REF! | DU20: 552 | DY20: 552 | EC20: 552 | EG20: 552 | EK20: 552 | EO20: 552 | ES20: 552 | EW20: 552 | FA20: 552 | FE20: 552 | FI20: 552 | FM20: 552 | FR20: =SUMPRODUCT(--(MOD(COLUMN(DU20:ER20),4)=MOD(COLUMN(DU20),4)),DU20:ER20)+SUMPRODUCT(--(MOD(COLUMN(ES20:FP20),4)=MOD(COLUMN(ES20),4)),ES20:FP20) -> 6624 | FS20: =SUMPRODUCT(--(MOD(COLUMN(DU20:ER20),4)=MOD(COLUMN(DU20),4)),DU20:ER20)*#REF!+SUMPRODUCT(--(MOD(COLUMN(ES20:FP20),4)=MOD(COLUMN(ES20),4)),ES20:FP20)*#REF! -> #REF!
A21: BPW (нет в системе) | E21: =IF(ISBLANK(G21),"",IF($A$6:$A$64=$A21,COUNTIF($A$6:A21,$A21),"")) | H21: Итого | L21: =IF(K21="RUB",J21/ЮАНЬ,IF(K21="EUR",J21*ЕВРО/ЮАНЬ,"")) | N21: =IF(BP21>0,1,IF(BN21>0,2,)) -> 0 | BL21: =SUMPRODUCT(--(MOD(COLUMN($O21:$AL21),4)=MOD(COLUMN($O21)+0,4)),$O21:$AL21) +SUMPRODUCT(--(MOD(COLUMN($AM21:$BJ21),4)=MOD(COLUMN($AM21)+0,4)),$AM21:$BJ21) -> 0 | BM21: =SUMPRODUCT(--(MOD(COLUMN($O21:$AL21),4)=MOD(COLUMN($O21)+0,4)),$O21:$AL21)*$I21 +SUMPRODUCT(--(MOD(COLUMN($AM21:$BJ21),4)=MOD(COLUMN($AM21)+0,4)),$AM21:$BJ21)*$I21 -> 0 | BN21: =SUMPRODUCT(--(MOD(COLUMN($O21:$AL21),4)=MOD(COLUMN($O21)+1,4)),$O21:$AL21) +SUMPRODUCT(--(MOD(COLUMN($AM21:$BJ21),4)=MOD(COLUMN($AM21)+1,4)),$AM21:$BJ21) -> 0 | BO21: =SUMPRODUCT(--(MOD(COLUMN($O21:$AL21),4)=MOD(COLUMN($O21)+1,4)),$O21:$AL21)*$I21 +SUMPRODUCT(--(MOD(COLUMN($AM21:$BJ21),4)=MOD(COLUMN($AM21)+1,4)),$AM21:$BJ21)*$I21 -> 0 | BP21: =SUMPRODUCT(--(MOD(COLUMN($O21:$AL21),4)=MOD(COLUMN($O21)+2,4)),$O21:$AL21) +SUMPRODUCT(--(MOD(COLUMN($AM21:$BJ21),4)=MOD(COLUMN($AM21)+2,4)),$AM21:$BJ21) -> 0 | BQ21: =SUMPRODUCT(--(MOD(COLUMN($O21:$AL21),4)=MOD(COLUMN($O21)+2,4)),$O21:$AL21)*$I21 +SUMPRODUCT(--(MOD(COLUMN($AM21:$BJ21),4)=MOD(COLUMN($AM21)+2,4)),$AM21:$BJ21)*$I21 -> 0 | DQ21: =SUMPRODUCT(--(MOD(COLUMN(BT21:CQ21),4)=MOD(COLUMN(BT21),4)),BT21:CQ21)+SUMPRODUCT(--(MOD(COLUMN(CR21:DO21),4)=MOD(COLUMN(CR21),4)),CR21:DO21) -> 0 | DR21: =SUMPRODUCT(--(MOD(COLUMN(BT21:CQ21),4)=MOD(COLUMN(BT21),4)),BT21:CQ21)*#REF!+SUMPRODUCT(--(MOD(COLUMN(CR21:DO21),4)=MOD(COLUMN(CR21),4)),CR21:DO21)*#REF! -> #REF! | FR21: =SUMPRODUCT(--(MOD(COLUMN(DU21:ER21),4)=MOD(COLUMN(DU21),4)),DU21:ER21)+SUMPRODUCT(--(MOD(COLUMN(ES21:FP21),4)=MOD(COLUMN(ES21),4)),ES21:FP21) -> 0 | FS21: =SUMPRODUCT(--(MOD(COLUMN(DU21:ER21),4)=MOD(COLUMN(DU21),4)),DU21:ER21)*#REF!+SUMPRODUCT(--(MOD(COLUMN(ES21:FP21),4)=MOD(COLUMN(ES21),4)),ES21:FP21)*#REF! -> #REF!
A22: BPW (нет в системе) | E22: =IF(ISBLANK(G22),"",IF($A$6:$A$64=$A22,COUNTIF($A$6:A22,$A22),"")) | L22: =IF(K22="RUB",J22/ЮАНЬ,IF(K22="EUR",J22*ЕВРО/ЮАНЬ,"")) | N22: =IF(BP22>0,1,IF(BN22>0,2,)) -> 0 | BL22: =SUMPRODUCT(--(MOD(COLUMN($O22:$AL22),4)=MOD(COLUMN($O22)+0,4)),$O22:$AL22) +SUMPRODUCT(--(MOD(COLUMN($AM22:$BJ22),4)=MOD(COLUMN($AM22)+0,4)),$AM22:$BJ22) -> 0 | BM22: =SUMPRODUCT(--(MOD(COLUMN($O22:$AL22),4)=MOD(COLUMN($O22)+0,4)),$O22:$AL22)*$I22 +SUMPRODUCT(--(MOD(COLUMN($AM22:$BJ22),4)=MOD(COLUMN($AM22)+0,4)),$AM22:$BJ22)*$I22 -> 0 | BN22: =SUMPRODUCT(--(MOD(COLUMN($O22:$AL22),4)=MOD(COLUMN($O22)+1,4)),$O22:$AL22) +SUMPRODUCT(--(MOD(COLUMN($AM22:$BJ22),4)=MOD(COLUMN($AM22)+1,4)),$AM22:$BJ22) -> 0 | BO22: =SUMPRODUCT(--(MOD(COLUMN($O22:$AL22),4)=MOD(COLUMN($O22)+1,4)),$O22:$AL22)*$I22 +SUMPRODUCT(--(MOD(COLUMN($AM22:$BJ22),4)=MOD(COLUMN($AM22)+1,4)),$AM22:$BJ22)*$I22 -> 0 | BP22: =SUMPRODUCT(--(MOD(COLUMN($O22:$AL22),4)=MOD(COLUMN($O22)+2,4)),$O22:$AL22) +SUMPRODUCT(--(MOD(COLUMN($AM22:$BJ22),4)=MOD(COLUMN($AM22)+2,4)),$AM22:$BJ22) -> 0 | BQ22: =SUMPRODUCT(--(MOD(COLUMN($O22:$AL22),4)=MOD(COLUMN($O22)+2,4)),$O22:$AL22)*$I22 +SUMPRODUCT(--(MOD(COLUMN($AM22:$BJ22),4)=MOD(COLUMN($AM22)+2,4)),$AM22:$BJ22)*$I22 -> 0 | DQ22: =SUMPRODUCT(--(MOD(COLUMN(BT22:CQ22),4)=MOD(COLUMN(BT22),4)),BT22:CQ22)+SUMPRODUCT(--(MOD(COLUMN(CR22:DO22),4)=MOD(COLUMN(CR22),4)),CR22:DO22) -> 0 | DR22: =SUMPRODUCT(--(MOD(COLUMN(BT22:CQ22),4)=MOD(COLUMN(BT22),4)),BT22:CQ22)*#REF!+SUMPRODUCT(--(MOD(COLUMN(CR22:DO22),4)=MOD(COLUMN(CR22),4)),CR22:DO22)*#REF! -> #REF! | FR22: =SUMPRODUCT(--(MOD(COLUMN(DU22:ER22),4)=MOD(COLUMN(DU22),4)),DU22:ER22)+SUMPRODUCT(--(MOD(COLUMN(ES22:FP22),4)=MOD(COLUMN(ES22),4)),ES22:FP22) -> 0 | FS22: =SUMPRODUCT(--(MOD(COLUMN(DU22:ER22),4)=MOD(COLUMN(DU22),4)),DU22:ER22)*#REF!+SUMPRODUCT(--(MOD(COLUMN(ES22:FP22),4)=MOD(COLUMN(ES22),4)),ES22:FP22)*#REF! -> #REF!
A23: HJBridge (нет в системе) | B23: Договор не подписан | C23: ВБК Восток | D23: Прасолов, Соловьёв | E23: =IF(ISBLANK(G23),"",IF($A$6:$A$64=$A23,COUNTIF($A$6:A23,$A23),"")) -> 1 | F23: 1 | G23: 6402250340 | H23: Дисковый тормозной механизм (левый) | I23: =2160/НДС_20 -> 1800 | L23: =IF(K23="RUB",J23/ЮАНЬ,IF(K23="EUR",J23*ЕВРО/ЮАНЬ,"")) | N23: =IF(BP23>0,1,IF(BN23>0,2,)) -> 0 | U23: 0 | BL23: =SUMPRODUCT(--(MOD(COLUMN($O23:$AL23),4)=MOD(COLUMN($O23)+0,4)),$O23:$AL23) +SUMPRODUCT(--(MOD(COLUMN($AM23:$BJ23),4)=MOD(COLUMN($AM23)+0,4)),$AM23:$BJ23) -> 0 | BM23: =SUMPRODUCT(--(MOD(COLUMN($O23:$AL23),4)=MOD(COLUMN($O23)+0,4)),$O23:$AL23)*$I23 +SUMPRODUCT(--(MOD(COLUMN($AM23:$BJ23),4)=MOD(COLUMN($AM23)+0,4)),$AM23:$BJ23)*$I23 -> 0 | BN23: =SUMPRODUCT(--(MOD(COLUMN($O23:$AL23),4)=MOD(COLUMN($O23)+1,4)),$O23:$AL23) +SUMPRODUCT(--(MOD(COLUMN($AM23:$BJ23),4)=MOD(COLUMN($AM23)+1,4)),$AM23:$BJ23) -> 0 | BO23: =SUMPRODUCT(--(MOD(COLUMN($O23:$AL23),4)=MOD(COLUMN($O23)+1,4)),$O23:$AL23)*$I23 +SUMPRODUCT(--(MOD(COLUMN($AM23:$BJ23),4)=MOD(COLUMN($AM23)+1,4)),$AM23:$BJ23)*$I23 -> 0 | BP23: =SUMPRODUCT(--(MOD(COLUMN($O23:$AL23),4)=MOD(COLUMN($O23)+2,4)),$O23:$AL23) +SUMPRODUCT(--(MOD(COLUMN($AM23:$BJ23),4)=MOD(COLUMN($AM23)+2,4)),$AM23:$BJ23) -> 0 | BQ23: =SUMPRODUCT(--(MOD(COLUMN($O23:$AL23),4)=MOD(COLUMN($O23)+2,4)),$O23:$AL23)*$I23 +SUMPRODUCT(--(MOD(COLUMN($AM23:$BJ23),4)=MOD(COLUMN($AM23)+2,4)),$AM23:$BJ23)*$I23 -> 0 | BT23: 621 | BX23: 621 | CB23: 621 | CF23: 621 | CJ23: 621 | CN23: 621 | CR23: 621 | CV23: 621 | CZ23: 621 | DD23: 621 | DH23: 621 | DL23: 621 | DQ23: =SUMPRODUCT(--(MOD(COLUMN(BT23:CQ23),4)=MOD(COLUMN(BT23),4)),BT23:CQ23)+SUMPRODUCT(--(MOD(COLUMN(CR23:DO23),4)=MOD(COLUMN(CR23),4)),CR23:DO23) -> 7452 | DR23: =SUMPRODUCT(--(MOD(COLUMN(BT23:CQ23),4)=MOD(COLUMN(BT23),4)),BT23:CQ23)*#REF!+SUMPRODUCT(--(MOD(COLUMN(CR23:DO23),4)=MOD(COLUMN(CR23),4)),CR23:DO23)*#REF! -> #REF! | DU23: 828 | DY23: 828 | EC23: 828 | EG23: 828 | EK23: 828 | EO23: 828 | ES23: 828 | EW23: 828 | FA23: 828 | FE23: 828 | FI23: 828 | FM23: 828 | FR23: =SUMPRODUCT(--(MOD(COLUMN(DU23:ER23),4)=MOD(COLUMN(DU23),4)),DU23:ER23)+SUMPRODUCT(--(MOD(COLUMN(ES23:FP23),4)=MOD(COLUMN(ES23),4)),ES23:FP23) -> 9936 | FS23: =SUMPRODUCT(--(MOD(COLUMN(DU23:ER23),4)=MOD(COLUMN(DU23),4)),DU23:ER23)*#REF!+SUMPRODUCT(--(MOD(COLUMN(ES23:FP23),4)=MOD(COLUMN(ES23),4)),ES23:FP23)*#REF! -> #REF!
A24: HJBridge (нет в системе) | B24: Договор не подписан | C24: ВБК Восток | D24: Прасолов, Соловьёв | E24: =IF(ISBLANK(G24),"",IF($A$6:$A$64=$A24,COUNTIF($A$6:A24,$A24),"")) -> 2 | F24: 1 | G24: 6402250350 | H24: Дисковый тормозной механизм (правый) | I24: =I23 -> 1800 | L24: =IF(K24="RUB",J24/ЮАНЬ,IF(K24="EUR",J24*ЕВРО/ЮАНЬ,"")) | N24: =IF(BP24>0,1,IF(BN24>0,2,)) -> 0 | U24: 0 | BL24: =SUMPRODUCT(--(MOD(COLUMN($O24:$AL24),4)=MOD(COLUMN($O24)+0,4)),$O24:$AL24) +SUMPRODUCT(--(MOD(COLUMN($AM24:$BJ24),4)=MOD(COLUMN($AM24)+0,4)),$AM24:$BJ24) -> 0 | BM24: =SUMPRODUCT(--(MOD(COLUMN($O24:$AL24),4)=MOD(COLUMN($O24)+0,4)),$O24:$AL24)*$I24 +SUMPRODUCT(--(MOD(COLUMN($AM24:$BJ24),4)=MOD(COLUMN($AM24)+0,4)),$AM24:$BJ24)*$I24 -> 0 | BN24: =SUMPRODUCT(--(MOD(COLUMN($O24:$AL24),4)=MOD(COLUMN($O24)+1,4)),$O24:$AL24) +SUMPRODUCT(--(MOD(COLUMN($AM24:$BJ24),4)=MOD(COLUMN($AM24)+1,4)),$AM24:$BJ24) -> 0 | BO24: =SUMPRODUCT(--(MOD(COLUMN($O24:$AL24),4)=MOD(COLUMN($O24)+1,4)),$O24:$AL24)*$I24 +SUMPRODUCT(--(MOD(COLUMN($AM24:$BJ24),4)=MOD(COLUMN($AM24)+1,4)),$AM24:$BJ24)*$I24 -> 0 | BP24: =SUMPRODUCT(--(MOD(COLUMN($O24:$AL24),4)=MOD(COLUMN($O24)+2,4)),$O24:$AL24) +SUMPRODUCT(--(MOD(COLUMN($AM24:$BJ24),4)=MOD(COLUMN($AM24)+2,4)),$AM24:$BJ24) -> 0 | BQ24: =SUMPRODUCT(--(MOD(COLUMN($O24:$AL24),4)=MOD(COLUMN($O24)+2,4)),$O24:$AL24)*$I24 +SUMPRODUCT(--(MOD(COLUMN($AM24:$BJ24),4)=MOD(COLUMN($AM24)+2,4)),$AM24:$BJ24)*$I24 -> 0 | BT24: 621 | BX24: 621 | CB24: 621 | CF24: 621 | CJ24: 621 | CN24: 621 | CR24: 621 | CV24: 621 | CZ24: 621 | DD24: 621 | DH24: 621 | DL24: 621 | DQ24: =SUMPRODUCT(--(MOD(COLUMN(BT24:CQ24),4)=MOD(COLUMN(BT24),4)),BT24:CQ24)+SUMPRODUCT(--(MOD(COLUMN(CR24:DO24),4)=MOD(COLUMN(CR24),4)),CR24:DO24) -> 7452 | DR24: =SUMPRODUCT(--(MOD(COLUMN(BT24:CQ24),4)=MOD(COLUMN(BT24),4)),BT24:CQ24)*#REF!+SUMPRODUCT(--(MOD(COLUMN(CR24:DO24),4)=MOD(COLUMN(CR24),4)),CR24:DO24)*#REF! -> #REF! | DU24: 828 | DY24: 828 | EC24: 828 | EG24: 828 | EK24: 828 | EO24: 828 | ES24: 828 | EW24: 828 | FA24: 828 | FE24: 828 | FI24: 828 | FM24: 828 | FR24: =SUMPRODUCT(--(MOD(COLUMN(DU24:ER24),4)=MOD(COLUMN(DU24),4)),DU24:ER24)+SUMPRODUCT(--(MOD(COLUMN(ES24:FP24),4)=MOD(COLUMN(ES24),4)),ES24:FP24) -> 9936 | FS24: =SUMPRODUCT(--(MOD(COLUMN(DU24:ER24),4)=MOD(COLUMN(DU24),4)),DU24:ER24)*#REF!+SUMPRODUCT(--(MOD(COLUMN(ES24:FP24),4)=MOD(COLUMN(ES24),4)),ES24:FP24)*#REF! -> #REF!
A25: HJBridge (нет в системе) | B25: Договор не подписан | C25: ВБК Восток | D25: Прасолов, Соловьёв | E25: =IF(ISBLANK(G25),"",IF($A$6:$A$64=$A25,COUNTIF($A$6:A25,$A25),"")) -> 3 | F25: 1 | G25: 4410328080 | H25: Датчик АБС, 0,4 м | I25: =84/НДС_20 -> 70 | L25: =IF(K25="RUB",J25/ЮАНЬ,IF(K25="EUR",J25*ЕВРО/ЮАНЬ,"")) | N25: =IF(BP25>0,1,IF(BN25>0,2,)) -> 0 | U25: 0 | BL25: =SUMPRODUCT(--(MOD(COLUMN($O25:$AL25),4)=MOD(COLUMN($O25)+0,4)),$O25:$AL25) +SUMPRODUCT(--(MOD(COLUMN($AM25:$BJ25),4)=MOD(COLUMN($AM25)+0,4)),$AM25:$BJ25) -> 0 | BM25: =SUMPRODUCT(--(MOD(COLUMN($O25:$AL25),4)=MOD(COLUMN($O25)+0,4)),$O25:$AL25)*$I25 +SUMPRODUCT(--(MOD(COLUMN($AM25:$BJ25),4)=MOD(COLUMN($AM25)+0,4)),$AM25:$BJ25)*$I25 -> 0 | BN25: =SUMPRODUCT(--(MOD(COLUMN($O25:$AL25),4)=MOD(COLUMN($O25)+1,4)),$O25:$AL25) +SUMPRODUCT(--(MOD(COLUMN($AM25:$BJ25),4)=MOD(COLUMN($AM25)+1,4)),$AM25:$BJ25) -> 0 | BO25: =SUMPRODUCT(--(MOD(COLUMN($O25:$AL25),4)=MOD(COLUMN($O25)+1,4)),$O25:$AL25)*$I25 +SUMPRODUCT(--(MOD(COLUMN($AM25:$BJ25),4)=MOD(COLUMN($AM25)+1,4)),$AM25:$BJ25)*$I25 -> 0 | BP25: =SUMPRODUCT(--(MOD(COLUMN($O25:$AL25),4)=MOD(COLUMN($O25)+2,4)),$O25:$AL25) +SUMPRODUCT(--(MOD(COLUMN($AM25:$BJ25),4)=MOD(COLUMN($AM25)+2,4)),$AM25:$BJ25) -> 0 | BQ25: =SUMPRODUCT(--(MOD(COLUMN($O25:$AL25),4)=MOD(COLUMN($O25)+2,4)),$O25:$AL25)*$I25 +SUMPRODUCT(--(MOD(COLUMN($AM25:$BJ25),4)=MOD(COLUMN($AM25)+2,4)),$AM25:$BJ25)*$I25 -> 0 | BT25: 414 | BX25: 414 | CB25: 414 | CF25: 414 | CJ25: 414 | CN25: 414 | CR25: 414 | CV25: 414 | CZ25: 414 | DD25: 414 | DH25: 414 | DL25: 414 | DQ25: =SUMPRODUCT(--(MOD(COLUMN(BT25:CQ25),4)=MOD(COLUMN(BT25),4)),BT25:CQ25)+SUMPRODUCT(--(MOD(COLUMN(CR25:DO25),4)=MOD(COLUMN(CR25),4)),CR25:DO25) -> 4968 | DR25: =SUMPRODUCT(--(MOD(COLUMN(BT25:CQ25),4)=MOD(COLUMN(BT25),4)),BT25:CQ25)*#REF!+SUMPRODUCT(--(MOD(COLUMN(CR25:DO25),4)=MOD(COLUMN(CR25),4)),CR25:DO25)*#REF! -> #REF! | DU25: 552 | DY25: 552 | EC25: 552 | EG25: 552 | EK25: 552 | EO25: 552 | ES25: 552 | EW25: 552 | FA25: 552 | FE25: 552 | FI25: 552 | FM25: 552 | FR25: =SUMPRODUCT(--(MOD(COLUMN(DU25:ER25),4)=MOD(COLUMN(DU25),4)),DU25:ER25)+SUMPRODUCT(--(MOD(COLUMN(ES25:FP25),4)=MOD(COLUMN(ES25),4)),ES25:FP25) -> 6624 | FS25: =SUMPRODUCT(--(MOD(COLUMN(DU25:ER25),4)=MOD(COLUMN(DU25),4)),DU25:ER25)*#REF!+SUMPRODUCT(--(MOD(COLUMN(ES25:FP25),4)=MOD(COLUMN(ES25),4)),ES25:FP25)*#REF! -> #REF!
A26: HJBridge (нет в системе) | B26: Договор не подписан | C26: ВБК Восток | D26: Прасолов, Соловьёв | E26: =IF(ISBLANK(G26),"",IF($A$6:$A$64=$A26,COUNTIF($A$6:A26,$A26),"")) -> 4 | F26: 1 | G26: 8997598154 | H26: Втулка датчика АБС | I26: =8.4/НДС_20 -> 7 | L26: =IF(K26="RUB",J26/ЮАНЬ,IF(K26="EUR",J26*ЕВРО/ЮАНЬ,"")) | N26: =IF(BP26>0,1,IF(BN26>0,2,)) -> 0 | U26: 0 | BL26: =SUMPRODUCT(--(MOD(COLUMN($O26:$AL26),4)=MOD(COLUMN($O26)+0,4)),$O26:$AL26) +SUMPRODUCT(--(MOD(COLUMN($AM26:$BJ26),4)=MOD(COLUMN($AM26)+0,4)),$AM26:$BJ26) -> 0 | BM26: =SUMPRODUCT(--(MOD(COLUMN($O26:$AL26),4)=MOD(COLUMN($O26)+0,4)),$O26:$AL26)*$I26 +SUMPRODUCT(--(MOD(COLUMN($AM26:$BJ26),4)=MOD(COLUMN($AM26)+0,4)),$AM26:$BJ26)*$I26 -> 0 | BN26: =SUMPRODUCT(--(MOD(COLUMN($O26:$AL26),4)=MOD(COLUMN($O26)+1,4)),$O26:$AL26) +SUMPRODUCT(--(MOD(COLUMN($AM26:$BJ26),4)=MOD(COLUMN($AM26)+1,4)),$AM26:$BJ26) -> 0 | BO26: =SUMPRODUCT(--(MOD(COLUMN($O26:$AL26),4)=MOD(COLUMN($O26)+1,4)),$O26:$AL26)*$I26 +SUMPRODUCT(--(MOD(COLUMN($AM26:$BJ26),4)=MOD(COLUMN($AM26)+1,4)),$AM26:$BJ26)*$I26 -> 0 | BP26: =SUMPRODUCT(--(MOD(COLUMN($O26:$AL26),4)=MOD(COLUMN($O26)+2,4)),$O26:$AL26) +SUMPRODUCT(--(MOD(COLUMN($AM26:$BJ26),4)=MOD(COLUMN($AM26)+2,4)),$AM26:$BJ26) -> 0 | BQ26: =SUMPRODUCT(--(MOD(COLUMN($O26:$AL26),4)=MOD(COLUMN($O26)+2,4)),$O26:$AL26)*$I26 +SUMPRODUCT(--(MOD(COLUMN($AM26:$BJ26),4)=MOD(COLUMN($AM26)+2,4)),$AM26:$BJ26)*$I26 -> 0 | BT26: 414 | BX26: 414 | CB26: 414 | CF26: 414 | CJ26: 414 | CN26: 414 | CR26: 414 | CV26: 414 | CZ26: 414 | DD26: 414 | DH26: 414 | DL26: 414 | DQ26: =SUMPRODUCT(--(MOD(COLUMN(BT26:CQ26),4)=MOD(COLUMN(BT26),4)),BT26:CQ26)+SUMPRODUCT(--(MOD(COLUMN(CR26:DO26),4)=MOD(COLUMN(CR26),4)),CR26:DO26) -> 4968 | DR26: =SUMPRODUCT(--(MOD(COLUMN(BT26:CQ26),4)=MOD(COLUMN(BT26),4)),BT26:CQ26)*#REF!+SUMPRODUCT(--(MOD(COLUMN(CR26:DO26),4)=MOD(COLUMN(CR26),4)),CR26:DO26)*#REF! -> #REF! | DU26: 552 | DY26: 552 | EC26: 552 | EG26: 552 | EK26: 552 | EO26: 552 | ES26: 552 | EW26: 552 | FA26: 552 | FE26: 552 | FI26: 552 | FM26: 552 | FR26: =SUMPRODUCT(--(MOD(COLUMN(DU26:ER26),4)=MOD(COLUMN(DU26),4)),DU26:ER26)+SUMPRODUCT(--(MOD(COLUMN(ES26:FP26),4)=MOD(COLUMN(ES26),4)),ES26:FP26) -> 6624 | FS26: =SUMPRODUCT(--(MOD(COLUMN(DU26:ER26),4)=MOD(COLUMN(DU26),4)),DU26:ER26)*#REF!+SUMPRODUCT(--(MOD(COLUMN(ES26:FP26),4)=MOD(COLUMN(ES26),4)),ES26:FP26)*#REF! -> #REF!
A27: HJBridge (нет в системе) | B27: Договор не подписан | C27: ВБК Восток | D27: Прасолов, Соловьёв | E27: =IF(ISBLANK(G27),"",IF($A$6:$A$64=$A27,COUNTIF($A$6:A27,$A27),"")) -> 5 | F27: 1 | G27: 4235050030 | H27: Тормозная камера, тип 20 | I27: =163.08/НДС_20 -> 135.9 | L27: =IF(K27="RUB",J27/ЮАНЬ,IF(K27="EUR",J27*ЕВРО/ЮАНЬ,"")) | N27: =IF(BP27>0,1,IF(BN27>0,2,)) -> 0 | U27: 0 | BL27: =SUMPRODUCT(--(MOD(COLUMN($O27:$AL27),4)=MOD(COLUMN($O27)+0,4)),$O27:$AL27) +SUMPRODUCT(--(MOD(COLUMN($AM27:$BJ27),4)=MOD(COLUMN($AM27)+0,4)),$AM27:$BJ27) -> 0 | BM27: =SUMPRODUCT(--(MOD(COLUMN($O27:$AL27),4)=MOD(COLUMN($O27)+0,4)),$O27:$AL27)*$I27 +SUMPRODUCT(--(MOD(COLUMN($AM27:$BJ27),4)=MOD(COLUMN($AM27)+0,4)),$AM27:$BJ27)*$I27 -> 0 | BN27: =SUMPRODUCT(--(MOD(COLUMN($O27:$AL27),4)=MOD(COLUMN($O27)+1,4)),$O27:$AL27) +SUMPRODUCT(--(MOD(COLUMN($AM27:$BJ27),4)=MOD(COLUMN($AM27)+1,4)),$AM27:$BJ27) -> 0 | BO27: =SUMPRODUCT(--(MOD(COLUMN($O27:$AL27),4)=MOD(COLUMN($O27)+1,4)),$O27:$AL27)*$I27 +SUMPRODUCT(--(MOD(COLUMN($AM27:$BJ27),4)=MOD(COLUMN($AM27)+1,4)),$AM27:$BJ27)*$I27 -> 0 | BP27: =SUMPRODUCT(--(MOD(COLUMN($O27:$AL27),4)=MOD(COLUMN($O27)+2,4)),$O27:$AL27) +SUMPRODUCT(--(MOD(COLUMN($AM27:$BJ27),4)=MOD(COLUMN($AM27)+2,4)),$AM27:$BJ27) -> 0 | BQ27: =SUMPRODUCT(--(MOD(COLUMN($O27:$AL27),4)=MOD(COLUMN($O27)+2,4)),$O27:$AL27)*$I27 +SUMPRODUCT(--(MOD(COLUMN($AM27:$BJ27),4)=MOD(COLUMN($AM27)+2,4)),$AM27:$BJ27)*$I27 -> 0 | DQ27: =SUMPRODUCT(--(MOD(COLUMN(BT27:CQ27),4)=MOD(COLUMN(BT27),4)),BT27:CQ27)+SUMPRODUCT(--(MOD(COLUMN(CR27:DO27),4)=MOD(COLUMN(CR27),4)),CR27:DO27) -> 0 | DR27: =SUMPRODUCT(--(MOD(COLUMN(BT27:CQ27),4)=MOD(COLUMN(BT27),4)),BT27:CQ27)*#REF!+SUMPRODUCT(--(MOD(COLUMN(CR27:DO27),4)=MOD(COLUMN(CR27),4)),CR27:DO27)*#REF! -> #REF! | FR27: =SUMPRODUCT(--(MOD(COLUMN(DU27:ER27),4)=MOD(COLUMN(DU27),4)),DU27:ER27)+SUMPRODUCT(--(MOD(COLUMN(ES27:FP27),4)=MOD(COLUMN(ES27),4)),ES27:FP27) -> 0 | FS27: =SUMPRODUCT(--(MOD(COLUMN(DU27:ER27),4)=MOD(COLUMN(DU27),4)),DU27:ER27)*#REF!+SUMPRODUCT(--(MOD(COLUMN(ES27:FP27),4)=MOD(COLUMN(ES27),4)),ES27:FP27)*#REF! -> #REF!
A28: HJBridge (нет в системе) | B28: Договор не подписан | C28: ВБК Восток | D28: Прасолов, Соловьёв | E28: =IF(ISBLANK(G28),"",IF($A$6:$A$64=$A28,COUNTIF($A$6:A28,$A28),"")) -> 6 | F28: 1 | G28: 9254800506 | H28: Энергоаккумулятор, тип 20/24 | I28: =373.98/НДС_20 -> 311.65 | L28: =IF(K28="RUB",J28/ЮАНЬ,IF(K28="EUR",J28*ЕВРО/ЮАНЬ,"")) | N28: =IF(BP28>0,1,IF(BN28>0,2,)) -> 0 | U28: 0 | BL28: =SUMPRODUCT(--(MOD(COLUMN($O28:$AL28),4)=MOD(COLUMN($O28)+0,4)),$O28:$AL28) +SUMPRODUCT(--(MOD(COLUMN($AM28:$BJ28),4)=MOD(COLUMN($AM28)+0,4)),$AM28:$BJ28) -> 0 | BM28: =SUMPRODUCT(--(MOD(COLUMN($O28:$AL28),4)=MOD(COLUMN($O28)+0,4)),$O28:$AL28)*$I28 +SUMPRODUCT(--(MOD(COLUMN($AM28:$BJ28),4)=MOD(COLUMN($AM28)+0,4)),$AM28:$BJ28)*$I28 -> 0 | BN28: =SUMPRODUCT(--(MOD(COLUMN($O28:$AL28),4)=MOD(COLUMN($O28)+1,4)),$O28:$AL28) +SUMPRODUCT(--(MOD(COLUMN($AM28:$BJ28),4)=MOD(COLUMN($AM28)+1,4)),$AM28:$BJ28) -> 0 | BO28: =SUMPRODUCT(--(MOD(COLUMN($O28:$AL28),4)=MOD(COLUMN($O28)+1,4)),$O28:$AL28)*$I28 +SUMPRODUCT(--(MOD(COLUMN($AM28:$BJ28),4)=MOD(COLUMN($AM28)+1,4)),$AM28:$BJ28)*$I28 -> 0 | BP28: =SUMPRODUCT(--(MOD(COLUMN($O28:$AL28),4)=MOD(COLUMN($O28)+2,4)),$O28:$AL28) +SUMPRODUCT(--(MOD(COLUMN($AM28:$BJ28),4)=MOD(COLUMN($AM28)+2,4)),$AM28:$BJ28) -> 0 | BQ28: =SUMPRODUCT(--(MOD(COLUMN($O28:$AL28),4)=MOD(COLUMN($O28)+2,4)),$O28:$AL28)*$I28 +SUMPRODUCT(--(MOD(COLUMN($AM28:$BJ28),4)=MOD(COLUMN($AM28)+2,4)),$AM28:$BJ28)*$I28 -> 0 | DQ28: =SUMPRODUCT(--(MOD(COLUMN(BT28:CQ28),4)=MOD(COLUMN(BT28),4)),BT28:CQ28)+SUMPRODUCT(--(MOD(COLUMN(CR28:DO28),4)=MOD(COLUMN(CR28),4)),CR28:DO28) -> 0 | DR28: =SUMPRODUCT(--(MOD(COLUMN(BT28:CQ28),4)=MOD(COLUMN(BT28),4)),BT28:CQ28)*#REF!+SUMPRODUCT(--(MOD(COLUMN(CR28:DO28),4)=MOD(COLUMN(CR28),4)),CR28:DO28)*#REF! -> #REF! | FR28: =SUMPRODUCT(--(MOD(COLUMN(DU28:ER28),4)=MOD(COLUMN(DU28),4)),DU28:ER28)+SUMPRODUCT(--(MOD(COLUMN(ES28:FP28),4)=MOD(COLUMN(ES28),4)),ES28:FP28) -> 0 | FS28: =SUMPRODUCT(--(MOD(COLUMN(DU28:ER28),4)=MOD(COLUMN(DU28),4)),DU28:ER28)*#REF!+SUMPRODUCT(--(MOD(COLUMN(ES28:FP28),4)=MOD(COLUMN(ES28),4)),ES28:FP28)*#REF! -> #REF!
A29: HJBridge (нет в системе) | B29: Договор не подписан | C29: ВБК Восток | D29: Прасолов, Соловьёв | E29: =IF(ISBLANK(G29),"",IF($A$6:$A$64=$A29,COUNTIF($A$6:A29,$A29),"")) -> 7 | F29: 1 | G29: 4235041050 | H29: Тормозная камера, тип 16 | I29: =156/НДС_20 -> 130 | L29: =IF(K29="RUB",J29/ЮАНЬ,IF(K29="EUR",J29*ЕВРО/ЮАНЬ,"")) | N29: =IF(BP29>0,1,IF(BN29>0,2,)) -> 0 | U29: 0 | BL29: =SUMPRODUCT(--(MOD(COLUMN($O29:$AL29),4)=MOD(COLUMN($O29)+0,4)),$O29:$AL29) +SUMPRODUCT(--(MOD(COLUMN($AM29:$BJ29),4)=MOD(COLUMN($AM29)+0,4)),$AM29:$BJ29) -> 0 | BM29: =SUMPRODUCT(--(MOD(COLUMN($O29:$AL29),4)=MOD(COLUMN($O29)+0,4)),$O29:$AL29)*$I29 +SUMPRODUCT(--(MOD(COLUMN($AM29:$BJ29),4)=MOD(COLUMN($AM29)+0,4)),$AM29:$BJ29)*$I29 -> 0 | BN29: =SUMPRODUCT(--(MOD(COLUMN($O29:$AL29),4)=MOD(COLUMN($O29)+1,4)),$O29:$AL29) +SUMPRODUCT(--(MOD(COLUMN($AM29:$BJ29),4)=MOD(COLUMN($AM29)+1,4)),$AM29:$BJ29) -> 0 | BO29: =SUMPRODUCT(--(MOD(COLUMN($O29:$AL29),4)=MOD(COLUMN($O29)+1,4)),$O29:$AL29)*$I29 +SUMPRODUCT(--(MOD(COLUMN($AM29:$BJ29),4)=MOD(COLUMN($AM29)+1,4)),$AM29:$BJ29)*$I29 -> 0 | BP29: =SUMPRODUCT(--(MOD(COLUMN($O29:$AL29),4)=MOD(COLUMN($O29)+2,4)),$O29:$AL29) +SUMPRODUCT(--(MOD(COLUMN($AM29:$BJ29),4)=MOD(COLUMN($AM29)+2,4)),$AM29:$BJ29) -> 0 | BQ29: =SUMPRODUCT(--(MOD(COLUMN($O29:$AL29),4)=MOD(COLUMN($O29)+2,4)),$O29:$AL29)*$I29 +SUMPRODUCT(--(MOD(COLUMN($AM29:$BJ29),4)=MOD(COLUMN($AM29)+2,4)),$AM29:$BJ29)*$I29 -> 0 | DQ29: =SUMPRODUCT(--(MOD(COLUMN(BT29:CQ29),4)=MOD(COLUMN(BT29),4)),BT29:CQ29)+SUMPRODUCT(--(MOD(COLUMN(CR29:DO29),4)=MOD(COLUMN(CR29),4)),CR29:DO29) -> 0 | DR29: =SUMPRODUCT(--(MOD(COLUMN(BT29:CQ29),4)=MOD(COLUMN(BT29),4)),BT29:CQ29)*#REF!+SUMPRODUCT(--(MOD(COLUMN(CR29:DO29),4)=MOD(COLUMN(CR29),4)),CR29:DO29)*#REF! -> #REF! | FR29: =SUMPRODUCT(--(MOD(COLUMN(DU29:ER29),4)=MOD(COLUMN(DU29),4)),DU29:ER29)+SUMPRODUCT(--(MOD(COLUMN(ES29:FP29),4)=MOD(COLUMN(ES29),4)),ES29:FP29) -> 0 | FS29: =SUMPRODUCT(--(MOD(COLUMN(DU29:ER29),4)=MOD(COLUMN(DU29),4)),DU29:ER29)*#REF!+SUMPRODUCT(--(MOD(COLUMN(ES29:FP29),4)=MOD(COLUMN(ES29),4)),ES29:FP29)*#REF! -> #REF!
