Workbook

Sheet 2026_Мустафин
E1: Дата | G1: 46168
A2: 11.25 | B2: - курс юань/рубль | E2: 8.33 | G2: - курс евро/юань
F3: Подсветить артикул: | G3: - | I3: 2026-I | J3: 2026-II | K3: 2025 - II полугодие | L3: Валюта продажи | M3: Продажи 2024 | BO3: Продажи 2025
A4: Клиент | B4: Условия оплаты | C4: Поставщик | D4: Менеджер | E4: п\п | F4: 2 - продукт WABCO | G4: Номер изделия/ артикул | H4: Наименование | I4: Цена, юань, без НДС | J4: Цена, юань, без НДС | K4: Цена в валюте из контракта с клиентом, без НДС | L4: Валюта из контракта с клиентом | M4: Январь 2024 | Q4: Февраль 2024 | U4: Март 2024 | Y4: Апрель 2024 | AC4: Май 2024 | AG4: Июнь 2024 | AK4: Июль 2024 | AO4: Август 2024 | AS4: Сентябрь 2024 | AW4: Октябрь 2024 | BA4: 45597 | BE4: 45627 | BI4: ИТОГО, 2024 | BO4: 45658 | BT4: 45689 | BY4: 45717 | CD4: 45748 | CI4: 45778 | CN4: 45809 | CS4: 45839 | CX4: 45870 | DC4: 45901 | DH4: 45931 | DM4: 45962 | DR4: 45992 | DW4: ИТОГО, 2025 | EE4: 46023 | EI4: 46054 | EM4: 46082 | EQ4: 46113 | EU4: 46143 | EY4: 46174 | FC4: 46204 | FG4: 46235 | FK4: 46266 | FO4: 46296 | FS4: 46327 | FW4: 46357 | GA4: ИТОГО, 2026 | GG4: 46388 | GK4: 46419 | GO4: 46447 | GS4: 46478 | GW4: 46508 | HA4: 46539 | HE4: 46569 | HI4: 46600 | HM4: 46631 | HQ4: 46661 | HU4: 46692 | HY4: 46722 | IC4: ИТОГО, 2027 | II4: 46753 | IM4: 46784 | IQ4: 46813 | IU4: 46844 | IY4: 46874 | JC4: 46905 | JG4: 46935 | JK4: 46966 | JO4: 46997 | JS4: 47027 | JW4: 47058 | KA4: 47088 | KE4: ИТОГО, 2028
M5: AOP, шт | N5: Прогноз, шт | O5: Факт, шт | P5: Коментарий | Q5: AOP, шт | R5: Прогноз, шт | S5: Факт, шт | T5: Коментарий | U5: AOP, шт | V5: Прогноз, шт | W5: Факт, шт | X5: Коментарий | Y5: AOP, шт | Z5: Прогноз, шт | AA5: Факт, шт | AB5: Коментарий | AC5: AOP, шт | AD5: Прогноз, шт | AE5: Факт, шт | AF5: Коментарий | AG5: AOP, шт | AH5: Прогноз, шт | AI5: Факт, шт | AJ5: Коментарий | AK5: AOP, шт | AL5: Прогноз, шт | AM5: Факт, шт | AN5: Коментарий | AO5: AOP, шт | AP5: Прогноз, шт | AQ5: Факт, шт | AR5: Коментарий | AS5: AOP, шт | AT5: Прогноз, шт | AU5: Факт, шт | AV5: Коментарий | AW5: AOP, шт | AX5: Прогноз, шт | AY5: Факт, шт | AZ5: Коментарий | BA5: AOP, шт | BB5: Прогноз, шт | BC5: Факт, шт | BD5: Коментарий | BE5: AOP, шт | BF5: Прогноз, шт | BG5: Факт, шт | BH5: Коментарий | BI5: AOP, шт | BJ5: Продажи AOP, CNY | BK5: Прогноз, шт | BL5: Продажи Прогноз, CNY | BM5: Факт, шт | BN5: Продажи Факт, CNY | BO5: AOP, шт | BP5: AOP негатив, шт | BQ5: Прогноз, шт | BR5: Факт, шт | BS5: Коментарий | BT5: AOP, шт | BU5: AOP негатив, шт | BV5: Прогноз, шт | BW5: Факт, шт | BX5: Коментарий | BY5: AOP, шт | BZ5: AOP негатив, шт | CA5: Прогноз, шт | CB5: Факт, шт | CC5: Коментарий | CD5: AOP, шт | CE5: AOP негатив, шт | CF5: Прогноз, шт | CG5: Факт, шт | CH5: Коментарий | CI5: AOP, шт | CJ5: AOP негатив, шт | CK5: Прогноз, шт | CL5: Факт, шт | CM5: Коментарий | CN5: AOP, шт | CO5: AOP негатив, шт | CP5: Прогноз, шт | CQ5: Факт, шт | CR5: Коментарий | CS5: AOP, шт | CT5: AOP негатив, шт | CU5: Прогноз, шт | CV5: Факт, шт | CW5: Коментарий | CX5: AOP, шт | CY5: AOP негатив, шт | CZ5: Прогноз, шт | DA5: Факт, шт | DB5: Коментарий | DC5: AOP, шт | DD5: AOP негатив, шт | DE5: Прогноз, шт | DF5: Факт, шт | DG5: Коментарий | DH5: AOP, шт | DI5: AOP негатив, шт | DJ5: Прогноз, шт | DK5: Факт, шт | DL5: Коментарий | DM5: AOP, шт | DN5: AOP негатив, шт | DO5: Прогноз, шт | DP5: Факт, шт | DQ5: Коментарий | DR5: AOP, шт | DS5: AOP негатив, шт | DT5: Прогноз, шт | DU5: Факт, шт | DV5: Коментарий | DW5: AOP, шт | DX5: Продажи AOP, CNY | DY5: AOP негатив, шт | DZ5: Продажи AOP негатив, CNY | EA5: Прогноз, шт | EB5: Продажи Прогноз, CNY | EC5: Факт, шт | ED5: Продажи Факт, CNY | EE5: AOP, шт | EF5: Прогноз, шт | EG5: Факт, шт | EH5: Коментарий | EI5: AOP, шт | EJ5: Прогноз, шт | EK5: Факт, шт | EL5: Коментарий | EM5: AOP, шт | EN5: Прогноз, шт | EO5: Факт, шт | EP5: Коментарий | EQ5: AOP, шт | ER5: Прогноз, шт | ES5: Факт, шт | ET5: Коментарий | EU5: AOP, шт | EV5: Прогноз, шт | EW5: Факт, шт | EX5: Коментарий | EY5: AOP, шт | EZ5: Прогноз, шт | FA5: Факт, шт | FB5: Коментарий | FC5: AOP, шт | FD5: Прогноз, шт | FE5: Факт, шт | FF5: Коментарий | FG5: AOP, шт | FH5: Прогноз, шт | FI5: Факт, шт | FJ5: Коментарий | FK5: AOP, шт | FL5: Прогноз, шт | FM5: Факт, шт | FN5: Коментарий | FO5: AOP, шт | FP5: Прогноз, шт | FQ5: Факт, шт | FR5: Коментарий | FS5: AOP, шт | FT5: Прогноз, шт | FU5: Факт, шт | FV5: Коментарий | FW5: AOP, шт | FX5: Прогноз, шт | FY5: Факт, шт | FZ5: Коментарий | GA5: AOP, шт | GB5: Продажи AOP, CNY | GC5: Прогноз, шт | GD5: Продажи Прогноз, CNY | GE5: Факт, шт | GF5: Продажи Факт, CNY | GG5: AOP, шт | GH5: Прогноз, шт | GI5: Факт, шт | GJ5: Коментарий | GK5: AOP, шт | GL5: Прогноз, шт | GM5: Факт, шт | GN5: Коментарий | GO5: AOP, шт | GP5: Прогноз, шт | GQ5: Факт, шт | GR5: Коментарий | GS5: AOP, шт | GT5: Прогноз, шт | GU5: Факт, шт | GV5: Коментарий | GW5: AOP, шт | GX5: Прогноз, шт | GY5: Факт, шт | GZ5: Коментарий | HA5: AOP, шт | HB5: Прогноз, шт | HC5: Факт, шт | HD5: Коментарий | HE5: AOP, шт | HF5: Прогноз, шт | HG5: Факт, шт | HH5: Коментарий | HI5: AOP, шт | HJ5: Прогноз, шт | HK5: Факт, шт | HL5: Коментарий | HM5: AOP, шт | HN5: Прогноз, шт | HO5: Факт, шт | HP5: Коментарий | HQ5: AOP, шт | HR5: Прогноз, шт | HS5: Факт, шт | HT5: Коментарий | HU5: AOP, шт | HV5: Прогноз, шт | HW5: Факт, шт | HX5: Коментарий | HY5: AOP, шт | HZ5: Прогноз, шт | IA5: Факт, шт | IB5: Коментарий | IC5: AOP, шт | ID5: Продажи AOP, CNY | IE5: Прогноз, шт | IF5: Продажи Прогноз, CNY | IG5: Факт, шт | IH5: Продажи Факт, CNY | II5: AOP, шт | IJ5: Прогноз, шт | IK5: Факт, шт | IL5: Коментарий | IM5: AOP, шт | IN5: Прогноз, шт | IO5: Факт, шт | IP5: Коментарий | IQ5: AOP, шт | IR5: Прогноз, шт | IS5: Факт, шт | IT5: Коментарий | IU5: AOP, шт | IV5: Прогноз, шт | IW5: Факт, шт | IX5: Коментарий | IY5: AOP, шт | IZ5: Прогноз, шт | JA5: Факт, шт | JB5: Коментарий | JC5: AOP, шт | JD5: Прогноз, шт | JE5: Факт, шт | JF5: Коментарий | JG5: AOP, шт | JH5: Прогноз, шт | JI5: Факт, шт | JJ5: Коментарий | JK5: AOP, шт | JL5: Прогноз, шт | JM5: Факт, шт | JN5: Коментарий | JO5: AOP, шт | JP5: Прогноз, шт | JQ5: Факт, шт | JR5: Коментарий | JS5: AOP, шт | JT5: Прогноз, шт | JU5: Факт, шт | JV5: Коментарий | JW5: AOP, шт | JX5: Прогноз, шт | JY5: Факт, шт | JZ5: Коментарий | KA5: AOP, шт | KB5: Прогноз, шт | KC5: Факт, шт | KD5: Коментарий | KE5: AOP, шт | KF5: Продажи AOP, CNY | KG5: Прогноз, шт | KH5: Продажи Прогноз, CNY | KI5: Факт, шт | KJ5: Продажи Факт, CNY | KN5: Кол-во в сете | KO5: Сет
A6: НЕФАЗ ПАО | B6: Отсрочка 30 дней | C6: ВБК РУС | D6: Мустафин Ринат | E6: 1 | F6: 1 | G6: 9522010010 | H6: Головка соединительная (управляющая) | I6: =89.6/1.2 -> 74.666667 | J6: =89.6/1.2 -> 74.666667 | M6: 102 | N6: 102 | O6: 0 | Q6: 50 | R6: 32 | S6: 32 | T6: Клиент изменил план | U6: 0 | V6: 50 | W6: 50 | X6: Клиент изменил план | Y6: 40 | Z6: 50 | AA6: 50 | AB6: Клиент изменил план | AC6: 40 | AD6: 40 | AE6: 0 | AG6: 40 | AH6: 25 | AI6: 25 | AJ6: КамАЗ не дает в необходимом объеме шасси для выполнения ранее намеченного плана по производству-продаже | AK6: 40 | AL6: 25 | AM6: 25 | AN6: КамАЗ не дает в необходимом объеме шасси для выполнения ранее намеченного плана по производству-продаже | AO6: 40 | AP6: 0 | AQ6: 0 | AR6: КамАЗ не дает в необходимом объеме шасси для выполнения ранее намеченного плана по производству-продаже | AS6: 40 | AT6: 0 | AU6: 0 | AV6: КамАЗ не дает в необходимом объеме шасси для выполнения ранее намеченного плана по производству-продаже, также имеет место общее снижение спроса | AW6: 40 | AX6: 0 | AY6: 0 | AZ6: КамАЗ не дает в необходимом объеме шасси для выполнения ранее намеченного плана по производству-продаже, также имеет место общее снижение спроса | BA6: 40 | BB6: 0 | BC6: 0 | BD6: КамАЗ не дает в необходимом объеме шасси для выполнения ранее намеченного плана по производству-продаже, также имеет место общее снижение спроса | BE6: 40 | BF6: 0 | BG6: 0 | BH6: КамАЗ не дает в необходимом объеме шасси для выполнения ранее намеченного плана по производству-продаже, также имеет место общее снижение спроса | BI6: =SUMPRODUCT(--(MOD(COLUMN($M6:$BH6),4)=MOD(COLUMN($M6),4)),$M6:$BH6) -> 512 | BJ6: =BI6*$I6 -> 38229.333 | BK6: =SUMPRODUCT(--(MOD(COLUMN($M6:$BH6),4)=MOD(COLUMN($M6)+1,4)),$M6:$BH6) -> 324 | BL6: =BK6*$I6 -> 24192 | BM6: =SUMPRODUCT(--(MOD(COLUMN($M6:$BH6),4)=MOD(COLUMN($M6)+2,4)),$M6:$BH6) -> 182 | BN6: =BM6*$I6 -> 13589.333 | BO6: =$KN6*0 -> 0 | BP6: =$KN6*0 -> 0 | BQ6: =$KN6*0 -> 0 | BR6: 0 | BT6: =$KN6*5 -> 5 | BU6: =$KN6*0 -> 0 | BV6: =$KN6*0 -> 0 | BW6: 0 | BY6: =$KN6*15 -> 15 | BZ6: =$KN6*15 -> 15 | CA6: =$KN6*0 -> 0 | CB6: 0 | CD6: =$KN6*15 -> 15 | CE6: =$KN6*15 -> 15 | CF6: =$KN6*0 -> 0 | CG6: 0 | CI6: =$KN6*15 -> 15 | CJ6: =$KN6*15 -> 15 | CK6: =$KN6*0 -> 0 | CL6: 0 | CN6: =$KN6*15 -> 15 | CO6: =$KN6*15 -> 15 | CP6: =$KN6*0 -> 0 | CQ6: 0 | CS6: =$KN6*15 -> 15 | CT6: =$KN6*15 -> 15 | CU6: =$KN6*0 -> 0 | CV6: 0 | CX6: =$KN6*15 -> 15 | CY6: =$KN6*15 -> 15 | CZ6: =$KN6*0 -> 0 | DA6: 0 | DC6: =$KN6*15 -> 15 | DD6: =$KN6*15 -> 15 | DE6: =$KN6*0 -> 0 | DF6: 0 | DH6: =$KN6*15 -> 15 | DI6: =$KN6*15 -> 15 | DJ6: =$KN6*0 -> 0 | DK6: 0 | DM6: =$KN6*15 -> 15 | DN6: 15 | DO6: =$KN6*0 -> 0 | DP6: 0 | DR6: 15 | DS6: 15 | DT6: 0 | DU6: 0 | DW6: {=SUMPRODUCT(--(MOD(COLUMN($BO6:$DV6),5)=MOD(COLUMN($BO6),5)),$BO6:$DV6)} -> 155 | DX6: =DW6*$J6 -> 11573.333 | DY6: {=SUMPRODUCT(--(MOD(COLUMN($BO6:$DV6),5)=MOD(COLUMN($BP6),5)),$BO6:$DV6)} -> 150 | DZ6: =DY6*$J6 -> 11200 | EA6: {=SUMPRODUCT(--(MOD(COLUMN($BO6:$DV6),5)=MOD(COLUMN($BQ6),5)),$BO6:$DV6)} -> 0 | EB6: =EA6*$J6 -> 0 | EC6: {=SUMPRODUCT(--(MOD(COLUMN($BO6:$DV6),5)=MOD(COLUMN($BR6),5)),$BO6:$DV6)} -> 0 | ED6: =EC6*$J6 -> 0 | EE6: =$KN6*8 -> 8 | EF6: 8 | EG6: 0 | EI6: =$KN6*9 -> 9 | EJ6: 50 | EK6: 0 | EM6: =$KN6*9 -> 9 | EN6: 0 | EQ6: =$KN6*15 -> 15 | ER6: 1 | EU6: =$KN6*15 -> 15 | EV6: 0 | EY6: =$KN6*15 -> 15 | EZ6: 45 | FC6: =$KN6*15 -> 15 | FD6: 15 | FG6: =$KN6*15 -> 15 | FH6: 15 | FK6: =$KN6*15 -> 15 | FL6: 15 | FO6: =$KN6*15 -> 15 | FP6: 15 | FS6: =$KN6*14 -> 14 | FT6: 14 | FW6: =$KN6*10 -> 10 | FX6: 10 | GA6: =SUMPRODUCT(--(MOD(COLUMN($EE6:$FZ6),4)=MOD(COLUMN($EE6),4)),$EE6:$FZ6) -> 155 | GB6: =GA6*$J6 -> 11573.333 | GC6: =SUMPRODUCT(--(MOD(COLUMN($EE6:$FZ6),4)=MOD(COLUMN($EF6),4)),$EE6:$FZ6) -> 188 | GD6: =GC6*$J6 -> 14037.333 | GE6: =SUMPRODUCT(--(MOD(COLUMN($EE6:$FZ6),4)=MOD(COLUMN($EG6),4)),$EE6:$FZ6) -> 0 | GF6: =GE6*$J6 -> 0 | GG6: =$KN6*10 -> 10 | GK6: =$KN6*10 -> 10 | GO6: =$KN6*15 -> 15 | GS6: =$KN6*20 -> 20 | GW6: =$KN6*20 -> 20 | HA6: =$KN6*20 -> 20 | HE6: =$KN6*20 -> 20 | HI6: =$KN6*20 -> 20 | HM6: =$KN6*20 -> 20 | HQ6: =$KN6*20 -> 20 | HU6: =$KN6*20 -> 20 | HY6: 20 | IC6: {=SUMPRODUCT(--(MOD(COLUMN($GG6:$IB6),4)=MOD(COLUMN($GG6),4)),$GG6:$IB6)} -> 215 | ID6: =IC6*$J6 -> 16053.333 | IE6: {=SUMPRODUCT(--(MOD(COLUMN($GG6:$IB6),4)=MOD(COLUMN($GH6),4)),$GG6:$IB6)} -> 0 | IF6: =IE6*$J6 -> 0 | IG6: {=SUMPRODUCT(--(MOD(COLUMN($GG6:$IB6),4)=MOD(COLUMN($GI6),4)),$GG6:$IB6)} -> 0 | IH6: =IG6*$J6 -> 0 | II6: =$KN6*15 -> 15 | IM6: =$KN6*15 -> 15 | IQ6: =$KN6*20 -> 20 | IU6: =$KN6*25 -> 25 | IY6: =$KN6*25 -> 25 | JC6: =$KN6*25 -> 25 | JG6: =$KN6*30 -> 30 | JK6: =$KN6*30 -> 30 | JO6: =$KN6*30 -> 30 | JS6: =$KN6*30 -> 30 | JW6: =$KN6*30 -> 30 | KA6: 30 | KE6: {=SUMPRODUCT(--(MOD(COLUMN($II6:$KD6),4)=MOD(COLUMN($II6),4)),$II6:$KD6)} -> 305 | KF6: =KE6*$J6 -> 22773.333 | KG6: {=SUMPRODUCT(--(MOD(COLUMN($II6:$KD6),4)=MOD(COLUMN($IJ6),4)),$II6:$KD6)} -> 0 | KH6: =KG6*$J6 -> 0 | KI6: {=SUMPRODUCT(--(MOD(COLUMN($II6:$KD6),4)=MOD(COLUMN($IK6),4)),$II6:$KD6)} -> 0 | KJ6: =KI6*$J6 -> 0 | KN6: 1 | KO6: TEBS 2s/2m 12м
E7: 2 | F7: 1 | G7: 9522010020 | H7: Головка соединительная (питающая) | I7: =89.6/1.2 -> 74.666667 | J7: =89.6/1.2 -> 74.666667 | M7: 102 | N7: 102 | O7: 0 | Q7: 50 | R7: 32 | S7: 32 | U7: 0 | V7: 50 | W7: 50 | Y7: 40 | Z7: 50 | AA7: 50 | AC7: 40 | AD7: 40 | AE7: 0 | AG7: 40 | AH7: 25 | AI7: 25 | AK7: 40 | AL7: 25 | AM7: 25 | AO7: 40 | AP7: 0 | AQ7: 0 | AS7: 40 | AT7: 0 | AU7: 0 | AW7: 40 | AX7: 0 | AY7: 0 | BA7: 40 | BB7: 0 | BC7: 0 | BE7: 40 | BF7: =$KN7*0 -> 0 | BG7: 0 | BI7: =SUMPRODUCT(--(MOD(COLUMN($M7:$BH7),4)=MOD(COLUMN($M7),4)),$M7:$BH7) -> 512 | BJ7: =BI7*$I7 -> 38229.333 | BK7: =SUMPRODUCT(--(MOD(COLUMN($M7:$BH7),4)=MOD(COLUMN($M7)+1,4)),$M7:$BH7) -> 324 | BL7: =BK7*$I7 -> 24192 | BM7: =SUMPRODUCT(--(MOD(COLUMN($M7:$BH7),4)=MOD(COLUMN($M7)+2,4)),$M7:$BH7) -> 182 | BN7: =BM7*$I7 -> 13589.333 | BO7: =$KN7*0 -> 0 | BP7: =$KN7*0 -> 0 | BQ7: =$KN7*0 -> 0 | BR7: 0 | BT7: =$KN7*5 -> 5 | BU7: =$KN7*0 -> 0 | BV7: =$KN7*0 -> 0 | BW7: 0 | BY7: =$KN7*15 -> 15 | BZ7: =$KN7*15 -> 15 | CA7: =$KN7*0 -> 0 | CB7: 0 | CD7: =$KN7*15 -> 15 | CE7: =$KN7*15 -> 15 | CF7: =$KN7*0 -> 0 | CG7: 0 | CI7: =$KN7*15 -> 15 | CJ7: =$KN7*15 -> 15 | CK7: =$KN7*0 -> 0 | CL7: 0 | CN7: =$KN7*15 -> 15 | CO7: =$KN7*15 -> 15 | CP7: =$KN7*0 -> 0 | CQ7: 0 | CS7: =$KN7*15 -> 15 | CT7: =$KN7*15 -> 15 | CU7: =$KN7*0 -> 0 | CV7: 0 | CX7: =$KN7*15 -> 15 | CY7: =$KN7*15 -> 15 | CZ7: =$KN7*0 -> 0 | DA7: 0 | DC7: =$KN7*15 -> 15 | DD7: =$KN7*15 -> 15 | DE7: =$KN7*0 -> 0 | DF7: 0 | DH7: =$KN7*15 -> 15 | DI7: =$KN7*15 -> 15 | DJ7: =$KN7*0 -> 0 | DK7: 0 | DM7: =$KN7*15 -> 15 | DN7: =$KN7*15 -> 15 | DO7: =$KN7*0 -> 0 | DP7: 0 | DR7: =$KN7*15 -> 15 | DS7: =$KN7*15 -> 15 | DT7: =$KN7*0 -> 0 | DU7: 0 | DW7: {=SUMPRODUCT(--(MOD(COLUMN($BO7:$DV7),5)=MOD(COLUMN($BO7),5)),$BO7:$DV7)} -> 155 | DX7: =DW7*$J7 -> 11573.333 | DY7: {=SUMPRODUCT(--(MOD(COLUMN($BO7:$DV7),5)=MOD(COLUMN($BP7),5)),$BO7:$DV7)} -> 150 | DZ7: =DY7*$J7 -> 11200 | EA7: {=SUMPRODUCT(--(MOD(COLUMN($BO7:$DV7),5)=MOD(COLUMN($BQ7),5)),$BO7:$DV7)} -> 0 | EB7: =EA7*$J7 -> 0 | EC7: {=SUMPRODUCT(--(MOD(COLUMN($BO7:$DV7),5)=MOD(COLUMN($BR7),5)),$BO7:$DV7)} -> 0 | ED7: =EC7*$J7 -> 0 | EE7: =$KN7*8 -> 8 | EF7: 8 | EG7: 0 | EI7: =$KN7*9 -> 9 | EJ7: 50 | EK7: 0 | EM7: =$KN7*9 -> 9 | EN7: 0 | EQ7: =$KN7*15 -> 15 | ER7: 1 | EU7: =$KN7*15 -> 15 | EV7: 0 | EY7: =$KN7*15 -> 15 | EZ7: 45 | FC7: =$KN7*15 -> 15 | FD7: 15 | FG7: =$KN7*15 -> 15 | FH7: 15 | FK7: =$KN7*15 -> 15 | FL7: 15 | FO7: =$KN7*15 -> 15 | FP7: 15 | FS7: =$KN7*14 -> 14 | FT7: 14 | FW7: =$KN7*10 -> 10 | FX7: 10 | GA7: =SUMPRODUCT(--(MOD(COLUMN($EE7:$FZ7),4)=MOD(COLUMN($EE7),4)),$EE7:$FZ7) -> 155 | GB7: =GA7*$J7 -> 11573.333 | GC7: =SUMPRODUCT(--(MOD(COLUMN($EE7:$FZ7),4)=MOD(COLUMN($EF7),4)),$EE7:$FZ7) -> 188 | GD7: =GC7*$J7 -> 14037.333 | GE7: =SUMPRODUCT(--(MOD(COLUMN($EE7:$FZ7),4)=MOD(COLUMN($EG7),4)),$EE7:$FZ7) -> 0 | GF7: =GE7*$J7 -> 0 | GG7: =$KN7*10 -> 10 | GK7: =$KN7*10 -> 10 | GO7: =$KN7*15 -> 15 | GS7: =$KN7*20 -> 20 | GW7: =$KN7*20 -> 20 | HA7: =$KN7*20 -> 20 | HE7: =$KN7*20 -> 20 | HI7: =$KN7*20 -> 20 | HM7: =$KN7*20 -> 20 | HQ7: =$KN7*20 -> 20 | HU7: =$KN7*20 -> 20 | HY7: =$KN7*20 -> 20 | IC7: {=SUMPRODUCT(--(MOD(COLUMN($GG7:$IB7),4)=MOD(COLUMN($GG7),4)),$GG7:$IB7)} -> 215 | ID7: =IC7*$J7 -> 16053.333 | IE7: {=SUMPRODUCT(--(MOD(COLUMN($GG7:$IB7),4)=MOD(COLUMN($GH7),4)),$GG7:$IB7)} -> 0 | IF7: =IE7*$J7 -> 0 | IG7: {=SUMPRODUCT(--(MOD(COLUMN($GG7:$IB7),4)=MOD(COLUMN($GI7),4)),$GG7:$IB7)} -> 0 | IH7: =IG7*$J7 -> 0 | II7: =$KN7*15 -> 15 | IM7: =$KN7*15 -> 15 | IQ7: =$KN7*20 -> 20 | IU7: =$KN7*25 -> 25 | IY7: =$KN7*25 -> 25 | JC7: =$KN7*25 -> 25 | JG7: =$KN7*30 -> 30 | JK7: =$KN7*30 -> 30 | JO7: =$KN7*30 -> 30 | JS7: =$KN7*30 -> 30 | JW7: =$KN7*30 -> 30 | KA7: 30 | KE7: {=SUMPRODUCT(--(MOD(COLUMN($II7:$KD7),4)=MOD(COLUMN($II7),4)),$II7:$KD7)} -> 305 | KF7: =KE7*$J7 -> 22773.333 | KG7: {=SUMPRODUCT(--(MOD(COLUMN($II7:$KD7),4)=MOD(COLUMN($IJ7),4)),$II7:$KD7)} -> 0 | KH7: =KG7*$J7 -> 0 | KI7: {=SUMPRODUCT(--(MOD(COLUMN($II7:$KD7),4)=MOD(COLUMN($IK7),4)),$II7:$KD7)} -> 0 | KJ7: =KI7*$J7 -> 0 | KN7: 1
E8: 3 | F8: 1 | G8: 9710029000 | H8: Воздухораспределитель с клапаном растормаживания | I8: =639/1.2 -> 532.5 | J8: =639/1.2 -> 532.5 | M8: 102 | N8: 102 | O8: 0 | Q8: 50 | R8: 32 | S8: 32 | U8: 0 | V8: 50 | W8: 50 | Y8: 40 | Z8: 50 | AA8: 50 | AC8: 40 | AD8: 40 | AE8: 0 | AG8: 40 | AH8: 25 | AI8: 25 | AK8: 40 | AL8: 25 | AM8: 25 | AO8: 40 | AP8: 0 | AQ8: 0 | AS8: 40 | AT8: 0 | AU8: 0 | AW8: 40 | AX8: 0 | AY8: 0 | BA8: 40 | BB8: 0 | BC8: 0 | BE8: 40 | BF8: =$KN8*0 -> 0 | BG8: 0 | BI8: =SUMPRODUCT(--(MOD(COLUMN($M8:$BH8),4)=MOD(COLUMN($M8),4)),$M8:$BH8) -> 512 | BJ8: =BI8*$I8 -> 272640 | BK8: =SUMPRODUCT(--(MOD(COLUMN($M8:$BH8),4)=MOD(COLUMN($M8)+1,4)),$M8:$BH8) -> 324 | BL8: =BK8*$I8 -> 172530 | BM8: =SUMPRODUCT(--(MOD(COLUMN($M8:$BH8),4)=MOD(COLUMN($M8)+2,4)),$M8:$BH8) -> 182 | BN8: =BM8*$I8 -> 96915 | BO8: =$KN8*0 -> 0 | BP8: =$KN8*0 -> 0 | BQ8: =$KN8*0 -> 0 | BR8: 0 | BT8: =$KN8*5 -> 5 | BU8: =$KN8*0 -> 0 | BV8: =$KN8*0 -> 0 | BW8: 0 | BY8: =$KN8*15 -> 15 | BZ8: =$KN8*15 -> 15 | CA8: =$KN8*0 -> 0 | CB8: 0 | CD8: =$KN8*15 -> 15 | CE8: =$KN8*15 -> 15 | CF8: =$KN8*0 -> 0 | CG8: 0 | CI8: =$KN8*15 -> 15 | CJ8: =$KN8*15 -> 15 | CK8: =$KN8*0 -> 0 | CL8: 0 | CN8: =$KN8*15 -> 15 | CO8: =$KN8*15 -> 15 | CP8: =$KN8*0 -> 0 | CQ8: 0 | CS8: =$KN8*15 -> 15 | CT8: =$KN8*15 -> 15 | CU8: =$KN8*0 -> 0 | CV8: 0 | CX8: =$KN8*15 -> 15 | CY8: =$KN8*15 -> 15 | CZ8: =$KN8*0 -> 0 | DA8: 0 | DC8: =$KN8*15 -> 15 | DD8: =$KN8*15 -> 15 | DE8: =$KN8*0 -> 0 | DF8: 0 | DH8: =$KN8*15 -> 15 | DI8: =$KN8*15 -> 15 | DJ8: =$KN8*0 -> 0 | DK8: 0 | DM8: =$KN8*15 -> 15 | DN8: =$KN8*15 -> 15 | DO8: =$KN8*0 -> 0 | DP8: 0 | DR8: =$KN8*15 -> 15 | DS8: =$KN8*15 -> 15 | DT8: =$KN8*0 -> 0 | DU8: 0 | DW8: {=SUMPRODUCT(--(MOD(COLUMN($BO8:$DV8),5)=MOD(COLUMN($BO8),5)),$BO8:$DV8)} -> 155 | DX8: =DW8*$J8 -> 82537.5 | DY8: {=SUMPRODUCT(--(MOD(COLUMN($BO8:$DV8),5)=MOD(COLUMN($BP8),5)),$BO8:$DV8)} -> 150 | DZ8: =DY8*$J8 -> 79875 | EA8: {=SUMPRODUCT(--(MOD(COLUMN($BO8:$DV8),5)=MOD(COLUMN($BQ8),5)),$BO8:$DV8)} -> 0 | EB8: =EA8*$J8 -> 0 | EC8: {=SUMPRODUCT(--(MOD(COLUMN($BO8:$DV8),5)=MOD(COLUMN($BR8),5)),$BO8:$DV8)} -> 0 | ED8: =EC8*$J8 -> 0 | EE8: =$KN8*8 -> 8 | EF8: 8 | EG8: 0 | EI8: =$KN8*9 -> 9 | EJ8: 50 | EK8: 0 | EM8: =$KN8*9 -> 9 | EN8: 0 | EQ8: =$KN8*15 -> 15 | ER8: 1 | EU8: =$KN8*15 -> 15 | EV8: 0 | EY8: =$KN8*15 -> 15 | EZ8: 45 | FC8: =$KN8*15 -> 15 | FD8: 15 | FG8: =$KN8*15 -> 15 | FH8: 15 | FK8: =$KN8*15 -> 15 | FL8: 15 | FO8: =$KN8*15 -> 15 | FP8: 15 | FS8: =$KN8*14 -> 14 | FT8: 14 | FW8: =$KN8*10 -> 10 | FX8: 10 | GA8: =SUMPRODUCT(--(MOD(COLUMN($EE8:$FZ8),4)=MOD(COLUMN($EE8),4)),$EE8:$FZ8) -> 155 | GB8: =GA8*$J8 -> 82537.5 | GC8: =SUMPRODUCT(--(MOD(COLUMN($EE8:$FZ8),4)=MOD(COLUMN($EF8),4)),$EE8:$FZ8) -> 188 | GD8: =GC8*$J8 -> 100110 | GE8: =SUMPRODUCT(--(MOD(COLUMN($EE8:$FZ8),4)=MOD(COLUMN($EG8),4)),$EE8:$FZ8) -> 0 | GF8: =GE8*$J8 -> 0 | GG8: =$KN8*10 -> 10 | GK8: =$KN8*10 -> 10 | GO8: =$KN8*15 -> 15 | GS8: =$KN8*20 -> 20 | GW8: =$KN8*20 -> 20 | HA8: =$KN8*20 -> 20 | HE8: =$KN8*20 -> 20 | HI8: =$KN8*20 -> 20 | HM8: =$KN8*20 -> 20 | HQ8: =$KN8*20 -> 20 | HU8: =$KN8*20 -> 20 | HY8: =$KN8*20 -> 20 | IC8: {=SUMPRODUCT(--(MOD(COLUMN($GG8:$IB8),4)=MOD(COLUMN($GG8),4)),$GG8:$IB8)} -> 215 | ID8: =IC8*$J8 -> 114487.5 | IE8: {=SUMPRODUCT(--(MOD(COLUMN($GG8:$IB8),4)=MOD(COLUMN($GH8),4)),$GG8:$IB8)} -> 0 | IF8: =IE8*$J8 -> 0 | IG8: {=SUMPRODUCT(--(MOD(COLUMN($GG8:$IB8),4)=MOD(COLUMN($GI8),4)),$GG8:$IB8)} -> 0 | IH8: =IG8*$J8 -> 0 | II8: =$KN8*15 -> 15 | IM8: =$KN8*15 -> 15 | IQ8: =$KN8*20 -> 20 | IU8: =$KN8*25 -> 25 | IY8: =$KN8*25 -> 25 | JC8: =$KN8*25 -> 25 | JG8: =$KN8*30 -> 30 | JK8: =$KN8*30 -> 30 | JO8: =$KN8*30 -> 30 | JS8: =$KN8*30 -> 30 | JW8: =$KN8*30 -> 30 | KA8: 30 | KE8: {=SUMPRODUCT(--(MOD(COLUMN($II8:$KD8),4)=MOD(COLUMN($II8),4)),$II8:$KD8)} -> 305 | KF8: =KE8*$J8 -> 162412.5 | KG8: {=SUMPRODUCT(--(MOD(COLUMN($II8:$KD8),4)=MOD(COLUMN($IJ8),4)),$II8:$KD8)} -> 0 | KH8: =KG8*$J8 -> 0 | KI8: {=SUMPRODUCT(--(MOD(COLUMN($II8:$KD8),4)=MOD(COLUMN($IK8),4)),$II8:$KD8)} -> 0 | KJ8: =KI8*$J8 -> 0 | KN8: 1
E9: 4 | F9: 1 | G9: 4801020640 | H9: Модулятор EBS, с PEM, без фит. | I9: =4169.1/1.2*1.048 -> 3641.014 | J9: =4169/1.2*1.048*1.05 -> 3822.973 | M9: 102 | N9: 102 | O9: 0 | Q9: 50 | R9: 32 | S9: 32 | U9: 0 | V9: 50 | W9: 50 | Y9: 40 | Z9: 50 | AA9: 50 | AC9: 40 | AD9: 40 | AE9: 0 | AG9: 40 | AH9: 25 | AI9: 25 | AK9: 40 | AL9: 25 | AM9: 25 | AO9: 40 | AP9: 0 | AQ9: 0 | AS9: 40 | AT9: 0 | AU9: 0 | AW9: 40 | AX9: 0 | AY9: 0 | BA9: 40 | BB9: 0 | BC9: 0 | BE9: 40 | BF9: =$KN9*0 -> 0 | BG9: 0 | BI9: =SUMPRODUCT(--(MOD(COLUMN($M9:$BH9),4)=MOD(COLUMN($M9),4)),$M9:$BH9) -> 512 | BJ9: =BI9*$I9 -> 1864199.2 | BK9: =SUMPRODUCT(--(MOD(COLUMN($M9:$BH9),4)=MOD(COLUMN($M9)+1,4)),$M9:$BH9) -> 324 | BL9: =BK9*$I9 -> 1179688.5 | BM9: =SUMPRODUCT(--(MOD(COLUMN($M9:$BH9),4)=MOD(COLUMN($M9)+2,4)),$M9:$BH9) -> 182 | BN9: =BM9*$I9 -> 662664.55 | BO9: =$KN9*0 -> 0 | BP9: =$KN9*0 -> 0 | BQ9: =$KN9*0 -> 0 | BR9: 0 | BT9: =$KN9*5 -> 5 | BU9: =$KN9*0 -> 0 | BV9: =$KN9*0 -> 0 | BW9: 0 | BY9: =$KN9*15 -> 15 | BZ9: =$KN9*15 -> 15 | CA9: =$KN9*0 -> 0 | CB9: 0 | CD9: =$KN9*15 -> 15 | CE9: =$KN9*15 -> 15 | CF9: =$KN9*0 -> 0 | CG9: 0 | CI9: =$KN9*15 -> 15 | CJ9: =$KN9*15 -> 15 | CK9: =$KN9*0 -> 0 | CL9: 0 | CN9: =$KN9*15 -> 15 | CO9: =$KN9*15 -> 15 | CP9: =$KN9*0 -> 0 | CQ9: 0 | CS9: =$KN9*15 -> 15 | CT9: =$KN9*15 -> 15 | CU9: =$KN9*0 -> 0 | CV9: 0 | CX9: =$KN9*15 -> 15 | CY9: =$KN9*15 -> 15 | CZ9: =$KN9*0 -> 0 | DA9: 0 | DC9: =$KN9*15 -> 15 | DD9: =$KN9*15 -> 15 | DE9: =$KN9*0 -> 0 | DF9: 0 | DH9: =$KN9*15 -> 15 | DI9: =$KN9*15 -> 15 | DJ9: =$KN9*0 -> 0 | DK9: 0 | DM9: =$KN9*15 -> 15 | DN9: =$KN9*15 -> 15 | DO9: =$KN9*0 -> 0 | DP9: 0 | DR9: =$KN9*15 -> 15 | DS9: =$KN9*15 -> 15 | DT9: =$KN9*0 -> 0 | DU9: 0 | DW9: {=SUMPRODUCT(--(MOD(COLUMN($BO9:$DV9),5)=MOD(COLUMN($BO9),5)),$BO9:$DV9)} -> 155 | DX9: =DW9*$J9 -> 592560.82 | DY9: {=SUMPRODUCT(--(MOD(COLUMN($BO9:$DV9),5)=MOD(COLUMN($BP9),5)),$BO9:$DV9)} -> 150 | DZ9: =DY9*$J9 -> 573445.95 | EA9: {=SUMPRODUCT(--(MOD(COLUMN($BO9:$DV9),5)=MOD(COLUMN($BQ9),5)),$BO9:$DV9)} -> 0 | EB9: =EA9*$J9 -> 0 | EC9: {=SUMPRODUCT(--(MOD(COLUMN($BO9:$DV9),5)=MOD(COLUMN($BR9),5)),$BO9:$DV9)} -> 0 | ED9: =EC9*$J9 -> 0 | EE9: =$KN9*8 -> 8 | EF9: 8 | EG9: 0 | EI9: =$KN9*9 -> 9 | EJ9: 50 | EK9: 0 | EM9: =$KN9*9 -> 9 | EN9: 0 | EP9: Требуется перезаключение договора. Заказы смещены на 2 месяца | EQ9: =$KN9*15 -> 15 | ER9: 2 | ES9: 1 | EU9: =$KN9*15 -> 15 | EV9: 3 | EW9: 1 | EY9: =$KN9*15 -> 15 | EZ9: 45 | FC9: =$KN9*15 -> 15 | FD9: 15 | FG9: =$KN9*15 -> 15 | FH9: 15 | FK9: =$KN9*15 -> 15 | FL9: 15 | FO9: =$KN9*15 -> 15 | FP9: 15 | FS9: =$KN9*14 -> 14 | FT9: 14 | FW9: =$KN9*10 -> 10 | FX9: 10 | GA9: =SUMPRODUCT(--(MOD(COLUMN($EE9:$FZ9),4)=MOD(COLUMN($EE9),4)),$EE9:$FZ9) -> 155 | GB9: =GA9*$J9 -> 592560.82 | GC9: =SUMPRODUCT(--(MOD(COLUMN($EE9:$FZ9),4)=MOD(COLUMN($EF9),4)),$EE9:$FZ9) -> 192 | GD9: =GC9*$J9 -> 734010.82 | GE9: =SUMPRODUCT(--(MOD(COLUMN($EE9:$FZ9),4)=MOD(COLUMN($EG9),4)),$EE9:$FZ9) -> 2 | GF9: =GE9*$J9 -> 7645.946 | GG9: =$KN9*10 -> 10 | GK9: =$KN9*10 -> 10 | GO9: =$KN9*15 -> 15 | GS9: =$KN9*20 -> 20 | GW9: =$KN9*20 -> 20 | HA9: =$KN9*20 -> 20 | HE9: =$KN9*20 -> 20 | HI9: =$KN9*20 -> 20 | HM9: =$KN9*20 -> 20 | HQ9: =$KN9*20 -> 20 | HU9: =$KN9*20 -> 20 | HY9: =$KN9*20 -> 20 | IC9: {=SUMPRODUCT(--(MOD(COLUMN($GG9:$IB9),4)=MOD(COLUMN($GG9),4)),$GG9:$IB9)} -> 215 | ID9: =IC9*$J9 -> 821939.2 | IE9: {=SUMPRODUCT(--(MOD(COLUMN($GG9:$IB9),4)=MOD(COLUMN($GH9),4)),$GG9:$IB9)} -> 0 | IF9: =IE9*$J9 -> 0 | IG9: {=SUMPRODUCT(--(MOD(COLUMN($GG9:$IB9),4)=MOD(COLUMN($GI9),4)),$GG9:$IB9)} -> 0 | IH9: =IG9*$J9 -> 0 | II9: =$KN9*15 -> 15 | IM9: =$KN9*15 -> 15 | IQ9: =$KN9*20 -> 20 | IU9: =$KN9*25 -> 25 | IY9: =$KN9*25 -> 25 | JC9: =$KN9*25 -> 25 | JG9: =$KN9*30 -> 30 | JK9: =$KN9*30 -> 30 | JO9: =$KN9*30 -> 30 | JS9: =$KN9*30 -> 30 | JW9: =$KN9*30 -> 30 | KA9: 30 | KE9: {=SUMPRODUCT(--(MOD(COLUMN($II9:$KD9),4)=MOD(COLUMN($II9),4)),$II9:$KD9)} -> 305 | KF9: =KE9*$J9 -> 1166006.8 | KG9: {=SUMPRODUCT(--(MOD(COLUMN($II9:$KD9),4)=MOD(COLUMN($IJ9),4)),$II9:$KD9)} -> 0 | KH9: =KG9*$J9 -> 0 | KI9: {=SUMPRODUCT(--(MOD(COLUMN($II9:$KD9),4)=MOD(COLUMN($IK9),4)),$II9:$KD9)} -> 0 | KJ9: =KI9*$J9 -> 0 | KN9: 1
E10: 5 | F10: 1 | G10: 4491731200 | H10: Кабель питания, 12 м | I10: =842.2/1.2 -> 701.83333 | J10: =842.2/1.2 -> 701.83333 | M10: 102 | N10: 102 | O10: 0 | Q10: 50 | R10: 32 | S10: 32 | U10: 0 | V10: 50 | W10: 50 | Y10: 40 | Z10: 50 | AA10: 50 | AC10: 40 | AD10: 40 | AE10: 0 | AG10: 40 | AH10: 25 | AI10: 25 | AK10: 40 | AL10: 25 | AM10: 25 | AO10: 40 | AP10: 0 | AQ10: 0 | AS10: 40 | AT10: 0 | AU10: 0 | AW10: 40 | AX10: 0 | AY10: 0 | BA10: 40 | BB10: 0 | BC10: 0 | BE10: 40 | BF10: =$KN10*0 -> 0 | BG10: 0 | BI10: =SUMPRODUCT(--(MOD(COLUMN($M10:$BH10),4)=MOD(COLUMN($M10),4)),$M10:$BH10) -> 512 | BJ10: =BI10*$I10 -> 359338.67 | BK10: =SUMPRODUCT(--(MOD(COLUMN($M10:$BH10),4)=MOD(COLUMN($M10)+1,4)),$M10:$BH10) -> 324 | BL10: =BK10*$I10 -> 227394 | BM10: =SUMPRODUCT(--(MOD(COLUMN($M10:$BH10),4)=MOD(COLUMN($M10)+2,4)),$M10:$BH10) -> 182 | BN10: =BM10*$I10 -> 127733.67 | BO10: =$KN10*0 -> 0 | BP10: =$KN10*0 -> 0 | BQ10: =$KN10*0 -> 0 | BR10: 0 | BT10: =$KN10*5 -> 5 | BU10: =$KN10*0 -> 0 | BV10: =$KN10*0 -> 0 | BW10: 0 | BY10: =$KN10*15 -> 15 | BZ10: =$KN10*15 -> 15 | CA10: =$KN10*0 -> 0 | CB10: 0 | CD10: =$KN10*15 -> 15 | CE10: =$KN10*15 -> 15 | CF10: =$KN10*0 -> 0 | CG10: 0 | CI10: =$KN10*15 -> 15 | CJ10: =$KN10*15 -> 15 | CK10: =$KN10*0 -> 0 | CL10: 0 | CN10: =$KN10*15 -> 15 | CO10: =$KN10*15 -> 15 | CP10: =$KN10*0 -> 0 | CQ10: 0 | CS10: =$KN10*15 -> 15 | CT10: =$KN10*15 -> 15 | CU10: =$KN10*0 -> 0 | CV10: 0 | CX10: =$KN10*15 -> 15 | CY10: =$KN10*15 -> 15 | CZ10: =$KN10*0 -> 0 | DA10: 0 | DC10: =$KN10*15 -> 15 | DD10: =$KN10*15 -> 15 | DE10: =$KN10*0 -> 0 | DF10: 0 | DH10: =$KN10*15 -> 15 | DI10: =$KN10*15 -> 15 | DJ10: =$KN10*0 -> 0 | DK10: 0 | DM10: =$KN10*15 -> 15 | DN10: =$KN10*15 -> 15 | DO10: =$KN10*0 -> 0 | DP10: 0 | DR10: =$KN10*15 -> 15 | DS10: =$KN10*15 -> 15 | DT10: =$KN10*0 -> 0 | DU10: 0 | DW10: {=SUMPRODUCT(--(MOD(COLUMN($BO10:$DV10),5)=MOD(COLUMN($BO10),5)),$BO10:$DV10)} -> 155 | DX10: =DW10*$J10 -> 108784.17 | DY10: {=SUMPRODUCT(--(MOD(COLUMN($BO10:$DV10),5)=MOD(COLUMN($BP10),5)),$BO10:$DV10)} -> 150 | DZ10: =DY10*$J10 -> 105275 | EA10: {=SUMPRODUCT(--(MOD(COLUMN($BO10:$DV10),5)=MOD(COLUMN($BQ10),5)),$BO10:$DV10)} -> 0 | EB10: =EA10*$J10 -> 0 | EC10: {=SUMPRODUCT(--(MOD(COLUMN($BO10:$DV10),5)=MOD(COLUMN($BR10),5)),$BO10:$DV10)} -> 0 | ED10: =EC10*$J10 -> 0 | EE10: =$KN10*8 -> 8 | EF10: 8 | EG10: 0 | EI10: =$KN10*9 -> 9 | EJ10: 50 | EK10: 0 | EM10: =$KN10*9 -> 9 | EN10: 0 | EQ10: =$KN10*15 -> 15 | ER10: 1 | EU10: =$KN10*15 -> 15 | EV10: 0 | EY10: =$KN10*15 -> 15 | EZ10: 45 | FC10: =$KN10*15 -> 15 | FD10: 15 | FG10: =$KN10*15 -> 15 | FH10: 15 | FK10: =$KN10*15 -> 15 | FL10: 15 | FO10: =$KN10*15 -> 15 | FP10: 15 | FS10: =$KN10*14 -> 14 | FT10: 14 | FW10: =$KN10*10 -> 10 | FX10: 10 | GA10: =SUMPRODUCT(--(MOD(COLUMN($EE10:$FZ10),4)=MOD(COLUMN($EE10),4)),$EE10:$FZ10) -> 155 | GB10: =GA10*$J10 -> 108784.17 | GC10: =SUMPRODUCT(--(MOD(COLUMN($EE10:$FZ10),4)=MOD(COLUMN($EF10),4)),$EE10:$FZ10) -> 188 | GD10: =GC10*$J10 -> 131944.67 | GE10: =SUMPRODUCT(--(MOD(COLUMN($EE10:$FZ10),4)=MOD(COLUMN($EG10),4)),$EE10:$FZ10) -> 0 | GF10: =GE10*$J10 -> 0 | GG10: =$KN10*10 -> 10 | GK10: =$KN10*10 -> 10 | GO10: =$KN10*15 -> 15 | GS10: =$KN10*20 -> 20 | GW10: =$KN10*20 -> 20 | HA10: =$KN10*20 -> 20 | HE10: =$KN10*20 -> 20 | HI10: =$KN10*20 -> 20 | HM10: =$KN10*20 -> 20 | HQ10: =$KN10*20 -> 20 | HU10: =$KN10*20 -> 20 | HY10: =$KN10*20 -> 20 | IC10: {=SUMPRODUCT(--(MOD(COLUMN($GG10:$IB10),4)=MOD(COLUMN($GG10),4)),$GG10:$IB10)} -> 215 | ID10: =IC10*$J10 -> 150894.17 | IE10: {=SUMPRODUCT(--(MOD(COLUMN($GG10:$IB10),4)=MOD(COLUMN($GH10),4)),$GG10:$IB10)} -> 0 | IF10: =IE10*$J10 -> 0 | IG10: {=SUMPRODUCT(--(MOD(COLUMN($GG10:$IB10),4)=MOD(COLUMN($GI10),4)),$GG10:$IB10)} -> 0 | IH10: =IG10*$J10 -> 0 | II10: =$KN10*15 -> 15 | IM10: =$KN10*15 -> 15 | IQ10: =$KN10*20 -> 20 | IU10: =$KN10*25 -> 25 | IY10: =$KN10*25 -> 25 | JC10: =$KN10*25 -> 25 | JG10: =$KN10*30 -> 30 | JK10: =$KN10*30 -> 30 | JO10: =$KN10*30 -> 30 | JS10: =$KN10*30 -> 30 | JW10: =$KN10*30 -> 30 | KA10: 30 | KE10: {=SUMPRODUCT(--(MOD(COLUMN($II10:$KD10),4)=MOD(COLUMN($II10),4)),$II10:$KD10)} -> 305 | KF10: =KE10*$J10 -> 214059.17 | KG10: {=SUMPRODUCT(--(MOD(COLUMN($II10:$KD10),4)=MOD(COLUMN($IJ10),4)),$II10:$KD10)} -> 0 | KH10: =KG10*$J10 -> 0 | KI10: {=SUMPRODUCT(--(MOD(COLUMN($II10:$KD10),4)=MOD(COLUMN($IK10),4)),$II10:$KD10)} -> 0 | KJ10: =KI10*$J10 -> 0 | KN10: 1
E11: 6 | F11: 1 | G11: 4497230500 | H11: Кабель датчика, 5 м | I11: =71.7/1.2 -> 59.75 | J11: =71.7/1.2 -> 59.75 | M11: 204 | N11: 204 | O11: 0 | Q11: 50 | R11: 64 | S11: 64 | U11: 0 | V11: 100 | W11: 100 | Y11: 80 | Z11: 100 | AA11: 100 | AC11: 80 | AD11: 80 | AE11: 0 | AG11: 80 | AH11: 50 | AI11: 25 | AK11: 80 | AL11: 50 | AM11: 50 | AO11: 80 | AP11: 0 | AQ11: 0 | AS11: 80 | AT11: 0 | AU11: 0 | AW11: 80 | AX11: 0 | AY11: 0 | BA11: 80 | BB11: 0 | BC11: 0 | BE11: 80 | BF11: =$KN11*0 -> 0 | BG11: 0 | BI11: =SUMPRODUCT(--(MOD(COLUMN($M11:$BH11),4)=MOD(COLUMN($M11),4)),$M11:$BH11) -> 974 | BJ11: =BI11*$I11 -> 58196.5 | BK11: =SUMPRODUCT(--(MOD(COLUMN($M11:$BH11),4)=MOD(COLUMN($M11)+1,4)),$M11:$BH11) -> 648 | BL11: =BK11*$I11 -> 38718 | BM11: =SUMPRODUCT(--(MOD(COLUMN($M11:$BH11),4)=MOD(COLUMN($M11)+2,4)),$M11:$BH11) -> 339 | BN11: =BM11*$I11 -> 20255.25 | BO11: =$KN11*0 -> 0 | BP11: =$KN11*0 -> 0 | BQ11: =$KN11*0 -> 0 | BR11: 0 | BT11: =$KN11*5 -> 10 | BU11: =$KN11*0 -> 0 | BV11: =$KN11*0 -> 0 | BW11: 0 | BY11: =$KN11*15 -> 30 | BZ11: =$KN11*15 -> 30 | CA11: =$KN11*0 -> 0 | CB11: 0 | CD11: =$KN11*15 -> 30 | CE11: =$KN11*15 -> 30 | CF11: =$KN11*0 -> 0 | CG11: 0 | CI11: =$KN11*15 -> 30 | CJ11: =$KN11*15 -> 30 | CK11: =$KN11*0 -> 0 | CL11: 0 | CN11: =$KN11*15 -> 30 | CO11: =$KN11*15 -> 30 | CP11: =$KN11*0 -> 0 | CQ11: 0 | CS11: =$KN11*15 -> 30 | CT11: =$KN11*15 -> 30 | CU11: =$KN11*0 -> 0 | CV11: 0 | CX11: =$KN11*15 -> 30 | CY11: =$KN11*15 -> 30 | CZ11: =$KN11*0 -> 0 | DA11: 0 | DC11: =$KN11*15 -> 30 | DD11: =$KN11*15 -> 30 | DE11: =$KN11*0 -> 0 | DF11: 0 | DH11: =$KN11*15 -> 30 | DI11: =$KN11*15 -> 30 | DJ11: =$KN11*0 -> 0 | DK11: 0 | DM11: =$KN11*15 -> 30 | DN11: =$KN11*15 -> 30 | DO11: =$KN11*0 -> 0 | DP11: 0 | DR11: =$KN11*15 -> 30 | DS11: =$KN11*15 -> 30 | DT11: =$KN11*0 -> 0 | DU11: 0 | DW11: {=SUMPRODUCT(--(MOD(COLUMN($BO11:$DV11),5)=MOD(COLUMN($BO11),5)),$BO11:$DV11)} -> 310 | DX11: =DW11*$J11 -> 18522.5 | DY11: {=SUMPRODUCT(--(MOD(COLUMN($BO11:$DV11),5)=MOD(COLUMN($BP11),5)),$BO11:$DV11)} -> 300 | DZ11: =DY11*$J11 -> 17925 | EA11: {=SUMPRODUCT(--(MOD(COLUMN($BO11:$DV11),5)=MOD(COLUMN($BQ11),5)),$BO11:$DV11)} -> 0 | EB11: =EA11*$J11 -> 0 | EC11: {=SUMPRODUCT(--(MOD(COLUMN($BO11:$DV11),5)=MOD(COLUMN($BR11),5)),$BO11:$DV11)} -> 0 | ED11: =EC11*$J11 -> 0 | EE11: =$KN11*8+100 -> 116 | EF11: 16 | EG11: 0 | EI11: =$KN11*9 -> 18 | EJ11: 100 | EK11: 0 | EM11: =$KN11*9 -> 18 | EN11: 0 | EQ11: =$KN11*15 -> 30 | ER11: 2 | EU11: =$KN11*15 -> 30 | EV11: 0 | EY11: =$KN11*15 -> 30 | EZ11: 90 | FC11: =$KN11*15 -> 30 | FD11: 30 | FG11: =$KN11*15 -> 30 | FH11: 30 | FK11: =$KN11*15 -> 30 | FL11: 30 | FO11: =$KN11*15 -> 30 | FP11: 30 | FS11: =$KN11*14 -> 28 | FT11: 28 | FW11: =$KN11*10 -> 20 | FX11: 20 | GA11: =SUMPRODUCT(--(MOD(COLUMN($EE11:$FZ11),4)=MOD(COLUMN($EE11),4)),$EE11:$FZ11) -> 410 | GB11: =GA11*$J11 -> 24497.5 | GC11: =SUMPRODUCT(--(MOD(COLUMN($EE11:$FZ11),4)=MOD(COLUMN($EF11),4)),$EE11:$FZ11) -> 376 | GD11: =GC11*$J11 -> 22466 | GE11: =SUMPRODUCT(--(MOD(COLUMN($EE11:$FZ11),4)=MOD(COLUMN($EG11),4)),$EE11:$FZ11) -> 0 | GF11: =GE11*$J11 -> 0 | GG11: =$KN11*10 -> 20 | GK11: =$KN11*10 -> 20 | GO11: =$KN11*15 -> 30 | GS11: =$KN11*20 -> 40 | GW11: =$KN11*20 -> 40 | HA11: =$KN11*20 -> 40 | HE11: =$KN11*20 -> 40 | HI11: =$KN11*20 -> 40 | HM11: =$KN11*20 -> 40 | HQ11: =$KN11*20 -> 40 | HU11: =$KN11*20 -> 40 | HY11: =$KN11*20 -> 40 | IC11: {=SUMPRODUCT(--(MOD(COLUMN($GG11:$IB11),4)=MOD(COLUMN($GG11),4)),$GG11:$IB11)} -> 430 | ID11: =IC11*$J11 -> 25692.5 | IE11: {=SUMPRODUCT(--(MOD(COLUMN($GG11:$IB11),4)=MOD(COLUMN($GH11),4)),$GG11:$IB11)} -> 0 | IF11: =IE11*$J11 -> 0 | IG11: {=SUMPRODUCT(--(MOD(COLUMN($GG11:$IB11),4)=MOD(COLUMN($GI11),4)),$GG11:$IB11)} -> 0 | IH11: =IG11*$J11 -> 0 | II11: =$KN11*15 -> 30 | IM11: =$KN11*15 -> 30 | IQ11: =$KN11*20 -> 40 | IU11: =$KN11*25 -> 50 | IY11: =$KN11*25 -> 50 | JC11: =$KN11*25 -> 50 | JG11: =$KN11*30 -> 60 | JK11: =$KN11*30 -> 60 | JO11: =$KN11*30 -> 60 | JS11: =$KN11*30 -> 60 | JW11: =$KN11*30 -> 60 | KA11: 30 | KE11: {=SUMPRODUCT(--(MOD(COLUMN($II11:$KD11),4)=MOD(COLUMN($II11),4)),$II11:$KD11)} -> 580 | KF11: =KE11*$J11 -> 34655 | KG11: {=SUMPRODUCT(--(MOD(COLUMN($II11:$KD11),4)=MOD(COLUMN($IJ11),4)),$II11:$KD11)} -> 0 | KH11: =KG11*$J11 -> 0 | KI11: {=SUMPRODUCT(--(MOD(COLUMN($II11:$KD11),4)=MOD(COLUMN($IK11),4)),$II11:$KD11)} -> 0 | KJ11: =KI11*$J11 -> 0 | KN11: 2
E12: 7 | F12: 1 | G12: 4640061000 | H12: Кран уровня пола, 5-ти портовый | I12: =584/1.2 -> 486.66667 | J12: =584/1.2 -> 486.66667 | M12: 102 | N12: 102 | O12: 0 | Q12: 50 | R12: 32 | S12: 32 | U12: 0 | V12: 50 | W12: 50 | Y12: 40 | Z12: 50 | AA12: 50 | AC12: 40 | AD12: 40 | AE12: 0 | AG12: 40 | AH12: 25 | AI12: 25 | AK12: 40 | AL12: 25 | AM12: 25 | AO12: 40 | AP12: 0 | AQ12: 0 | AS12: 40 | AT12: 0 | AU12: 0 | AW12: 40 | AX12: 0 | AY12: 0 | BA12: 40 | BB12: 0 | BC12: 0 | BE12: 40 | BF12: =$KN12*0 -> 0 | BG12: 0 | BI12: =SUMPRODUCT(--(MOD(COLUMN($M12:$BH12),4)=MOD(COLUMN($M12),4)),$M12:$BH12) -> 512 | BJ12: =BI12*$I12 -> 249173.33 | BK12: =SUMPRODUCT(--(MOD(COLUMN($M12:$BH12),4)=MOD(COLUMN($M12)+1,4)),$M12:$BH12) -> 324 | BL12: =BK12*$I12 -> 157680 | BM12: =SUMPRODUCT(--(MOD(COLUMN($M12:$BH12),4)=MOD(COLUMN($M12)+2,4)),$M12:$BH12) -> 182 | BN12: =BM12*$I12 -> 88573.333 | BO12: =$KN12*0 -> 0 | BP12: =$KN12*0 -> 0 | BQ12: =$KN12*0 -> 0 | BR12: 0 | BT12: =$KN12*5 -> 5 | BU12: =$KN12*0 -> 0 | BV12: =$KN12*0 -> 0 | BW12: 0 | BY12: =$KN12*15 -> 15 | BZ12: =$KN12*15 -> 15 | CA12: =$KN12*0 -> 0 | CB12: 0 | CD12: =$KN12*15 -> 15 | CE12: =$KN12*15 -> 15 | CF12: =$KN12*0 -> 0 | CG12: 0 | CI12: =$KN12*15 -> 15 | CJ12: =$KN12*15 -> 15 | CK12: =$KN12*0 -> 0 | CL12: 0 | CN12: =$KN12*15 -> 15 | CO12: =$KN12*15 -> 15 | CP12: =$KN12*0 -> 0 | CQ12: 0 | CS12: =$KN12*15 -> 15 | CT12: =$KN12*15 -> 15 | CU12: =$KN12*0 -> 0 | CV12: 0 | CX12: =$KN12*15 -> 15 | CY12: =$KN12*15 -> 15 | CZ12: =$KN12*0 -> 0 | DA12: 0 | DC12: =$KN12*15 -> 15 | DD12: =$KN12*15 -> 15 | DE12: =$KN12*0 -> 0 | DF12: 0 | DH12: =$KN12*15 -> 15 | DI12: =$KN12*15 -> 15 | DJ12: =$KN12*0 -> 0 | DK12: 0 | DM12: =$KN12*15 -> 15 | DN12: =$KN12*15 -> 15 | DO12: =$KN12*0 -> 0 | DP12: 0 | DR12: =$KN12*15 -> 15 | DS12: =$KN12*15 -> 15 | DT12: =$KN12*0 -> 0 | DU12: 0 | DW12: {=SUMPRODUCT(--(MOD(COLUMN($BO12:$DV12),5)=MOD(COLUMN($BO12),5)),$BO12:$DV12)} -> 155 | DX12: =DW12*$J12 -> 75433.333 | DY12: {=SUMPRODUCT(--(MOD(COLUMN($BO12:$DV12),5)=MOD(COLUMN($BP12),5)),$BO12:$DV12)} -> 150 | DZ12: =DY12*$J12 -> 73000 | EA12: {=SUMPRODUCT(--(MOD(COLUMN($BO12:$DV12),5)=MOD(COLUMN($BQ12),5)),$BO12:$DV12)} -> 0 | EB12: =EA12*$J12 -> 0 | EC12: {=SUMPRODUCT(--(MOD(COLUMN($BO12:$DV12),5)=MOD(COLUMN($BR12),5)),$BO12:$DV12)} -> 0 | ED12: =EC12*$J12 -> 0 | EE12: =$KN12*8 -> 8 | EF12: 8 | EG12: 0 | EI12: =$KN12*9 -> 9 | EJ12: 50 | EK12: 0 | EM12: =$KN12*9 -> 9 | EN12: 0 | EQ12: =$KN12*15 -> 15 | ER12: 1 | EU12: =$KN12*15 -> 15 | EV12: 0 | EY12: =$KN12*15 -> 15 | EZ12: 45 | FC12: =$KN12*15 -> 15 | FD12: 15 | FG12: =$KN12*15 -> 15 | FH12: 15 | FK12: =$KN12*15 -> 15 | FL12: 15 | FO12: =$KN12*15 -> 15 | FP12: 15 | FS12: =$KN12*14 -> 14 | FT12: 14 | FW12: =$KN12*10 -> 10 | FX12: 10 | GA12: =SUMPRODUCT(--(MOD(COLUMN($EE12:$FZ12),4)=MOD(COLUMN($EE12),4)),$EE12:$FZ12) -> 155 | GB12: =GA12*$J12 -> 75433.333 | GC12: =SUMPRODUCT(--(MOD(COLUMN($EE12:$FZ12),4)=MOD(COLUMN($EF12),4)),$EE12:$FZ12) -> 188 | GD12: =GC12*$J12 -> 91493.333 | GE12: =SUMPRODUCT(--(MOD(COLUMN($EE12:$FZ12),4)=MOD(COLUMN($EG12),4)),$EE12:$FZ12) -> 0 | GF12: =GE12*$J12 -> 0 | GG12: =$KN12*10 -> 10 | GK12: =$KN12*10 -> 10 | GO12: =$KN12*15 -> 15 | GS12: =$KN12*20 -> 20 | GW12: =$KN12*20 -> 20 | HA12: =$KN12*20 -> 20 | HE12: =$KN12*20 -> 20 | HI12: =$KN12*20 -> 20 | HM12: =$KN12*20 -> 20 | HQ12: =$KN12*20 -> 20 | HU12: =$KN12*20 -> 20 | HY12: =$KN12*20 -> 20 | IC12: {=SUMPRODUCT(--(MOD(COLUMN($GG12:$IB12),4)=MOD(COLUMN($GG12),4)),$GG12:$IB12)} -> 215 | ID12: =IC12*$J12 -> 104633.33 | IE12: {=SUMPRODUCT(--(MOD(COLUMN($GG12:$IB12),4)=MOD(COLUMN($GH12),4)),$GG12:$IB12)} -> 0 | IF12: =IE12*$J12 -> 0 | IG12: {=SUMPRODUCT(--(MOD(COLUMN($GG12:$IB12),4)=MOD(COLUMN($GI12),4)),$GG12:$IB12)} -> 0 | IH12: =IG12*$J12 -> 0 | II12: =$KN12*15 -> 15 | IM12: =$KN12*15 -> 15 | IQ12: =$KN12*20 -> 20 | IU12: =$KN12*25 -> 25 | IY12: =$KN12*25 -> 25 | JC12: =$KN12*25 -> 25 | JG12: =$KN12*30 -> 30 | JK12: =$KN12*30 -> 30 | JO12: =$KN12*30 -> 30 | JS12: =$KN12*30 -> 30 | JW12: =$KN12*30 -> 30 | KA12: 30 | KE12: {=SUMPRODUCT(--(MOD(COLUMN($II12:$KD12),4)=MOD(COLUMN($II12),4)),$II12:$KD12)} -> 305 | KF12: =KE12*$J12 -> 148433.33 | KG12: {=SUMPRODUCT(--(MOD(COLUMN($II12:$KD12),4)=MOD(COLUMN($IJ12),4)),$II12:$KD12)} -> 0 | KH12: =KG12*$J12 -> 0 | KI12: {=SUMPRODUCT(--(MOD(COLUMN($II12:$KD12),4)=MOD(COLUMN($IK12),4)),$II12:$KD12)} -> 0 | KJ12: =KI12*$J12 -> 0 | KN12: 1
E13: 8 | F13: 1 | G13: 4630320200 | H13: Кран ручного управления | I13: =537.4/1.2 -> 447.83333 | J13: =537.4/1.2 -> 447.83333 | M13: 102 | N13: 102 | O13: 0 | Q13: 50 | R13: 32 | S13: 32 | U13: 0 | V13: 50 | W13: 50 | Y13: 40 | Z13: 50 | AA13: 50 | AC13: 40 | AD13: 40 | AE13: 0 | AG13: 40 | AH13: 25 | AI13: 25 | AK13: 40 | AL13: 25 | AM13: 25 | AO13: 40 | AP13: 0 | AQ13: 0 | AS13: 40 | AT13: 0 | AU13: 0 | AW13: 40 | AX13: 0 | AY13: 0 | BA13: 40 | BB13: 0 | BC13: 0 | BE13: 40 | BF13: =$KN13*0 -> 0 | BG13: 0 | BI13: =SUMPRODUCT(--(MOD(COLUMN($M13:$BH13),4)=MOD(COLUMN($M13),4)),$M13:$BH13) -> 512 | BJ13: =BI13*$I13 -> 229290.67 | BK13: =SUMPRODUCT(--(MOD(COLUMN($M13:$BH13),4)=MOD(COLUMN($M13)+1,4)),$M13:$BH13) -> 324 | BL13: =BK13*$I13 -> 145098 | BM13: =SUMPRODUCT(--(MOD(COLUMN($M13:$BH13),4)=MOD(COLUMN($M13)+2,4)),$M13:$BH13) -> 182 | BN13: =BM13*$I13 -> 81505.667 | BO13: =$KN13*0 -> 0 | BP13: =$KN13*0 -> 0 | BQ13: =$KN13*0 -> 0 | BR13: 0 | BT13: =$KN13*5 -> 5 | BU13: =$KN13*0 -> 0 | BV13: =$KN13*0 -> 0 | BW13: 0 | BY13: =$KN13*15 -> 15 | BZ13: =$KN13*15 -> 15 | CA13: =$KN13*0 -> 0 | CB13: 0 | CD13: =$KN13*15 -> 15 | CE13: =$KN13*15 -> 15 | CF13: =$KN13*0 -> 0 | CG13: 0 | CI13: =$KN13*15 -> 15 | CJ13: =$KN13*15 -> 15 | CK13: =$KN13*0 -> 0 | CL13: 0 | CN13: =$KN13*15 -> 15 | CO13: =$KN13*15 -> 15 | CP13: =$KN13*0 -> 0 | CQ13: 0 | CS13: =$KN13*15 -> 15 | CT13: =$KN13*15 -> 15 | CU13: =$KN13*0 -> 0 | CV13: 0 | CX13: =$KN13*15 -> 15 | CY13: =$KN13*15 -> 15 | CZ13: =$KN13*0 -> 0 | DA13: 0 | DC13: =$KN13*15 -> 15 | DD13: =$KN13*15 -> 15 | DE13: =$KN13*0 -> 0 | DF13: 0 | DH13: =$KN13*15 -> 15 | DI13: =$KN13*15 -> 15 | DJ13: =$KN13*0 -> 0 | DK13: 0 | DM13: =$KN13*15 -> 15 | DN13: =$KN13*15 -> 15 | DO13: =$KN13*0 -> 0 | DP13: 0 | DR13: =$KN13*15 -> 15 | DS13: =$KN13*15 -> 15 | DT13: =$KN13*0 -> 0 | DU13: 0 | DW13: {=SUMPRODUCT(--(MOD(COLUMN($BO13:$DV13),5)=MOD(COLUMN($BO13),5)),$BO13:$DV13)} -> 155 | DX13: =DW13*$J13 -> 69414.167 | DY13: {=SUMPRODUCT(--(MOD(COLUMN($BO13:$DV13),5)=MOD(COLUMN($BP13),5)),$BO13:$DV13)} -> 150 | DZ13: =DY13*$J13 -> 67175 | EA13: {=SUMPRODUCT(--(MOD(COLUMN($BO13:$DV13),5)=MOD(COLUMN($BQ13),5)),$BO13:$DV13)} -> 0 | EB13: =EA13*$J13 -> 0 | EC13: {=SUMPRODUCT(--(MOD(COLUMN($BO13:$DV13),5)=MOD(COLUMN($BR13),5)),$BO13:$DV13)} -> 0 | ED13: =EC13*$J13 -> 0 | EE13: =$KN13*8 -> 8 | EF13: 8 | EG13: 0 | EI13: =$KN13*9 -> 9 | EJ13: 50 | EK13: 0 | EM13: =$KN13*9 -> 9 | EN13: 0 | EQ13: =$KN13*15 -> 15 | ER13: 1 | EU13: =$KN13*15 -> 15 | EV13: 0 | EY13: =$KN13*15 -> 15 | EZ13: 45 | FC13: =$KN13*15 -> 15 | FD13: 15 | FG13: =$KN13*15 -> 15 | FH13: 15 | FK13: =$KN13*15 -> 15 | FL13: 15 | FO13: =$KN13*15 -> 15 | FP13: 15 | FS13: =$KN13*14 -> 14 | FT13: 14 | FW13: =$KN13*10 -> 10 | FX13: 10 | GA13: =SUMPRODUCT(--(MOD(COLUMN($EE13:$FZ13),4)=MOD(COLUMN($EE13),4)),$EE13:$FZ13) -> 155 | GB13: =GA13*$J13 -> 69414.167 | GC13: =SUMPRODUCT(--(MOD(COLUMN($EE13:$FZ13),4)=MOD(COLUMN($EF13),4)),$EE13:$FZ13) -> 188 | GD13: =GC13*$J13 -> 84192.667 | GE13: =SUMPRODUCT(--(MOD(COLUMN($EE13:$FZ13),4)=MOD(COLUMN($EG13),4)),$EE13:$FZ13) -> 0 | GF13: =GE13*$J13 -> 0 | GG13: =$KN13*10 -> 10 | GK13: =$KN13*10 -> 10 | GO13: =$KN13*15 -> 15 | GS13: =$KN13*20 -> 20 | GW13: =$KN13*20 -> 20 | HA13: =$KN13*20 -> 20 | HE13: =$KN13*20 -> 20 | HI13: =$KN13*20 -> 20 | HM13: =$KN13*20 -> 20 | HQ13: =$KN13*20 -> 20 | HU13: =$KN13*20 -> 20 | HY13: =$KN13*20 -> 20 | IC13: {=SUMPRODUCT(--(MOD(COLUMN($GG13:$IB13),4)=MOD(COLUMN($GG13),4)),$GG13:$IB13)} -> 215 | ID13: =IC13*$J13 -> 96284.167 | IE13: {=SUMPRODUCT(--(MOD(COLUMN($GG13:$IB13),4)=MOD(COLUMN($GH13),4)),$GG13:$IB13)} -> 0 | IF13: =IE13*$J13 -> 0 | IG13: {=SUMPRODUCT(--(MOD(COLUMN($GG13:$IB13),4)=MOD(COLUMN($GI13),4)),$GG13:$IB13)} -> 0 | IH13: =IG13*$J13 -> 0 | II13: =$KN13*15 -> 15 | IM13: =$KN13*15 -> 15 | IQ13: =$KN13*20 -> 20 | IU13: =$KN13*25 -> 25 | IY13: =$KN13*25 -> 25 | JC13: =$KN13*25 -> 25 | JG13: =$KN13*30 -> 30 | JK13: =$KN13*30 -> 30 | JO13: =$KN13*30 -> 30 | JS13: =$KN13*30 -> 30 | JW13: =$KN13*30 -> 30 | KA13: 30 | KE13: {=SUMPRODUCT(--(MOD(COLUMN($II13:$KD13),4)=MOD(COLUMN($II13),4)),$II13:$KD13)} -> 305 | KF13: =KE13*$J13 -> 136589.17 | KG13: {=SUMPRODUCT(--(MOD(COLUMN($II13:$KD13),4)=MOD(COLUMN($IJ13),4)),$II13:$KD13)} -> 0 | KH13: =KG13*$J13 -> 0 | KI13: {=SUMPRODUCT(--(MOD(COLUMN($II13:$KD13),4)=MOD(COLUMN($IK13),4)),$II13:$KD13)} -> 0 | KJ13: =KI13*$J13 -> 0 | KN13: 1
E14: 9 | F14: 1 | G14: 4334010030 | H14: Упругий элемент | I14: =41.9/1.2 -> 34.916667 | J14: =41.9/1.2 -> 34.916667 | M14: 102 | N14: 102 | O14: 0 | Q14: 50 | R14: 32 | S14: 32 | U14: 0 | V14: 50 | W14: 50 | Y14: 40 | Z14: 50 | AA14: 50 | AC14: 40 | AD14: 40 | AE14: 0 | AG14: 40 | AH14: 25 | AI14: 25 | AK14: 40 | AL14: 25 | AM14: 25 | AO14: 40 | AP14: 0 | AQ14: 0 | AS14: 40 | AT14: 0 | AU14: 0 | AW14: 40 | AX14: 0 | AY14: 0 | BA14: 40 | BB14: 0 | BC14: 0 | BE14: 40 | BF14: =$KN14*0 -> 0 | BG14: 0 | BI14: =SUMPRODUCT(--(MOD(COLUMN($M14:$BH14),4)=MOD(COLUMN($M14),4)),$M14:$BH14) -> 512 | BJ14: =BI14*$I14 -> 17877.333 | BK14: =SUMPRODUCT(--(MOD(COLUMN($M14:$BH14),4)=MOD(COLUMN($M14)+1,4)),$M14:$BH14) -> 324 | BL14: =BK14*$I14 -> 11313 | BM14: =SUMPRODUCT(--(MOD(COLUMN($M14:$BH14),4)=MOD(COLUMN($M14)+2,4)),$M14:$BH14) -> 182 | BN14: =BM14*$I14 -> 6354.8333 | BO14: =$KN14*0 -> 0 | BP14: =$KN14*0 -> 0 | BQ14: =$KN14*0 -> 0 | BR14: 0 | BT14: =$KN14*5 -> 5 | BU14: =$KN14*0 -> 0 | BV14: =$KN14*0 -> 0 | BW14: 0 | BY14: =$KN14*15 -> 15 | BZ14: =$KN14*15 -> 15 | CA14: =$KN14*0 -> 0 | CB14: 0 | CD14: =$KN14*15 -> 15 | CE14: =$KN14*15 -> 15 | CF14: =$KN14*0 -> 0 | CG14: 0 | CI14: =$KN14*15 -> 15 | CJ14: =$KN14*15 -> 15 | CK14: =$KN14*0 -> 0 | CL14: 0 | CN14: =$KN14*15 -> 15 | CO14: =$KN14*15 -> 15 | CP14: =$KN14*0 -> 0 | CQ14: 0 | CS14: =$KN14*15 -> 15 | CT14: =$KN14*15 -> 15 | CU14: =$KN14*0 -> 0 | CV14: 0 | CX14: =$KN14*15 -> 15 | CY14: =$KN14*15 -> 15 | CZ14: =$KN14*0 -> 0 | DA14: 0 | DC14: =$KN14*15 -> 15 | DD14: =$KN14*15 -> 15 | DE14: =$KN14*0 -> 0 | DF14: 0 | DH14: =$KN14*15 -> 15 | DI14: =$KN14*15 -> 15 | DJ14: =$KN14*0 -> 0 | DK14: 0 | DM14: =$KN14*15 -> 15 | DN14: =$KN14*15 -> 15 | DO14: =$KN14*0 -> 0 | DP14: 0 | DR14: =$KN14*15 -> 15 | DS14: =$KN14*15 -> 15 | DT14: =$KN14*0 -> 0 | DU14: 0 | DW14: {=SUMPRODUCT(--(MOD(COLUMN($BO14:$DV14),5)=MOD(COLUMN($BO14),5)),$BO14:$DV14)} -> 155 | DX14: =DW14*$J14 -> 5412.0833 | DY14: {=SUMPRODUCT(--(MOD(COLUMN($BO14:$DV14),5)=MOD(COLUMN($BP14),5)),$BO14:$DV14)} -> 150 | DZ14: =DY14*$J14 -> 5237.5 | EA14: {=SUMPRODUCT(--(MOD(COLUMN($BO14:$DV14),5)=MOD(COLUMN($BQ14),5)),$BO14:$DV14)} -> 0 | EB14: =EA14*$J14 -> 0 | EC14: {=SUMPRODUCT(--(MOD(COLUMN($BO14:$DV14),5)=MOD(COLUMN($BR14),5)),$BO14:$DV14)} -> 0 | ED14: =EC14*$J14 -> 0 | EE14: =$KN14*8 -> 8 | EF14: 8 | EG14: 0 | EI14: =$KN14*9 -> 9 | EJ14: 50 | EK14: 0 | EM14: =$KN14*9 -> 9 | EN14: 0 | EQ14: =$KN14*15 -> 15 | ER14: 1 | EU14: =$KN14*15 -> 15 | EV14: 0 | EY14: =$KN14*15 -> 15 | EZ14: 45 | FC14: =$KN14*15 -> 15 | FD14: 15 | FG14: =$KN14*15 -> 15 | FH14: 15 | FK14: =$KN14*15 -> 15 | FL14: 15 | FO14: =$KN14*15 -> 15 | FP14: 15 | FS14: =$KN14*14 -> 14 | FT14: 14 | FW14: =$KN14*10 -> 10 | FX14: 10 | GA14: =SUMPRODUCT(--(MOD(COLUMN($EE14:$FZ14),4)=MOD(COLUMN($EE14),4)),$EE14:$FZ14) -> 155 | GB14: =GA14*$J14 -> 5412.0833 | GC14: =SUMPRODUCT(--(MOD(COLUMN($EE14:$FZ14),4)=MOD(COLUMN($EF14),4)),$EE14:$FZ14) -> 188 | GD14: =GC14*$J14 -> 6564.3333 | GE14: =SUMPRODUCT(--(MOD(COLUMN($EE14:$FZ14),4)=MOD(COLUMN($EG14),4)),$EE14:$FZ14) -> 0 | GF14: =GE14*$J14 -> 0 | GG14: =$KN14*10 -> 10 | GK14: =$KN14*10 -> 10 | GO14: =$KN14*15 -> 15 | GS14: =$KN14*20 -> 20 | GW14: =$KN14*20 -> 20 | HA14: =$KN14*20 -> 20 | HE14: =$KN14*20 -> 20 | HI14: =$KN14*20 -> 20 | HM14: =$KN14*20 -> 20 | HQ14: =$KN14*20 -> 20 | HU14: =$KN14*20 -> 20 | HY14: =$KN14*20 -> 20 | IC14: {=SUMPRODUCT(--(MOD(COLUMN($GG14:$IB14),4)=MOD(COLUMN($GG14),4)),$GG14:$IB14)} -> 215 | ID14: =IC14*$J14 -> 7507.0833 | IE14: {=SUMPRODUCT(--(MOD(COLUMN($GG14:$IB14),4)=MOD(COLUMN($GH14),4)),$GG14:$IB14)} -> 0 | IF14: =IE14*$J14 -> 0 | IG14: {=SUMPRODUCT(--(MOD(COLUMN($GG14:$IB14),4)=MOD(COLUMN($GI14),4)),$GG14:$IB14)} -> 0 | IH14: =IG14*$J14 -> 0 | II14: =$KN14*15 -> 15 | IM14: =$KN14*15 -> 15 | IQ14: =$KN14*20 -> 20 | IU14: =$KN14*25 -> 25 | IY14: =$KN14*25 -> 25 | JC14: =$KN14*25 -> 25 | JG14: =$KN14*30 -> 30 | JK14: =$KN14*30 -> 30 | JO14: =$KN14*30 -> 30 | JS14: =$KN14*30 -> 30 | JW14: =$KN14*30 -> 30 | KA14: 30 | KE14: {=SUMPRODUCT(--(MOD(COLUMN($II14:$KD14),4)=MOD(COLUMN($II14),4)),$II14:$KD14)} -> 305 | KF14: =KE14*$J14 -> 10649.583 | KG14: {=SUMPRODUCT(--(MOD(COLUMN($II14:$KD14),4)=MOD(COLUMN($IJ14),4)),$II14:$KD14)} -> 0 | KH14: =KG14*$J14 -> 0 | KI14: {=SUMPRODUCT(--(MOD(COLUMN($II14:$KD14),4)=MOD(COLUMN($IK14),4)),$II14:$KD14)} -> 0 | KJ14: =KI14*$J14 -> 0 | KN14: 1
E15: 10 | F15: 1 | G15: 4630840310 | H15: Клапан управления подъемом оси (LACV) | I15: =657.1/1.2 -> 547.58333 | J15: =657.1/1.2 -> 547.58333 | M15: 102 | N15: 102 | O15: 0 | Q15: 50 | R15: 32 | S15: 32 | U15: 0 | V15: 50 | W15: 50 | Y15: 40 | Z15: 50 | AA15: 50 | AC15: 40 | AD15: 40 | AE15: 0 | AG15: 40 | AH15: 25 | AI15: 25 | AK15: 40 | AL15: 25 | AM15: 25 | AO15: 40 | AP15: 0 | AQ15: 0 | AS15: 40 | AT15: 0 | AU15: 0 | AW15: 40 | AX15: 0 | AY15: 0 | BA15: 40 | BB15: 0 | BC15: 0 | BE15: 40 | BF15: =$KN15*0 -> 0 | BG15: 0 | BI15: =SUMPRODUCT(--(MOD(COLUMN($M15:$BH15),4)=MOD(COLUMN($M15),4)),$M15:$BH15) -> 512 | BJ15: =BI15*$I15 -> 280362.67 | BK15: =SUMPRODUCT(--(MOD(COLUMN($M15:$BH15),4)=MOD(COLUMN($M15)+1,4)),$M15:$BH15) -> 324 | BL15: =BK15*$I15 -> 177417 | BM15: =SUMPRODUCT(--(MOD(COLUMN($M15:$BH15),4)=MOD(COLUMN($M15)+2,4)),$M15:$BH15) -> 182 | BN15: =BM15*$I15 -> 99660.167 | BO15: =$KN15*0 -> 0 | BP15: =$KN15*0 -> 0 | BQ15: =$KN15*0 -> 0 | BR15: 0 | BT15: =$KN15*5 -> 5 | BU15: =$KN15*0 -> 0 | BV15: =$KN15*0 -> 0 | BW15: 0 | BY15: =$KN15*15 -> 15 | BZ15: =$KN15*15 -> 15 | CA15: =$KN15*0 -> 0 | CB15: 0 | CD15: =$KN15*15 -> 15 | CE15: =$KN15*15 -> 15 | CF15: =$KN15*0 -> 0 | CG15: 0 | CI15: =$KN15*15 -> 15 | CJ15: =$KN15*15 -> 15 | CK15: =$KN15*0 -> 0 | CL15: 0 | CN15: =$KN15*15 -> 15 | CO15: =$KN15*15 -> 15 | CP15: =$KN15*0 -> 0 | CQ15: 0 | CS15: =$KN15*15 -> 15 | CT15: =$KN15*15 -> 15 | CU15: =$KN15*0 -> 0 | CV15: 0 | CX15: =$KN15*15 -> 15 | CY15: =$KN15*15 -> 15 | CZ15: =$KN15*0 -> 0 | DA15: 0 | DC15: =$KN15*15 -> 15 | DD15: =$KN15*15 -> 15 | DE15: =$KN15*0 -> 0 | DF15: 0 | DH15: =$KN15*15 -> 15 | DI15: =$KN15*15 -> 15 | DJ15: =$KN15*0 -> 0 | DK15: 0 | DM15: =$KN15*15 -> 15 | DN15: =$KN15*15 -> 15 | DO15: =$KN15*0 -> 0 | DP15: 0 | DR15: =$KN15*15 -> 15 | DS15: =$KN15*15 -> 15 | DT15: =$KN15*0 -> 0 | DU15: 0 | DW15: {=SUMPRODUCT(--(MOD(COLUMN($BO15:$DV15),5)=MOD(COLUMN($BO15),5)),$BO15:$DV15)} -> 155 | DX15: =DW15*$J15 -> 84875.417 | DY15: {=SUMPRODUCT(--(MOD(COLUMN($BO15:$DV15),5)=MOD(COLUMN($BP15),5)),$BO15:$DV15)} -> 150 | DZ15: =DY15*$J15 -> 82137.5 | EA15: {=SUMPRODUCT(--(MOD(COLUMN($BO15:$DV15),5)=MOD(COLUMN($BQ15),5)),$BO15:$DV15)} -> 0 | EB15: =EA15*$J15 -> 0 | EC15: {=SUMPRODUCT(--(MOD(COLUMN($BO15:$DV15),5)=MOD(COLUMN($BR15),5)),$BO15:$DV15)} -> 0 | ED15: =EC15*$J15 -> 0 | EE15: =$KN15*8 -> 8 | EF15: 8 | EG15: 0 | EI15: =$KN15*9 -> 9 | EJ15: 50 | EK15: 0 | EM15: =$KN15*9 -> 9 | EN15: 0 | EQ15: =$KN15*15 -> 15 | ER15: 1 | EU15: =$KN15*15 -> 15 | EV15: 0 | EY15: =$KN15*15 -> 15 | EZ15: 45 | FC15: =$KN15*15 -> 15 | FD15: 15 | FG15: =$KN15*15 -> 15 | FH15: 15 | FK15: =$KN15*15 -> 15 | FL15: 15 | FO15: =$KN15*15 -> 15 | FP15: 15 | FS15: =$KN15*14 -> 14 | FT15: 14 | FW15: =$KN15*10 -> 10 | FX15: 10 | GA15: =SUMPRODUCT(--(MOD(COLUMN($EE15:$FZ15),4)=MOD(COLUMN($EE15),4)),$EE15:$FZ15) -> 155 | GB15: =GA15*$J15 -> 84875.417 | GC15: =SUMPRODUCT(--(MOD(COLUMN($EE15:$FZ15),4)=MOD(COLUMN($EF15),4)),$EE15:$FZ15) -> 188 | GD15: =GC15*$J15 -> 102945.67 | GE15: =SUMPRODUCT(--(MOD(COLUMN($EE15:$FZ15),4)=MOD(COLUMN($EG15),4)),$EE15:$FZ15) -> 0 | GF15: =GE15*$J15 -> 0 | GG15: =$KN15*10 -> 10 | GK15: =$KN15*10 -> 10 | GO15: =$KN15*15 -> 15 | GS15: =$KN15*20 -> 20 | GW15: =$KN15*20 -> 20 | HA15: =$KN15*20 -> 20 | HE15: =$KN15*20 -> 20 | HI15: =$KN15*20 -> 20 | HM15: =$KN15*20 -> 20 | HQ15: =$KN15*20 -> 20 | HU15: =$KN15*20 -> 20 | HY15: =$KN15*20 -> 20 | IC15: {=SUMPRODUCT(--(MOD(COLUMN($GG15:$IB15),4)=MOD(COLUMN($GG15),4)),$GG15:$IB15)} -> 215 | ID15: =IC15*$J15 -> 117730.42 | IE15: {=SUMPRODUCT(--(MOD(COLUMN($GG15:$IB15),4)=MOD(COLUMN($GH15),4)),$GG15:$IB15)} -> 0 | IF15: =IE15*$J15 -> 0 | IG15: {=SUMPRODUCT(--(MOD(COLUMN($GG15:$IB15),4)=MOD(COLUMN($GI15),4)),$GG15:$IB15)} -> 0 | IH15: =IG15*$J15 -> 0 | II15: =$KN15*15 -> 15 | IM15: =$KN15*15 -> 15 | IQ15: =$KN15*20 -> 20 | IU15: =$KN15*25 -> 25 | IY15: =$KN15*25 -> 25 | JC15: =$KN15*25 -> 25 | JG15: =$KN15*30 -> 30 | JK15: =$KN15*30 -> 30 | JO15: =$KN15*30 -> 30 | JS15: =$KN15*30 -> 30 | JW15: =$KN15*30 -> 30 | KA15: 30 | KE15: {=SUMPRODUCT(--(MOD(COLUMN($II15:$KD15),4)=MOD(COLUMN($II15),4)),$II15:$KD15)} -> 305 | KF15: =KE15*$J15 -> 167012.92 | KG15: {=SUMPRODUCT(--(MOD(COLUMN($II15:$KD15),4)=MOD(COLUMN($IJ15),4)),$II15:$KD15)} -> 0 | KH15: =KG15*$J15 -> 0 | KI15: {=SUMPRODUCT(--(MOD(COLUMN($II15:$KD15),4)=MOD(COLUMN($IK15),4)),$II15:$KD15)} -> 0 | KJ15: =KI15*$J15 -> 0 | KN15: 1 | KO15: LACV
E16: 11 | F16: 1 | G16: 4494430600 | H16: Кабель клапана управления подъемом оси, 6 м | I16: =164.2/1.2 -> 136.83333 | J16: =164.2/1.2 -> 136.83333 | M16: 102 | N16: 102 | O16: 0 | Q16: 50 | R16: 32 | S16: 32 | U16: 0 | V16: 50 | W16: 50 | Y16: 40 | Z16: 50 | AA16: 50 | AC16: 40 | AD16: 40 | AE16: 0 | AG16: 40 | AH16: 25 | AI16: 25 | AK16: 40 | AL16: 25 | AM16: 25 | AO16: 40 | AP16: 0 | AQ16: 0 | AS16: 40 | AT16: 0 | AU16: 0 | AW16: 40 | AX16: 0 | AY16: 0 | BA16: 40 | BB16: 0 | BC16: 0 | BE16: 40 | BF16: =$KN16*0 -> 0 | BG16: 0 | BI16: =SUMPRODUCT(--(MOD(COLUMN($M16:$BH16),4)=MOD(COLUMN($M16),4)),$M16:$BH16) -> 512 | BJ16: =BI16*$I16 -> 70058.667 | BK16: =SUMPRODUCT(--(MOD(COLUMN($M16:$BH16),4)=MOD(COLUMN($M16)+1,4)),$M16:$BH16) -> 324 | BL16: =BK16*$I16 -> 44334 | BM16: =SUMPRODUCT(--(MOD(COLUMN($M16:$BH16),4)=MOD(COLUMN($M16)+2,4)),$M16:$BH16) -> 182 | BN16: =BM16*$I16 -> 24903.667 | BO16: =$KN16*0 -> 0 | BP16: =$KN16*0 -> 0 | BQ16: =$KN16*0 -> 0 | BR16: 0 | BT16: =$KN16*5 -> 5 | BU16: =$KN16*0 -> 0 | BV16: =$KN16*0 -> 0 | BW16: 0 | BY16: =$KN16*15 -> 15 | BZ16: =$KN16*15 -> 15 | CA16: =$KN16*0 -> 0 | CB16: 0 | CD16: =$KN16*15 -> 15 | CE16: =$KN16*15 -> 15 | CF16: =$KN16*0 -> 0 | CG16: 0 | CI16: =$KN16*15 -> 15 | CJ16: =$KN16*15 -> 15 | CK16: =$KN16*0 -> 0 | CL16: 0 | CN16: =$KN16*15 -> 15 | CO16: =$KN16*15 -> 15 | CP16: =$KN16*0 -> 0 | CQ16: 0 | CS16: =$KN16*15 -> 15 | CT16: =$KN16*15 -> 15 | CU16: =$KN16*0 -> 0 | CV16: 0 | CX16: =$KN16*15 -> 15 | CY16: =$KN16*15 -> 15 | CZ16: =$KN16*0 -> 0 | DA16: 0 | DC16: =$KN16*15 -> 15 | DD16: =$KN16*15 -> 15 | DE16: =$KN16*0 -> 0 | DF16: 0 | DH16: =$KN16*15 -> 15 | DI16: =$KN16*15 -> 15 | DJ16: =$KN16*0 -> 0 | DK16: 0 | DM16: =$KN16*15 -> 15 | DN16: =$KN16*15 -> 15 | DO16: =$KN16*0 -> 0 | DP16: 0 | DR16: =$KN16*15 -> 15 | DS16: =$KN16*15 -> 15 | DT16: =$KN16*0 -> 0 | DU16: 0 | DW16: {=SUMPRODUCT(--(MOD(COLUMN($BO16:$DV16),5)=MOD(COLUMN($BO16),5)),$BO16:$DV16)} -> 155 | DX16: =DW16*$J16 -> 21209.167 | DY16: {=SUMPRODUCT(--(MOD(COLUMN($BO16:$DV16),5)=MOD(COLUMN($BP16),5)),$BO16:$DV16)} -> 150 | DZ16: =DY16*$J16 -> 20525 | EA16: {=SUMPRODUCT(--(MOD(COLUMN($BO16:$DV16),5)=MOD(COLUMN($BQ16),5)),$BO16:$DV16)} -> 0 | EB16: =EA16*$J16 -> 0 | EC16: {=SUMPRODUCT(--(MOD(COLUMN($BO16:$DV16),5)=MOD(COLUMN($BR16),5)),$BO16:$DV16)} -> 0 | ED16: =EC16*$J16 -> 0 | EE16: =$KN16*8 -> 8 | EF16: 8 | EG16: 0 | EI16: =$KN16*9 -> 9 | EJ16: 50 | EK16: 0 | EM16: =$KN16*9 -> 9 | EN16: 0 | EQ16: =$KN16*15 -> 15 | ER16: 1 | EU16: =$KN16*15 -> 15 | EV16: 0 | EY16: =$KN16*15 -> 15 | EZ16: 45 | FC16: =$KN16*15 -> 15 | FD16: 15 | FG16: =$KN16*15 -> 15 | FH16: 15 | FK16: =$KN16*15 -> 15 | FL16: 15 | FO16: =$KN16*15 -> 15 | FP16: 15 | FS16: =$KN16*14 -> 14 | FT16: 14 | FW16: =$KN16*10 -> 10 | FX16: 10 | GA16: =SUMPRODUCT(--(MOD(COLUMN($EE16:$FZ16),4)=MOD(COLUMN($EE16),4)),$EE16:$FZ16) -> 155 | GB16: =GA16*$J16 -> 21209.167 | GC16: =SUMPRODUCT(--(MOD(COLUMN($EE16:$FZ16),4)=MOD(COLUMN($EF16),4)),$EE16:$FZ16) -> 188 | GD16: =GC16*$J16 -> 25724.667 | GE16: =SUMPRODUCT(--(MOD(COLUMN($EE16:$FZ16),4)=MOD(COLUMN($EG16),4)),$EE16:$FZ16) -> 0 | GF16: =GE16*$J16 -> 0 | GG16: =$KN16*10 -> 10 | GK16: =$KN16*10 -> 10 | GO16: =$KN16*15 -> 15 | GS16: =$KN16*20 -> 20 | GW16: =$KN16*20 -> 20 | HA16: =$KN16*20 -> 20 | HE16: =$KN16*20 -> 20 | HI16: =$KN16*20 -> 20 | HM16: =$KN16*20 -> 20 | HQ16: =$KN16*20 -> 20 | HU16: =$KN16*20 -> 20 | HY16: =$KN16*20 -> 20 | IC16: {=SUMPRODUCT(--(MOD(COLUMN($GG16:$IB16),4)=MOD(COLUMN($GG16),4)),$GG16:$IB16)} -> 215 | ID16: =IC16*$J16 -> 29419.167 | IE16: {=SUMPRODUCT(--(MOD(COLUMN($GG16:$IB16),4)=MOD(COLUMN($GH16),4)),$GG16:$IB16)} -> 0 | IF16: =IE16*$J16 -> 0 | IG16: {=SUMPRODUCT(--(MOD(COLUMN($GG16:$IB16),4)=MOD(COLUMN($GI16),4)),$GG16:$IB16)} -> 0 | IH16: =IG16*$J16 -> 0 | II16: =$KN16*15 -> 15 | IM16: =$KN16*15 -> 15 | IQ16: =$KN16*20 -> 20 | IU16: =$KN16*25 -> 25 | IY16: =$KN16*25 -> 25 | JC16: =$KN16*25 -> 25 | JG16: =$KN16*30 -> 30 | JK16: =$KN16*30 -> 30 | JO16: =$KN16*30 -> 30 | JS16: =$KN16*30 -> 30 | JW16: =$KN16*30 -> 30 | KA16: 30 | KE16: {=SUMPRODUCT(--(MOD(COLUMN($II16:$KD16),4)=MOD(COLUMN($II16),4)),$II16:$KD16)} -> 305 | KF16: =KE16*$J16 -> 41734.167 | KG16: {=SUMPRODUCT(--(MOD(COLUMN($II16:$KD16),4)=MOD(COLUMN($IJ16),4)),$II16:$KD16)} -> 0 | KH16: =KG16*$J16 -> 0 | KI16: {=SUMPRODUCT(--(MOD(COLUMN($II16:$KD16),4)=MOD(COLUMN($IK16),4)),$II16:$KD16)} -> 0 | KJ16: =KI16*$J16 -> 0 | KN16: 1
E17: 12 | F17: 1 | G17: 4492731200 | H17: Кабель питания для прицепа, 12 м | I17: 1037 | J17: 1037 | EH17: Новый артикул | EJ17: 1 | EK17: 0 | EN17: 1 | EO17: 1 | EP17: Заказ февраля перенесена на март
E18: 13 | F18: 1 | G18: 4802070600 | H18: Ускорительный клапан EBS | I18: 1056 | J18: 1056 | EJ18: 1 | EK18: 0 | EN18: 1 | EO18: 1
E19: 14 | F19: 1 | G19: 4494301200 | H19: Кабель клапана ускорительного TEBS, 12 м | I19: 811 | J19: 811 | EJ19: 1 | EK19: 0 | EN19: 1 | EO19: 1
E20: 15 | F20: 1 | G20: 4497230800 | H20: Кабель датчика АБС, 8 м | I20: 210 | J20: 210 | EJ20: 2 | EK20: 0 | EN20: 2 | EO20: 2
E21: 16 | F21: 1 | G21: 4497230500 | H21: Кабель датчика АБС, 5 м | I21: 162 | J21: 162 | EJ21: 2 | EK21: 0 | EN21: 2 | EO21: 2
E22: 17 | F22: 1 | G22: 4640060020 | H22: Кран уровня пола | I22: 325 | J22: 325 | EJ22: 2 | EK22: 0 | EN22: 2 | EO22: 2
E23: 18 | F23: 2 | G23: 9522010010 | H23: Головка соединительная, с фильтром, управляющая | J23: =138.5/1.2 -> 115.41667 | BF23: =$KN23*0 -> 0 | DK23: 0 | DO23: =$KN23*0 -> 0 | DP23: 0 | DQ23: Новая номенклатура | DU23: 0 | DW23: {=SUMPRODUCT(--(MOD(COLUMN($BO23:$DV23),5)=MOD(COLUMN($BO23),5)),$BO23:$DV23)} -> 0 | DX23: =DW23*$J23 -> 0 | DY23: {=SUMPRODUCT(--(MOD(COLUMN($BO23:$DV23),5)=MOD(COLUMN($BP23),5)),$BO23:$DV23)} -> 0 | DZ23: =DY23*$J23 -> 0 | EA23: {=SUMPRODUCT(--(MOD(COLUMN($BO23:$DV23),5)=MOD(COLUMN($BQ23),5)),$BO23:$DV23)} -> 0 | EB23: =EA23*$J23 -> 0 | EC23: {=SUMPRODUCT(--(MOD(COLUMN($BO23:$DV23),5)=MOD(COLUMN($BR23),5)),$BO23:$DV23)} -> 0 | ED23: =EC23*$J23 -> 0 | EE23: 50 | EF23: 0 | EG23: 0 | EV23: 0 | GA23: =SUMPRODUCT(--(MOD(COLUMN($EE23:$FZ23),4)=MOD(COLUMN($EE23),4)),$EE23:$FZ23) -> 50 | GB23: =GA23*$J23 -> 5770.8333 | GC23: =SUMPRODUCT(--(MOD(COLUMN($EE23:$FZ23),4)=MOD(COLUMN($EF23),4)),$EE23:$FZ23) -> 0 | GD23: =GC23*$J23 -> 0 | GE23: =SUMPRODUCT(--(MOD(COLUMN($EE23:$FZ23),4)=MOD(COLUMN($EG23),4)),$EE23:$FZ23) -> 0 | GF23: =GE23*$J23 -> 0 | IC23: {=SUMPRODUCT(--(MOD(COLUMN($GG23:$IB23),4)=MOD(COLUMN($GG23),4)),$GG23:$IB23)} -> 0 | ID23: =IC23*$J23 -> 0 | IE23: {=SUMPRODUCT(--(MOD(COLUMN($GG23:$IB23),4)=MOD(COLUMN($GH23),4)),$GG23:$IB23)} -> 0 | IF23: =IE23*$J23 -> 0 | IG23: {=SUMPRODUCT(--(MOD(COLUMN($GG23:$IB23),4)=MOD(COLUMN($GI23),4)),$GG23:$IB23)} -> 0 | IH23: =IG23*$J23 -> 0 | KE23: {=SUMPRODUCT(--(MOD(COLUMN($II23:$KD23),4)=MOD(COLUMN($II23),4)),$II23:$KD23)} -> 0 | KF23: =KE23*$J23 -> 0 | KG23: {=SUMPRODUCT(--(MOD(COLUMN($II23:$KD23),4)=MOD(COLUMN($IJ23),4)),$II23:$KD23)} -> 0 | KH23: =KG23*$J23 -> 0 | KI23: {=SUMPRODUCT(--(MOD(COLUMN($II23:$KD23),4)=MOD(COLUMN($IK23),4)),$II23:$KD23)} -> 0 | KJ23: =KI23*$J23 -> 0 | KN23: 1 | KO23: Wabco 4s/3m 15m
E24: 19 | F24: 2 | G24: 9522010020 | H24: Головка соединительная, с фильтром, питающая | J24: =138.5/1.2 -> 115.41667 | BF24: =$KN24*0 -> 0 | DK24: 0 | DO24: =$KN24*0 -> 0 | DP24: 0 | DU24: 0 | DW24: {=SUMPRODUCT(--(MOD(COLUMN($BO24:$DV24),5)=MOD(COLUMN($BO24),5)),$BO24:$DV24)} -> 0 | DX24: =DW24*$J24 -> 0 | DY24: {=SUMPRODUCT(--(MOD(COLUMN($BO24:$DV24),5)=MOD(COLUMN($BP24),5)),$BO24:$DV24)} -> 0 | DZ24: =DY24*$J24 -> 0 | EA24: {=SUMPRODUCT(--(MOD(COLUMN($BO24:$DV24),5)=MOD(COLUMN($BQ24),5)),$BO24:$DV24)} -> 0 | EB24: =EA24*$J24 -> 0 | EC24: {=SUMPRODUCT(--(MOD(COLUMN($BO24:$DV24),5)=MOD(COLUMN($BR24),5)),$BO24:$DV24)} -> 0 | ED24: =EC24*$J24 -> 0 | EE24: 50 | EF24: 0 | EG24: 0 | EV24: 0 | GA24: =SUMPRODUCT(--(MOD(COLUMN($EE24:$FZ24),4)=MOD(COLUMN($EE24),4)),$EE24:$FZ24) -> 50 | GB24: =GA24*$J24 -> 5770.8333 | GC24: =SUMPRODUCT(--(MOD(COLUMN($EE24:$FZ24),4)=MOD(COLUMN($EF24),4)),$EE24:$FZ24) -> 0 | GD24: =GC24*$J24 -> 0 | GE24: =SUMPRODUCT(--(MOD(COLUMN($EE24:$FZ24),4)=MOD(COLUMN($EG24),4)),$EE24:$FZ24) -> 0 | GF24: =GE24*$J24 -> 0 | IC24: {=SUMPRODUCT(--(MOD(COLUMN($GG24:$IB24),4)=MOD(COLUMN($GG24),4)),$GG24:$IB24)} -> 0 | ID24: =IC24*$J24 -> 0 | IE24: {=SUMPRODUCT(--(MOD(COLUMN($GG24:$IB24),4)=MOD(COLUMN($GH24),4)),$GG24:$IB24)} -> 0 | IF24: =IE24*$J24 -> 0 | IG24: {=SUMPRODUCT(--(MOD(COLUMN($GG24:$IB24),4)=MOD(COLUMN($GI24),4)),$GG24:$IB24)} -> 0 | IH24: =IG24*$J24 -> 0 | KE24: {=SUMPRODUCT(--(MOD(COLUMN($II24:$KD24),4)=MOD(COLUMN($II24),4)),$II24:$KD24)} -> 0 | KF24: =KE24*$J24 -> 0 | KG24: {=SUMPRODUCT(--(MOD(COLUMN($II24:$KD24),4)=MOD(COLUMN($IJ24),4)),$II24:$KD24)} -> 0 | KH24: =KG24*$J24 -> 0 | KI24: {=SUMPRODUCT(--(MOD(COLUMN($II24:$KD24),4)=MOD(COLUMN($IK24),4)),$II24:$KD24)} -> 0 | KJ24: =KI24*$J24 -> 0 | KN24: 1
